Workbook

Sheet Forecast Q3
B2: 45550 | D2: ="Days = "&(+B2-A24) -> Days = 77 | E2: ="Days = "&(+A25-B2) -> Days = 15 | G2: 0.7 | M2: Weekly Orders
B3: QUARTER ORDERS | C3: CANCELLATIONS | D3: ORDERS PER DAY | E3: FORECAST ORDERS | F3: CURRENT TOTAL | G3: FORECAST TOTAL | H3: B/FWD | I3: TOTAL | J3: TARGET | K3: C/FWD | M3: 45480 | N3: 45487 | O3: 45494 | P3: 45501 | Q3: 45508 | R3: 45515 | S3: 45522 | T3: 45529 | U3: 45536 | V3: 45543 | W3: 45550 | X3: 45557 | Y3: 45564 | AA3: FORECAST 9/9/24 | AB3: FORECAST 15/9/24
A6: Salford | B6: 158 | C6: 2 | D6: =(B6-C6)/($B$2-$A$24) -> 2.025974 | E6: =rounddown(D6*($A$25-$B$2),0) -> 30 | F6: ='2024 - Q3'!Q6+'2024 - Q3'!R6 -> 173 | G6: =F6+round(E6*$G$2,0) -> 194 | H6: ='2024 - Q3'!B6 -> 80 | I6: =G6+H6 -> 274 | J6: ='2024 - Q3'!T6 -> 183 | K6: =I6-J6 -> 91 | M6: 13 | N6: 27 | O6: 30 | P6: 40 | Q6: 57 | R6: 65 | S6: 80 | T6: 106 | U6: 118 | V6: 147 | W6: 156 | AA6: 204 | AB6: 183
A7: Bolton | B7: 73 | C7: 8 | D7: =(B7-C7)/($B$2-$A$24) -> 0.84415584 | E7: =rounddown(D7*($A$25-$B$2),0) -> 12 | F7: ='2024 - Q3'!Q7+'2024 - Q3'!R7 -> 94 | G7: =F7+round(E7*$G$2,0) -> 102 | H7: ='2024 - Q3'!B7 -> -20 | I7: =G7+H7 -> 82 | J7: ='2024 - Q3'!T7 -> 168 | K7: =I7-J7 -> -86 | M7: 2 | N7: 8 | O7: 14 | P7: 16 | Q7: 25 | R7: 27 | S7: 36 | T7: 47 | U7: 54 | V7: 60 | W7: 65 | AA7: 103 | AB7: 93
A8: Bury | B8: 75 | C8: 3 | D8: =(B8-C8)/($B$2-$A$24) -> 0.93506494 | E8: =rounddown(D8*($A$25-$B$2),0) -> 14 | F8: ='2024 - Q3'!Q8+'2024 - Q3'!R8 -> 107 | G8: =F8+round(E8*$G$2,0) -> 117 | H8: ='2024 - Q3'!B8 -> 17 | I8: =G8+H8 -> 134 | J8: ='2024 - Q3'!T8 -> 118 | K8: =I8-J8 -> 16 | M8: 5 | N8: 6 | O8: 9 | P8: 18 | Q8: 30 | R8: 48 | S8: 53 | T8: 57 | U8: 62 | V8: 65 | W8: 72 | AA8: 120 | AB8: 111
A9: Rochdale | B9: 116 | C9: 2 | D9: =(B9-C9)/($B$2-$A$24) -> 1.4805195 | E9: =rounddown(D9*($A$25-$B$2),0) -> 22 | F9: ='2024 - Q3'!Q9+'2024 - Q3'!R9 -> 144 | G9: =F9+round(E9*$G$2,0) -> 159 | H9: ='2024 - Q3'!B9 -> 25 | I9: =G9+H9 -> 184 | J9: ='2024 - Q3'!T9 -> 148 | K9: =I9-J9 -> 36 | M9: 6 | N9: 23 | O9: 32 | P9: 42 | Q9: 48 | R9: 54 | S9: 60 | T9: 67 | U9: 73 | V9: 83 | W9: 114 | AA9: 150 | AB9: 159
A10: NORTH CDA | B10: =sum(B6:B9) -> 422 | C10: =sum(C6:C9) -> 15 | D10: =sum(D6:D9) -> 5.2857143 | E10: =sum(E6:E9) -> 78 | F10: =sum(F6:F9) -> 518 | G10: =sum(G6:G9) -> 572 | H10: =sum(H6:H9) -> 102 | I10: =sum(I6:I9) -> 674 | ... K10: =sum(K6:K9) -> 57
A11: Macclesfield | B11: 126 | C11: 9 | D11: =(B11-C11)/($B$2-$A$24) -> 1.5194805 | E11: =rounddown(D11*($A$25-$B$2),0) -> 22 | F11: ='2024 - Q3'!Q11+'2024 - Q3'!R11 -> 124 | G11: =F11+round(E11*$G$2,0) -> 139 | H11: ='2024 - Q3'!B11 -> 31 | I11: =G11+H11 -> 170 | J11: ='2024 - Q3'!T11 -> 139 | K11: =I11-J11 -> 31 | M11: 6 | N11: 13 | O11: 17 | P11: 23 | Q11: 29 | R11: 42 | S11: 66 | T11: 77 | U11: 88 | V11: 100 | W11: 117 | AA11: 148 | AB11: 134
A12: Denton | B12: 102 | C12: 8 | D12: =(B12-C12)/($B$2-$A$24) -> 1.2207792 | E12: =rounddown(D12*($A$25-$B$2),0) -> 18 | F12: ='2024 - Q3'!Q12+'2024 - Q3'!R12 -> 111 | G12: =F12+round(E12*$G$2,0) -> 124 | H12: ='2024 - Q3'!B12 -> 20 | I12: =G12+H12 -> 144 | J12: ='2024 - Q3'!T12 -> 127 | K12: =I12-J12 -> 17 | M12: 4 | N12: 15 | O12: 16 | P12: 19 | Q12: 28 | R12: 31 | S12: 38 | T12: 46 | U12: 66 | V12: 87 | W12: 94 | AA12: 130 | AB12: 119
A13: Altrincham | B13: 82 | C13: 4 | D13: =(B13-C13)/($B$2-$A$24) -> 1.012987 | E13: =rounddown(D13*($A$25-$B$2),0) -> 15 | F13: ='2024 - Q3'!Q13+'2024 - Q3'!R13 -> 89 | G13: =F13+round(E13*$G$2,0) -> 100 | H13: ='2024 - Q3'!B13 -> 47 | I13: =G13+H13 -> 147 | J13: ='2024 - Q3'!T13 -> 107 | K13: =I13-J13 -> 40 | M13: 2 | N13: 3 | O13: 9 | P13: 13 | Q13: 18 | R13: 29 | S13: 38 | T13: 46 | U13: 53 | V13: 65 | W13: 78 | AA13: 104 | AB13: 100
A14: Stockport | B14: 142 | C14: 4 | D14: =(B14-C14)/($B$2-$A$24) -> 1.7922078 | E14: =rounddown(D14*($A$25-$B$2),0) -> 26 | F14: ='2024 - Q3'!Q14+'2024 - Q3'!R14 -> 178 | G14: =F14+round(E14*$G$2,0) -> 196 | H14: ='2024 - Q3'!B14 -> 9 | I14: =G14+H14 -> 205 | J14: ='2024 - Q3'!T14 -> 186 | K14: =I14-J14 -> 19 | M14: 14 | N14: 18 | O14: 25 | P14: 35 | Q14: 40 | R14: 58 | S14: 70 | T14: 81 | U14: 91 | V14: 103 | W14: 138 | AA14: 175 | AB14: 183
A15: SOUTH CDA | B15: =sum(B11:B14) -> 452 | C15: =sum(C11:C14) -> 25 | D15: =sum(D11:D14) -> 5.5454545 | E15: =sum(E11:E14) -> 81 | F15: =sum(F11:F14) -> 502 | G15: =sum(G11:G14) -> 559 | H15: =sum(H11:H14) -> 107 | I15: =sum(I11:I14) -> 666 | ... K15: =sum(K11:K14) -> 107
A16: Bradford | B16: 105 | C16: 1 | D16: =(B16-C16)/($B$2-$A$24) -> 1.3506494 | E16: =rounddown(D16*($A$25-$B$2),0) -> 20 | F16: ='2024 - Q3'!Q16+'2024 - Q3'!R16 -> 118 | G16: =F16+round(E16*$G$2,0) -> 132 | H16: ='2024 - Q3'!B16 -> 20 | I16: =G16+H16 -> 152 | J16: ='2024 - Q3'!T16 -> 126 | K16: =I16-J16 -> 26 | M16: 1 | N16: 6 | O16: 8 | P16: 20 | Q16: 30 | R16: 35 | S16: 44 | T16: 53 | U16: 67 | V16: 72 | W16: 104 | AA16: 112 | AB16: 126
A17: Huddersfield | B17: 104 | C17: 2 | D17: =(B17-C17)/($B$2-$A$24) -> 1.3246753 | E17: =rounddown(D17*($A$25-$B$2),0) -> 19 | F17: ='2024 - Q3'!Q17+'2024 - Q3'!R17 -> 134 | G17: =F17+round(E17*$G$2,0) -> 147 | H17: ='2024 - Q3'!B17 -> 0 | I17: =G17+H17 -> 147 | J17: ='2024 - Q3'!T17 -> 149 | K17: =I17-J17 -> -2 | M17: 5 | N17: 11 | O17: 18 | P17: 22 | Q17: 28 | R17: 42 | S17: 54 | T17: 59 | U17: 71 | V17: 79 | W17: 102 | AA17: 140 | AB17: 136
A18: Silsden | B18: 41 | C18: 2 | D18: =(B18-C18)/($B$2-$A$24) -> 0.50649351 | E18: =rounddown(D18*($A$25-$B$2),0) -> 7 | F18: ='2024 - Q3'!Q18+'2024 - Q3'!R18 -> 45 | G18: =F18+round(E18*$G$2,0) -> 50 | H18: ='2024 - Q3'!B18 -> 14 | I18: =G18+H18 -> 64 | J18: ='2024 - Q3'!T18 -> 55 | K18: =I18-J18 -> 9 | M18: 3 | N18: 4 | O18: 5 | P18: 8 | Q18: 14 | R18: 16 | S18: 17 | T18: 19 | U18: 26 | V18: 31 | W18: 39 | AA18: 51 | AB18: 52
A19: WY CDA | B19: =sum(B16:B18) -> 250 | C19: =sum(C16:C18) -> 5 | D19: =sum(D16:D18) -> 3.1818182 | E19: =sum(E16:E18) -> 46 | F19: =sum(F16:F18) -> 297 | G19: =sum(G16:G18) -> 329 | H19: =sum(H16:H18) -> 34 | I19: =sum(I16:I18) -> 363 | ... K19: =sum(K16:K18) -> 33
A22: TOTAL | B22: =B19+B15+B10 -> 1124 | C22: =C19+C15+C10 -> 45 | D22: =D19+D15+D10 -> 14.012987 | E22: =E19+E15+E10 -> 205 | F22: =F19+F15+F10 -> 1317 | G22: =G19+G15+G10 -> 1460 | H22: =H19+H15+H10 -> 243 | I22: =I19+I15+I10 -> 1703 | ... K22: =K19+K15+K10 -> 197 | M22: =sum(M6:M21) -> 61 | N22: =sum(N6:N21) -> 134 | O22: =sum(O6:O21) -> 183 | P22: =sum(P6:P21) -> 256 | Q22: =sum(Q6:Q21) -> 347 | R22: =sum(R6:R21) -> 447 | S22: =sum(S6:S21) -> 556 | T22: =sum(T6:T21) -> 658 | ... Y22: =sum(Y6:Y21) -> 0 | AA22: =sum(AA6:AA21) -> 1437 | AB22: =sum(AB6:AB21) -> 1396
A24: 45473 | C24: =B22-C22 -> 1079 | L24: Orders Per Week | M24: =M22 -> 61 | N24: =N22-M22 -> 73 | O24: =O22-N22 -> 49 | P24: =P22-O22 -> 73 | Q24: =Q22-P22 -> 91 | R24: =R22-Q22 -> 100 | S24: =S22-R22 -> 109 | T24: =T22-S22 -> 102 | U24: =U22-T22 -> 111 | ... Y24: =Y22-X22 -> 0
A25: 45565

Sheet 2026 - Q3
A1: REGISTRATIONS (COUNTING) | AC1: Updated | AD1: By
B2: JULY | H2: AUG | N2: SEPT | T2: TOTAL
B3: Counting | C3: CLCP Regs | D3: Counting Fleet | E3: Total | F3: Target | H3: Counting | I3: CLCP Regs | J3: Counting Fleet | K3: Total | L3: Target | N3: Counting | O3: CLCP Regs | P3: Counting Fleet | Q3: Total | R3: Target | T3: Counting | U3: Counting Fleet | V3: Total | W3: Target | X3: TO GO | Y3: PER WEEK | Z3: QTR REGS | AA3: TARGET | AB3: REGS v TGT
A4: Bolton | B4: 32 | E4: =SUM(B4:D4) -> 32 | F4: 24 | G4: =E4/F4 -> 1.3333333 | H4: 7 | K4: =SUM(H4:J4) -> 7 | L4: 12 | M4: =K4/L4 -> 0.58333333 | N4: 21 | Q4: =SUM(N4:P4) -> 21 | R4: 69 | S4: =Q4/R4 -> 0.30434783 | T4: =N4+H4+B4+O4+I4 -> 60 | U4: =P4+J4+D4 -> 0 | V4: =sum(T4:U4) -> 60 | W4: =F4+L4+R4 -> 105 | X4: =W4-V4 -> 45 | Y4: =round(X4/$Y$24*7,0) -> 4 | Z4: =V4 -> 60 | AA4: =W4 -> 105 | AB4: =Z4/AA4 -> 0.57142857 | AC4: 46216 | AD4: DH
A5: Bury | B5: 16 | E5: =SUM(B5:D5) -> 16 | F5: 19 | G5: =E5/F5 -> 0.84210526 | H5: 2 | K5: =SUM(H5:J5) -> 2 | L5: 11 | M5: =K5/L5 -> 0.18181818 | N5: 18 | Q5: =SUM(N5:P5) -> 18 | R5: 47 | S5: =Q5/R5 -> 0.38297872 | T5: =N5+H5+B5+O5+I5 -> 36 | U5: =P5+J5+D5 -> 0 | V5: =sum(T5:U5) -> 36 | W5: =F5+L5+R5 -> 77 | X5: =W5-V5 -> 41 | Y5: =round(X5/$Y$24*7,0) -> 4 | Z5: =V5 -> 36 | AA5: =W5 -> 77 | AB5: =Z5/AA5 -> 0.46753247 | AC5: 46215 | AD5: TP
A6: Rochdale | B6: 24 | E6: =SUM(B6:D6) -> 24 | F6: 19 | G6: =E6/F6 -> 1.2631579 | H6: 6 | K6: =SUM(H6:J6) -> 6 | L6: 11 | M6: =K6/L6 -> 0.54545455 | N6: 23 | Q6: =SUM(N6:P6) -> 23 | R6: 55 | S6: =Q6/R6 -> 0.41818182 | T6: =N6+H6+B6+O6+I6 -> 53 | U6: =P6+J6+D6 -> 0 | V6: =sum(T6:U6) -> 53 | W6: =F6+L6+R6 -> 85 | X6: =W6-V6 -> 32 | Y6: =round(X6/$Y$24*7,0) -> 3 | Z6: =V6 -> 53 | AA6: =W6 -> 85 | AB6: =Z6/AA6 -> 0.62352941 | AC6: 46216 | AD6: PF
A7: SQ | B7: 29 | D7: 2 | E7: =SUM(B7:D7) -> 31 | F7: 32 | G7: =E7/F7 -> 0.96875 | H7: 4 | K7: =SUM(H7:J7) -> 4 | L7: 18 | M7: =K7/L7 -> 0.22222222 | N7: 13 | Q7: =SUM(N7:P7) -> 13 | R7: 90 | S7: =Q7/R7 -> 0.14444444 | T7: =N7+H7+B7+O7+I7 -> 46 | U7: =P7+J7+D7 -> 2 | V7: =sum(T7:U7) -> 48 | W7: =F7+L7+R7 -> 140 | X7: =W7-V7 -> 92 | Y7: =round(X7/$Y$24*7,0) -> 8 | Z7: =V7 -> 48 | AA7: =W7 -> 140 | AB7: =Z7/AA7 -> 0.34285714 | AC7: 46216 | AD7: WB
A8: NORTH CDA | B8: =sum(B4:B7) -> 101 | C8: =sum(C4:C7) -> 0 | D8: =sum(D4:D7) -> 2 | E8: =sum(E4:E7) -> 103 | F8: =sum(F4:F7) -> 94 | G8: =E8/F8 -> 1.0957447 | H8: =sum(H3:H7) -> 19 | I8: =sum(I4:I7) -> 0 | J8: =sum(J4:J7) -> 0 | K8: =sum(K4:K7) -> 19 | L8: =sum(L4:L7) -> 52 | M8: =K8/L8 -> 0.36538462 | N8: =sum(N4:N7) -> 75 | O8: =sum(O4:O7) -> 0 | P8: =sum(P4:P7) -> 0 | Q8: =sum(Q4:Q7) -> 75 | R8: =sum(R4:R7) -> 261 | S8: =Q8/R8 -> 0.28735632 | T8: =sum(T4:T7) -> 195 | U8: =sum(U4:U7) -> 2 | V8: =sum(V4:V7) -> 197 | W8: =sum(W4:W7) -> 407 | X8: =sum(X4:X7) -> 210 | Y8: =round(X8/Y24*7,0) -> 19 | Z8: =sum(Z4:Z7) -> 197 | AA8: =sum(AA4:AA7) -> 407 | AB8: =Z8/AA8 -> 0.48402948
A9: Altrincham | B9: 20 | E9: =SUM(B9:D9) -> 20 | F9: 19 | G9: =E9/F9 -> 1.0526316 | H9: 9 | K9: =SUM(H9:J9) -> 9 | L9: 11 | M9: =K9/L9 -> 0.81818182 | N9: 6 | Q9: =SUM(N9:P9) -> 6 | R9: 57 | S9: =Q9/R9 -> 0.10526316 | T9: =N9+H9+B9+O9+I9 -> 35 | U9: =P9+J9+D9 -> 0 | V9: =sum(T9:U9) -> 35 | W9: =F9+L9+R9 -> 87 | X9: =W9-V9 -> 52 | Y9: =round(X9/$Y$24*7,0) -> 5 | Z9: =V9 -> 35 | AA9: =W9 -> 87 | AB9: =Z9/AA9 -> 0.40229885 | AC9: 46209 | AD9: NF
A10: Denton | B10: 25 | D10: 3 | E10: =SUM(B10:D10) -> 28 | F10: 19 | G10: =E10/F10 -> 1.4736842 | H10: 7 | K10: =SUM(H10:J10) -> 7 | L10: 11 | M10: =K10/L10 -> 0.63636364 | N10: 9 | Q10: =SUM(N10:P10) -> 9 | R10: 63 | S10: =Q10/R10 -> 0.14285714 | T10: =N10+H10+B10+O10+I10 -> 41 | U10: =P10+J10+D10 -> 3 | V10: =sum(T10:U10) -> 44 | W10: =F10+L10+R10 -> 93 | X10: =W10-V10 -> 49 | Y10: =round(X10/$Y$24*7,0) -> 4 | Z10: =V10 -> 44 | AA10: =W10 -> 93 | AB10: =Z10/AA10 -> 0.47311828 | AC10: 46209 | AD10: NF
A11: Macclesfield | B11: 15 | E11: =SUM(B11:D11) -> 15 | F11: 21 | G11: =E11/F11 -> 0.71428571 | H11: 2 | K11: =SUM(H11:J11) -> 2 | L11: 13 | M11: =K11/L11 -> 0.15384615 | N11: 18 | Q11: =SUM(N11:P11) -> 18 | R11: 62 | S11: =Q11/R11 -> 0.29032258 | T11: =N11+H11+B11+O11+I11 -> 35 | U11: =P11+J11+D11 -> 0 | V11: =sum(T11:U11) -> 35 | W11: =F11+L11+R11 -> 96 | X11: =W11-V11 -> 61 | Y11: =round(X11/$Y$24*7,0) -> 5 | Z11: =V11 -> 35 | AA11: =W11 -> 96 | AB11: =Z11/AA11 -> 0.36458333 | AC11: 46209 | AD11: NF
A12: Stockport | B12: 40 | E12: =SUM(B12:D12) -> 40 | F12: 34 | G12: =E12/F12 -> 1.1764706 | H12: 8 | K12: =SUM(H12:J12) -> 8 | L12: 20 | M12: =K12/L12 -> 0.4 | N12: 18 | Q12: =SUM(N12:P12) -> 18 | R12: 97 | S12: =Q12/R12 -> 0.18556701 | T12: =N12+H12+B12+O12+I12 -> 66 | U12: =P12+J12+D12 -> 0 | V12: =sum(T12:U12) -> 66 | W12: =F12+L12+R12 -> 151 | X12: =W12-V12 -> 85 | Y12: =round(X12/$Y$24*7,0) -> 8 | Z12: =V12 -> 66 | AA12: =W12 -> 151 | AB12: =Z12/AA12 -> 0.43708609 | AC12: 46209 | AD12: NF
A13: SOUTH CDA | B13: =sum(B9:B12) -> 100 | C13: =sum(C9:C12) -> 0 | D13: =sum(D9:D12) -> 3 | E13: =sum(E9:E12) -> 103 | F13: =sum(F9:F12) -> 93 | G13: =E13/F13 -> 1.1075269 | H13: =sum(H9:H12) -> 26 | I13: =sum(I9:I12) -> 0 | J13: =sum(J9:J12) -> 0 | K13: =sum(K9:K12) -> 26 | L13: =sum(L9:L12) -> 55 | M13: =K13/L13 -> 0.47272727 | N13: =sum(N9:N12) -> 51 | O13: =sum(O9:O12) -> 0 | P13: =sum(P9:P12) -> 0 | Q13: =sum(Q9:Q12) -> 51 | R13: =sum(R9:R12) -> 279 | S13: =Q13/R13 -> 0.1827957 | T13: =sum(T9:T12) -> 177 | U13: =sum(U9:U12) -> 3 | V13: =sum(V9:V12) -> 180 | W13: =sum(W9:W12) -> 427 | X13: =sum(X9:X12) -> 247 | Y13: =round(X13/Y24*7,0) -> 22 | Z13: =sum(Z9:Z12) -> 180 | AA13: =sum(AA9:AA12) -> 427 | AB13: =Z13/AA13 -> 0.42154567
A14: Bradford | B14: 26 | D14: 4 | E14: =SUM(B14:D14) -> 30 | F14: 22 | G14: =E14/F14 -> 1.3636364 | H14: 10 | J14: 2 | K14: =SUM(H14:J14) -> 12 | L14: 13 | M14: =K14/L14 -> 0.92307692 | N14: 16 | P14: 2 | Q14: =SUM(N14:P14) -> 18 | R14: 70 | S14: =Q14/R14 -> 0.25714286 | T14: =N14+H14+B14+O14+I14 -> 52 | U14: =P14+J14+D14 -> 8 | V14: =sum(T14:U14) -> 60 | W14: =F14+L14+R14 -> 105 | X14: =W14-V14 -> 45 | Y14: =round(X14/$Y$24*7,0) -> 4 | Z14: =V14 -> 60 | AA14: =W14 -> 105 | AB14: =Z14/AA14 -> 0.57142857 | AC14: 46215 | AD14: SA
A15: Huddersfield | B15: 30 | C15: 0 | D15: 1 | E15: =SUM(B15:D15) -> 31 | F15: 23 | G15: =E15/F15 -> 1.3478261 | H15: 5 | J15: 2 | K15: =SUM(H15:J15) -> 7 | L15: 13 | M15: =K15/L15 -> 0.53846154 | N15: 20 | P15: 2 | Q15: =SUM(N15:P15) -> 22 | R15: 72 | S15: =Q15/R15 -> 0.30555556 | T15: =N15+H15+B15+O15+I15 -> 55 | U15: =P15+J15+D15 -> 5 | V15: =sum(T15:U15) -> 60 | W15: =F15+L15+R15 -> 108 | X15: =W15-V15 -> 48 | Y15: =round(X15/$Y$24*7,0) -> 4 | Z15: =V15 -> 60 | AA15: =W15 -> 108 | AB15: =Z15/AA15 -> 0.55555556 | AC15: 46216 | AD15: CM
A16: Silsden | B16: 9 | E16: =SUM(B16:D16) -> 9 | F16: 8 | G16: =E16/F16 -> 1.125 | H16: 2 | K16: =SUM(H16:J16) -> 2 | L16: 3 | M16: =K16/L16 -> 0.66666667 | N16: 3 | Q16: =SUM(N16:P16) -> 3 | R16: 23 | S16: =Q16/R16 -> 0.13043478 | T16: =N16+H16+B16+O16+I16 -> 14 | U16: =P16+J16+D16 -> 0 | V16: =sum(T16:U16) -> 14 | W16: =F16+L16+R16 -> 34 | X16: =W16-V16 -> 20 | Y16: =round(X16/$Y$24*7,0) -> 2 | Z16: =V16 -> 14 | AA16: =W16 -> 34 | AB16: =Z16/AA16 -> 0.41176471 | AC16: 46216 | AD16: RM
A17: WY CDA | B17: =sum(B14:B16) -> 65 | C17: =sum(C14:C16) -> 0 | D17: =sum(D14:D16) -> 5 | E17: =sum(E14:E16) -> 70 | F17: =sum(F14:F16) -> 53 | G17: =E17/F17 -> 1.3207547 | H17: =sum(H14:H16) -> 17 | I17: =sum(I14:I16) -> 0 | J17: =sum(J14:J16) -> 4 | K17: =sum(K14:K16) -> 21 | L17: =sum(L14:L16) -> 29 | M17: =K17/L17 -> 0.72413793 | N17: =sum(N14:N16) -> 39 | O17: =sum(O14:O16) -> 0 | P17: =sum(P14:P16) -> 4 | Q17: =sum(Q14:Q16) -> 43 | R17: =sum(R14:R16) -> 165 | S17: =Q17/R17 -> 0.26060606 | T17: =sum(T14:T16) -> 121 | U17: =sum(U14:U16) -> 13 | V17: =sum(V14:V16) -> 134 | W17: =sum(W14:W16) -> 247 | X17: =sum(X14:X16) -> 113 | Y17: =round(X17/Y24*7,0) -> 10 | Z17: =sum(Z14:Z16) -> 134 | AA17: =sum(AA14:AA16) -> 247 | AB17: =Z17/AA17 -> 0.54251012
A20: TOTAL | B20: =SUM(B8+B13+B17) -> 266 | C20: =SUM(C8+C13+C17) -> 0 | D20: =SUM(D8+D13+D17) -> 10 | E20: =SUM(E8+E13+E17) -> 276 | F20: =SUM(F8+F13+F17) -> 240 | G20: =E20/F20 -> 1.15 | H20: =SUM(H8+H13+H17) -> 62 | I20: =SUM(I8+I13+I17) -> 0 | J20: =SUM(J8+J13+J17) -> 4 | K20: =SUM(K8+K13+K17) -> 66 | L20: =SUM(L8+L13+L17) -> 136 | M20: =K20/L20 -> 0.48529412 | N20: =SUM(N8+N13+N17) -> 165 | O20: =SUM(O8+O13+O17) -> 0 | P20: =SUM(P8+P13+P17) -> 4 | Q20: =SUM(Q8+Q13+Q17) -> 169 | R20: =SUM(R8+R13+R17) -> 705 | S20: =Q20/R20 -> 0.23971631 | T20: =SUM(T8+T13+T17) -> 493 | U20: =SUM(U8+U13+U17) -> 18 | V20: =SUM(V8+V13+V17) -> 511 | W20: =SUM(W8+W13+W17) -> 1081 | X20: =SUM(X8+X13+X17) -> 570 | Y20: =round(X20/Y24*7,0) -> 51 | Z20: =Z8+Z13+Z17 -> 511 | AA20: =AA8+AA13+AA17 -> 1081 | AB20: =Z20/AA20 -> 0.47271045
Y22: 46295 | AA22: =Z17-AA17 -> -113
Y23: =today() -> 46216
Y24: =Y22-Y23 -> 79
A25: REGISTRATIONS (NON-COUNTING) | S25: Updated | T25: By
B26: JULY | F26: AUGUST | J26: SEPT | O26: TOTAL
B27: Non-Counting Fleet (Reg) | C27: Non-Counting Fleet (Unreg) | D27: Total | E27: Budget | F27: Non-Counting Fleet (Reg) | G27: Non-Counting Fleet (Unreg) | H27: Total | I27: Budget | J27: Non-Counting Fleet (Reg) | K27: Non-Counting Fleet (Unreg) | L27: Total | M27: Budget | O27: Non-Counting Fleet (Reg) | P27: Non-Counting Fleet (Unreg) | Q27: Total | R27: Budget
A28: Salford | B28: 11 | C28: 65 | D28: =SUM(B28:C28) -> 76 | G28: 18 | H28: =SUM(F28:G28) -> 18 | K28: 10 | L28: 0 | O28: =J28+F28+B28 -> 11 | P28: =K28+G28+C28 -> 93 | Q28: =P28+O28 -> 104 | R28: =M28+I28+E28 -> 0 | S28: 46216 | T28: GB
A29: NORTH CDA | B29: =sum(B28) -> 11 | C29: =sum(C28) -> 65 | D29: =sum(D28) -> 76 | E29: =sum(E28) -> 0 | F29: =sum(F28) -> 0 | G29: =sum(G28) -> 18 | H29: =sum(H28) -> 18 | I29: =sum(I28) -> 0 | ... M29: =sum(M28) -> 0 | O29: =sum(O28) -> 11 | P29: =sum(P28) -> 93 | Q29: =sum(Q28) -> 104 | R29: =sum(R28) -> 0
A30: Denton | C30: 19 | D30: =SUM(B30:C30) -> 19 | G30: 22 | H30: =SUM(F30:G30) -> 22 | K30: 20 | L30: =K30+J30 -> 20 | O30: =J30+F30+B30 -> 0 | P30: =C30+G30+K30 -> 61 | Q30: =P30+O30 -> 61 | R30: =M30+I30+E30 -> 0
A31: SOUTH CDA | B31: =sum(B30) -> 0 | C31: =sum(C30) -> 19 | D31: =sum(D30) -> 19 | E31: =sum(E30) -> 0 | F31: =sum(F30) -> 0 | G31: =sum(G30) -> 22 | H31: =sum(H30) -> 22 | I31: =sum(I30) -> 0 | ... M31: =sum(M30) -> 0 | O31: =sum(O30) -> 0 | P31: =sum(P30) -> 61 | Q31: =sum(Q30) -> 61 | R31: =sum(R30) -> 0
A32: Bradford | B32: 2 | C32: 28 | D32: =SUM(B32:C32) -> 30 | G32: 40 | H32: =SUM(F32:G32) -> 40 | K32: 40 | L32: =K32+J32 -> 40 | O32: =J32+F32+B32 -> 2 | P32: =K32+G32+C32 -> 108 | Q32: =P32+O32 -> 110 | R32: =M32+I32+E32 -> 0 | S32: 46216 | T32: GB
A33: WY CDA | B33: =sum(B32) -> 2 | C33: =sum(C32) -> 28 | D33: =sum(D32) -> 30 | E33: =sum(E32) -> 0 | F33: =sum(F32) -> 0 | G33: =sum(G32) -> 40 | H33: =sum(H32) -> 40 | I33: =sum(I32) -> 0 | ... M33: =sum(M32) -> 0 | O33: =sum(O32) -> 2 | P33: =sum(P32) -> 108 | Q33: =sum(Q32) -> 110 | R33: =sum(R32) -> 0
A36: TOTAL | B36: =B33+B31+B29 -> 13 | C36: =C33+C31+C29 -> 112 | D36: =D33+D31+D29 -> 125 | E36: =E33+E31+E29 -> 0 | F36: =F33+F31+F29 -> 0 | G36: =G33+G31+G29 -> 80 | H36: =H33+H31+H29 -> 80 | I36: =I33+I31+I29 -> 0 | ... M36: =M33+M31+M29 -> 0 | O36: =O33+O31+O29 -> 13 | P36: =P33+P31+P29 -> 262 | Q36: =Q33+Q31+Q29 -> 275 | R36: =R33+R31+R29 -> 0
R38: =Q36/R36 -> #DIV/0!
A40: USED COUNTING VOLUME | M40: Updated | N40: By
B41: JULY | E41: AUG | H41: SEPT | K41: TOTAL
B42: Counting | C42: Target | E42: Counting | F42: Target | H42: Counting | I42: Target | K42: Counting | L42: Target
A43: Bolton | B43: 21 | C43: 63 | D43: =B43/C43 -> 0.33333333 | F43: 62 | G43: =E43/F43 -> 0 | I43: 62 | J43: =H43/I43 -> 0 | K43: =H43+E43+B43 -> 21 | L43: =I43+F43+C43 -> 187 | M43: 46216 | N43: DH
A44: Bury | B44: 16 | C44: 55 | D44: =B44/C44 -> 0.29090909 | F44: 54 | G44: =E44/F44 -> 0 | I44: 54 | J44: =H44/I44 -> 0 | K44: =H44+E44+B44 -> 16 | L44: =I44+F44+C44 -> 163 | M44: 46215 | N44: TP
A45: Rochdale | B45: 19 | C45: 51 | D45: =B45/C45 -> 0.37254902 | F45: 50 | G45: =E45/F45 -> 0 | I45: 50 | J45: =H45/I45 -> 0 | K45: =H45+E45+B45 -> 19 | L45: =I45+F45+C45 -> 151 | M45: 46216 | N45: PF
A46: SQ | B46: 25 | C46: 60 | D46: =B46/C46 -> 0.41666667 | F46: 59 | G46: =E46/F46 -> 0 | I46: 59 | J46: =H46/I46 -> 0 | K46: =H46+E46+B46 -> 25 | L46: =I46+F46+C46 -> 178 | M46: 46216 | N46: WB
A47: NORTH CDA | B47: =sum(B43:B46) -> 81 | C47: =sum(C43:C46) -> 229 | D47: =B47/C47 -> 0.35371179 | E47: =sum(E43:E46) -> 0 | F47: =sum(F43:F46) -> 225 | G47: =E47/F47 -> 0 | H47: =sum(H43:H46) -> 0 | I47: =sum(I43:I46) -> 225 | J47: =H47/I47 -> 0 | K47: =sum(K43:K46) -> 81 | L47: =sum(L43:L46) -> 679
...

Sheet 2026 - Q2
A3: REGISTRATIONS (COUNTING) | AC3: Updated | AD3: By
B4: APR | G4: MAY | M4: JUNE | T4: TOTAL
B5: Counting | C5: Counting Fleet | D5: Total | E5: Target | G5: Counting | H5: CLCP Regs | I5: Counting Fleet | J5: Total | K5: Target | M5: Counting | N5: CLCP Regs | O5: Counting Fleet | P5: Total | Q5: Target | S5: B/FWD | T5: Counting | U5: Counting Fleet | V5: Total | W5: Target | X5: TO GO | Y5: PER WEEK | Z5: QTR REGS | AA5: TARGET | AB5: REGS v TGT
A6: Bolton | B6: 26 | D6: =SUM(B6:C6) -> 26 | E6: 21 | F6: =D6/E6 -> 1.2380952 | G6: 31 | I6: 1 | J6: =SUM(G6:I6) -> 32 | K6: 27 | L6: =J6/K6 -> 1.1851852 | M6: 42 | N6: 0 | O6: 1 | P6: =SUM(M6:O6) -> 43 | Q6: 48 | R6: =P6/Q6 -> 0.89583333 | T6: =M6+G6+B6+N6+H6 -> 99 | U6: =O6+I6+C6 -> 2 | V6: =sum(S6:U6) -> 101 | W6: =E6+K6+Q6 -> 96 | X6: =W6-V6 -> -5 | Y6: =round(X6/$Y$26*7,0) -> 3 | Z6: =U6+T6 -> 101 | AA6: =W6 -> 96 | AB6: =(T6+U6)/W6 -> 1.0520833 | AC6: 46203 | AD6: GB
A7: Bury | B7: 23 | D7: =SUM(B7:C7) -> 23 | E7: 15 | F7: =D7/E7 -> 1.5333333 | G7: 27 | I7: 1 | J7: =SUM(G7:I7) -> 28 | K7: 20 | L7: =J7/K7 -> 1.4 | M7: 25 | O7: 1 | P7: =SUM(M7:O7) -> 26 | Q7: 36 | R7: =P7/Q7 -> 0.72222222 | T7: =M7+G7+B7+N7+H7 -> 75 | U7: =O7+I7+C7 -> 2 | V7: =sum(S7:U7) -> 77 | W7: =E7+K7+Q7 -> 71 | X7: =W7-V7 -> -6 | Y7: =round(X7/$Y$26*7,0) -> 3 | Z7: =U7+T7 -> 77 | AA7: =W7 -> 71 | AB7: =(T7+U7)/W7 -> 1.084507 | AC7: 46203 | AD7: GB
A8: Rochdale | B8: 22 | D8: =SUM(B8:C8) -> 22 | E8: 17 | F8: =D8/E8 -> 1.2941176 | G8: 41 | J8: =SUM(G8:I8) -> 41 | K8: 23 | L8: =J8/K8 -> 1.7826087 | M8: 25 | N8: 2 | P8: =SUM(M8:O8) -> 27 | Q8: 40 | R8: =P8/Q8 -> 0.675 | T8: =M8+G8+B8+N8+H8 -> 90 | U8: =O8+I8+C8 -> 0 | V8: =sum(S8:U8) -> 90 | W8: =E8+K8+Q8 -> 80 | X8: =W8-V8 -> -10 | Y8: =round(X8/$Y$26*7,0) -> 5 | Z8: =U8+T8 -> 90 | AA8: =W8 -> 80 | AB8: =(T8+U8)/W8 -> 1.125 | AC8: 46203 | AD8: GB
A9: SQ | B9: 43 | C9: 9 | D9: =SUM(B9:C9) -> 52 | E9: 29 | F9: =D9/E9 -> 1.7931034 | G9: 38 | H9: 0 | I9: 7 | J9: =SUM(G9:I9) -> 45 | K9: 37 | L9: =J9/K9 -> 1.2162162 | M9: 43 | N9: 1 | O9: 6 | P9: =SUM(M9:O9) -> 50 | Q9: 60 | R9: =P9/Q9 -> 0.83333333 | T9: =M9+G9+B9+N9+H9 -> 125 | U9: =O9+I9+C9 -> 22 | V9: =sum(S9:U9) -> 147 | W9: =E9+K9+Q9 -> 126 | X9: =W9-V9 -> -21 | Y9: =round(X9/$Y$26*7,0) -> 11 | Z9: =U9+T9 -> 147 | AA9: =W9 -> 126 | AB9: =(T9+U9)/W9 -> 1.1666667 | AC9: 46203 | AD9: GB
A10: NORTH CDA | B10: =sum(B6:B9) -> 114 | C10: =sum(C6:C9) -> 9 | D10: =sum(D6:D9) -> 123 | E10: =sum(E6:E9) -> 82 | F10: =D10/E10 -> 1.5 | G10: =sum(G6:G9) -> 137 | H10: =sum(H6:H9) -> 0 | I10: =sum(I6:I9) -> 9 | J10: =sum(J6:J9) -> 146 | K10: =sum(K6:K9) -> 107 | L10: =J10/K10 -> 1.364486 | M10: =sum(M6:M9) -> 135 | N10: =sum(N6:N9) -> 3 | O10: =sum(O6:O9) -> 8 | P10: =sum(P6:P9) -> 146 | Q10: =sum(Q6:Q9) -> 184 | R10: =P10/Q10 -> 0.79347826 | S10: =sum(S6:S9) -> 0 | T10: =sum(T6:T9) -> 389 | U10: =sum(U6:U9) -> 26 | V10: =sum(V6:V9) -> 415 | W10: =sum(W6:W9) -> 373 | X10: =sum(X6:X9) -> -42 | Y10: =round(X10/Y26*7,0) -> 23 | Z10: =sum(Z6:Z9) -> 415 | AA10: =sum(AA6:AA9) -> 373 | AB10: =Z10/AA10 -> 1.1126005
A11: Altrincham | B11: 10 | D11: =SUM(B11:C11) -> 10 | E11: 16 | F11: =D11/E11 -> 0.625 | G11: 31 | J11: =SUM(G11:I11) -> 31 | K11: 21 | L11: =J11/K11 -> 1.4761905 | M11: 32 | P11: =SUM(M11:O11) -> 32 | Q11: 36 | R11: =P11/Q11 -> 0.88888889 | T11: =M11+G11+B11+N11+H11 -> 73 | U11: =O11+I11+C11 -> 0 | V11: =sum(S11:U11) -> 73 | W11: =E11+K11+Q11 -> 73 | X11: =W11-V11 -> 0 | Y11: =round(X11/$Y$26*7,0) -> 0 | Z11: =U11+T11 -> 73 | AA11: =W11 -> 73 | AB11: =(T11+U11)/W11 -> 1 | AC11: 46204 | AD11: NF
A12: Denton | B12: 27 | C12: 1 | D12: =SUM(B12:C12) -> 28 | E12: 17 | F12: =D12/E12 -> 1.6470588 | G12: 25 | I12: 1 | J12: =SUM(G12:I12) -> 26 | K12: 24 | L12: =J12/K12 -> 1.0833333 | M12: 28 | O12: 5 | P12: =SUM(M12:O12) -> 33 | Q12: 42 | R12: =P12/Q12 -> 0.78571429 | T12: =M12+G12+B12+N12+H12 -> 80 | U12: =O12+I12+C12 -> 7 | V12: =sum(S12:U12) -> 87 | W12: =E12+K12+Q12 -> 83 | X12: =W12-V12 -> -4 | Y12: =round(X12/$Y$26*7,0) -> 2 | Z12: =U12+T12 -> 87 | AA12: =W12 -> 83 | AB12: =(T12+U12)/W12 -> 1.0481928 | AC12: 46204 | AD12: NF
A13: Macclesfield | B13: 18 | D13: =SUM(B13:C13) -> 18 | E13: 18 | F13: =D13/E13 -> 1 | G13: 26 | J13: =SUM(G13:I13) -> 26 | K13: 23 | L13: =J13/K13 -> 1.1304348 | M13: 39 | P13: =SUM(M13:O13) -> 39 | Q13: 40 | R13: =P13/Q13 -> 0.975 | T13: =M13+G13+B13+N13+H13 -> 83 | U13: =O13+I13+C13 -> 0 | V13: =sum(S13:U13) -> 83 | W13: =E13+K13+Q13 -> 81 | X13: =W13-V13 -> -2 | Y13: =round(X13/$Y$26*7,0) -> 1 | Z13: =U13+T13 -> 83 | AA13: =W13 -> 81 | AB13: =(T13+U13)/W13 -> 1.0246914 | AC13: 46204 | AD13: NF
A14: Stockport | B14: 30 | D14: =SUM(B14:C14) -> 30 | E14: 30 | F14: =D14/E14 -> 1 | G14: 40 | J14: =SUM(G14:I14) -> 40 | K14: 39 | L14: =J14/K14 -> 1.025641 | M14: 62 | P14: =SUM(M14:O14) -> 62 | Q14: 66 | R14: =P14/Q14 -> 0.93939394 | T14: =M14+G14+B14+N14+H14 -> 132 | U14: =O14+I14+C14 -> 0 | V14: =sum(S14:U14) -> 132 | W14: =E14+K14+Q14 -> 135 | X14: =W14-V14 -> 3 | Y14: =round(X14/$Y$26*7,0) -> -2 | Z14: =U14+T14 -> 132 | AA14: =W14 -> 135 | AB14: =(T14+U14)/W14 -> 0.97777778 | AC14: 46204 | AD14: NF
A15: SOUTH CDA | B15: =sum(B11:B14) -> 85 | C15: =sum(C11:C14) -> 1 | D15: =sum(D11:D14) -> 86 | E15: =sum(E11:E14) -> 81 | F15: =D15/E15 -> 1.0617284 | G15: =sum(G11:G14) -> 122 | H15: =sum(H11:H14) -> 0 | I15: =sum(I11:I14) -> 1 | J15: =sum(J11:J14) -> 123 | K15: =sum(K11:K14) -> 107 | L15: =J15/K15 -> 1.1495327 | M15: =sum(M11:M14) -> 161 | N15: =sum(N11:N14) -> 0 | O15: =sum(O11:O14) -> 5 | P15: =sum(P11:P14) -> 166 | Q15: =sum(Q11:Q14) -> 184 | R15: =P15/Q15 -> 0.90217391 | S15: =sum(S11:S14) -> 0 | T15: =sum(T11:T14) -> 368 | U15: =sum(U11:U14) -> 7 | V15: =sum(V11:V14) -> 375 | W15: =sum(W11:W14) -> 372 | X15: =sum(X11:X14) -> -3 | Y15: =round(X15/Y26*7,0) -> 2 | Z15: =sum(Z11:Z14) -> 375 | AA15: =sum(AA11:AA14) -> 372 | AB15: =Z15/AA15 -> 1.0080645
A16: Bradford | B16: 18 | C16: 4 | D16: =SUM(B16:C16) -> 22 | E16: 22 | F16: =D16/E16 -> 1 | G16: 21 | I16: 6 | J16: =SUM(G16:I16) -> 27 | K16: 26 | L16: =J16/K16 -> 1.0384615 | M16: 23 | N16: 4 | O16: 3 | P16: =SUM(M16:O16) -> 30 | Q16: 44 | R16: =P16/Q16 -> 0.68181818 | T16: =M16+G16+B16+N16+H16 -> 66 | U16: =O16+I16+C16 -> 13 | V16: =sum(S16:U16) -> 79 | W16: =E16+K16+Q16 -> 92 | X16: =W16-V16 -> 13 | Y16: =round(X16/$Y$26*7,0) -> -7 | Z16: =U16+T16 -> 79 | AA16: =W16 -> 92 | AB16: =(T16+U16)/W16 -> 0.85869565 | AC16: 46203 | AD16: GB
A17: Huddersfield | B17: 19 | C17: 6 | D17: =SUM(B17:C17) -> 25 | E17: 21 | F17: =D17/E17 -> 1.1904762 | G17: 37 | H17: 1 | I17: 0 | J17: =SUM(G17:I17) -> 38 | K17: 27 | L17: =J17/K17 -> 1.4074074 | M17: 31 | N17: 1 | O17: 2 | P17: =SUM(M17:O17) -> 34 | Q17: 49 | R17: =P17/Q17 -> 0.69387755 | T17: =M17+G17+B17+N17+H17 -> 89 | U17: =O17+I17+C17 -> 8 | V17: =sum(S17:U17) -> 97 | W17: =E17+K17+Q17 -> 97 | X17: =W17-V17 -> 0 | Y17: =round(X17/$Y$26*7,0) -> 0 | Z17: =U17+T17 -> 97 | AA17: =W17 -> 97 | AB17: =(T17+U17)/W17 -> 1 | AC17: 46203 | AD17: GB
A18: Silsden | B18: 6 | D18: =SUM(B18:C18) -> 6 | E18: 6 | F18: =D18/E18 -> 1 | G18: 7 | J18: =SUM(G18:I18) -> 7 | K18: 9 | L18: =J18/K18 -> 0.77777778 | M18: 15 | N18: 2 | P18: =SUM(M18:O18) -> 17 | Q18: 13 | R18: =P18/Q18 -> 1.3076923 | T18: =M18+G18+B18+N18+H18 -> 30 | U18: =O18+I18+C18 -> 0 | V18: =sum(S18:U18) -> 30 | W18: =E18+K18+Q18 -> 28 | X18: =W18-V18 -> -2 | Y18: =round(X18/$Y$26*7,0) -> 1 | Z18: =U18+T18 -> 30 | AA18: =W18 -> 28 | AB18: =(T18+U18)/W18 -> 1.0714286 | AC18: 46203 | AD18: GB
A19: WY CDA | B19: =sum(B16:B18) -> 43 | C19: =sum(C16:C18) -> 10 | D19: =sum(D16:D18) -> 53 | E19: =sum(E16:E18) -> 49 | F19: =D19/E19 -> 1.0816327 | G19: =sum(G16:G18) -> 65 | H19: =sum(H16:H18) -> 1 | I19: =sum(I16:I18) -> 6 | J19: =sum(J16:J18) -> 72 | K19: =sum(K16:K18) -> 62 | L19: =J19/K19 -> 1.1612903 | M19: =sum(M16:M18) -> 69 | N19: =sum(N16:N18) -> 7 | O19: =sum(O16:O18) -> 5 | P19: =sum(P16:P18) -> 81 | Q19: =sum(Q16:Q18) -> 106 | R19: =P19/Q19 -> 0.76415094 | S19: =sum(S16:S18) -> 0 | T19: =sum(T16:T18) -> 185 | U19: =sum(U16:U18) -> 21 | V19: =sum(V16:V18) -> 206 | W19: =sum(W16:W18) -> 217 | X19: =sum(X16:X18) -> 11 | Y19: =round(X19/Y26*7,0) -> -6 | Z19: =sum(Z16:Z18) -> 206 | AA19: =sum(AA16:AA18) -> 217 | AB19: =Z19/AA19 -> 0.94930876
A22: TOTAL | B22: =B19+B15+B10 -> 242 | C22: =C19+C15+C10 -> 20 | D22: =D19+D15+D10 -> 262 | E22: =E19+E15+E10 -> 212 | F22: =D22/E22 -> 1.2358491 | G22: =G19+G15+G10 -> 324 | H22: =H19+H15+H10 -> 1 | I22: =I19+I15+I10 -> 16 | J22: =J19+J15+J10 -> 341 | K22: =K19+K15+K10 -> 276 | L22: =J22/K22 -> 1.2355072 | M22: =M19+M15+M10 -> 365 | N22: =N19+N15+N10 -> 10 | O22: =O19+O15+O10 -> 18 | P22: =P19+P15+P10 -> 393 | Q22: =Q19+Q15+Q10 -> 474 | R22: =P22/Q22 -> 0.82911392 | S22: =S19+S15+S10 -> 0 | T22: =T19+T15+T10 -> 942 | U22: =U19+U15+U10 -> 54 | V22: =V19+V15+V10 -> 996 | W22: =W19+W15+W10 -> 962 | X22: =X19+X15+X10 -> -34 | Y22: =round(X22/Y26*7,0) -> 18 | Z22: =Z19+Z15+Z10 -> 996 | AA22: =AA19+AA15+AA10 -> 962 | AB22: =(T22+U22)/W22 -> 1.035343
Y24: 46203 | AA24: =AA22-Z22 -> -34
A25: REGISTRATIONS (NON-COUNTING) | S25: Updated | T25: By | Y25: =today() -> 46216
B26: APRIL | F26: MAY | J26: JUNE | O26: TOTAL | Y26: =Y24-Y25 -> -13
B27: Non-Counting Fleet (Reg) | C27: Non-Counting Fleet (Unreg) | D27: Total | E27: Budget | F27: Non-Counting Fleet (Reg) | G27: Non-Counting Fleet (Unreg) | H27: Total | I27: Budget | J27: Non-Counting Fleet (Reg) | K27: Non-Counting Fleet (Unreg) | L27: Total | M27: Budget | O27: Non-Counting Fleet (Reg) | P27: Non-Counting Fleet (Unreg) | Q27: Total | R27: Budget
A28: Salford | B28: 198 | C28: 0 | D28: =SUM(B28:C28) -> 198 | E28: 100 | F28: 128 | G28: 0 | H28: =SUM(F28:G28) -> 128 | I28: 100 | J28: 328 | K28: 0 | L28: 0 | M28: 157 | O28: =J28+F28+B28 -> 654 | P28: =K28+G28+C28 -> 0 | Q28: =P28+O28 -> 654 | R28: =M28+I28+E28 -> 357 | S28: 46203 | T28: GB | Z28: `
A29: NORTH CDA | B29: =sum(B28) -> 198 | C29: =sum(C28) -> 0 | D29: =sum(D28) -> 198 | E29: =sum(E28) -> 100 | F29: =sum(F28) -> 128 | G29: =sum(G28) -> 0 | H29: =sum(H28) -> 128 | I29: =sum(I28) -> 100 | ... M29: =sum(M28) -> 157 | O29: =sum(O28) -> 654 | P29: =sum(P28) -> 0 | Q29: =sum(Q28) -> 654 | R29: =sum(R28) -> 357
A30: Denton | B30: 27 | D30: =SUM(B30:C30) -> 27 | E30: 20 | F30: 8 | G30: 0 | H30: =SUM(F30:G30) -> 8 | I30: 20 | J30: 45 | K30: 0 | L30: =K30+J30 -> 45 | M30: 47 | O30: =J30+F30+B30 -> 80 | P30: =C30+G30+K30 -> 0 | Q30: =P30+O30 -> 80 | R30: =M30+I30+E30 -> 87 | S30: 46204 | T30: NF
A31: SOUTH CDA | B31: =sum(B30) -> 27 | C31: =sum(C30) -> 0 | D31: =sum(D30) -> 27 | E31: =sum(E30) -> 20 | F31: =sum(F30) -> 8 | G31: =sum(G30) -> 0 | H31: =sum(H30) -> 8 | I31: =sum(I30) -> 20 | ... M31: =sum(M30) -> 47 | O31: =sum(O30) -> 80 | P31: =sum(P30) -> 0 | Q31: =sum(Q30) -> 80 | R31: =sum(R30) -> 87
A32: Bradford | B32: 13 | C32: 0 | D32: =SUM(B32:C32) -> 13 | E32: 27 | F32: 237 | G32: 0 | H32: =SUM(F32:G32) -> 237 | I32: 45 | J32: 34 | K32: 0 | L32: =K32+J32 -> 34 | M32: 57 | O32: =J32+F32+B32 -> 284 | P32: =K32+G32+C32 -> 0 | Q32: =P32+O32 -> 284 | R32: =M32+I32+E32 -> 129 | S32: 46203 | T32: GB
A33: WY CDA | B33: =sum(B32) -> 13 | C33: =sum(C32) -> 0 | D33: =sum(D32) -> 13 | E33: =sum(E32) -> 27 | F33: =sum(F32) -> 237 | G33: =sum(G32) -> 0 | H33: =sum(H32) -> 237 | I33: =sum(I32) -> 45 | ... M33: =sum(M32) -> 57 | O33: =sum(O32) -> 284 | P33: =sum(P32) -> 0 | Q33: =sum(Q32) -> 284 | R33: =sum(R32) -> 129
A36: TOTAL | B36: =B33+B31+B29 -> 238 | C36: =C33+C31+C29 -> 0 | D36: =D33+D31+D29 -> 238 | E36: =E33+E31+E29 -> 147 | F36: =F33+F31+F29 -> 373 | G36: =G33+G31+G29 -> 0 | H36: =H33+H31+H29 -> 373 | I36: =I33+I31+I29 -> 165 | ... M36: =M33+M31+M29 -> 261 | O36: =O33+O31+O29 -> 1018 | P36: =P33+P31+P29 -> 0 | Q36: =Q33+Q31+Q29 -> 1018 | R36: =R33+R31+R29 -> 573
R38: =Q36/R36 -> 1.7766143
A40: USED COUNTING VOLUME | M40: Updated | N40: By
B41: APRIL | E41: MAY | H41: JUNE | K41: TOTAL
B42: Counting | C42: Target | E42: Counting | F42: Target | H42: Counting | I42: Target | K42: Counting | L42: Target
A43: Bolton | B43: 68 | C43: 59 | D43: =B43/C43 -> 1.1525424 | E43: 57 | F43: 59 | G43: =E43/F43 -> 0.96610169 | H43: 56 | I43: 62 | J43: =H43/I43 -> 0.90322581 | K43: =H43+E43+B43 -> 181 | L43: =I43+F43+C43 -> 180 | M43: 46203 | N43: GB
A44: Bury | B44: 59 | C44: 51 | D44: =B44/C44 -> 1.1568627 | E44: 42 | F44: 51 | G44: =E44/F44 -> 0.82352941 | H44: 42 | I44: 54 | J44: =H44/I44 -> 0.77777778 | K44: =H44+E44+B44 -> 143 | L44: =I44+F44+C44 -> 156 | M44: 46203 | N44: GB
A45: Rochdale | B45: 49 | C45: 47 | D45: =B45/C45 -> 1.0425532 | E45: 47 | F45: 47 | G45: =E45/F45 -> 1 | H45: 44 | I45: 50 | J45: =H45/I45 -> 0.88 | K45: =H45+E45+B45 -> 140 | L45: =I45+F45+C45 -> 144 | M45: 46203 | N45: GB
A46: SQ | B46: 59 | C46: 56 | D46: =B46/C46 -> 1.0535714 | E46: 52 | F46: 56 | G46: =E46/F46 -> 0.92857143 | H46: 49 | I46: 59 | J46: =H46/I46 -> 0.83050847 | K46: =H46+E46+B46 -> 160 | L46: =I46+F46+C46 -> 171 | M46: 46203 | N46: GB | O46: =K47/L47 -> 0.95852535 | Q46: =K47-L47 -> -27
A47: NORTH CDA | B47: =sum(B43:B46) -> 235 | C47: =sum(C43:C46) -> 213 | D47: =B47/C47 -> 1.1032864 | E47: =sum(E43:E46) -> 198 | F47: =sum(F43:F46) -> 213 | G47: =E47/F47 -> 0.92957746 | H47: =sum(H43:H46) -> 191 | I47: =sum(I43:I46) -> 225 | J47: =H47/I47 -> 0.84888889 | K47: =sum(K43:K46) -> 624 | L47: =sum(L43:L46) -> 651
A48: Altrincham | B48: 49 | C48: 47 | D48: =B48/C48 -> 1.0425532 | E48: 41 | F48: 47 | G48: =E48/F48 -> 0.87234043 | H48: 48 | I48: 50 | J48: =H48/I48 -> 0.96 | K48: =H48+E48+B48 -> 138 | L48: =I48+F48+C48 -> 144 | M48: 46204 | N48: NF
A49: Denton | B49: 41 | C49: 42 | D49: =B49/C49 -> 0.97619048 | E49: 42 | F49: 42 | G49: =E49/F49 -> 1 | H49: 39 | I49: 44 | J49: =H49/I49 -> 0.88636364 | K49: =H49+E49+B49 -> 122 | L49: =I49+F49+C49 -> 128 | M49: 46204 | N49: NF
...

Sheet 2026 - Q1
A3: REGISTRATIONS (COUNTING) | AE3: Updated | AF3: By
B4: JAN | G4: FEB | L4: MAR | S4: TOTAL
B5: Counting | C5: Counting Fleet | D5: Total | E5: Target | G5: Counting | H5: CLCP Regs | I5: Counting Fleet | J5: Total | K5: Target | L5: Counting | M5: CLCP Regs | N5: Counting Fleet | O5: Total | P5: Target | R5: B/FWD | S5: Counting | T5: Counting Fleet | U5: Total | V5: Target | W5: TO GO | X5: PER WEEK | Y5: QTR REGS | Z5: TARGET | AA5: REGS v TGT | AB5: BOOST VOUCHERS ALLOCATED | AC5: BOOST VOUCHERS USED | AD5: LEFT
A6: Bolton | B6: 25 | D6: =SUM(B6:C6) -> 25 | E6: 22 | F6: =D6/E6 -> 1.1363636 | G6: 10 | J6: =SUM(G6:I6) -> 10 | K6: 11 | L6: 80 | O6: =SUM(L6:N6) -> 80 | P6: 90 | Q6: =O6/P6 -> 0.88888889 | S6: =L6+G6+B6+M6+H6 -> 115 | T6: =N6+I6+C6 -> 0 | U6: =sum(R6:T6) -> 115 | V6: =E6+K6+P6 -> 123 | W6: =V6-U6 -> 8 | X6: =round(W6/$X$26*7,0) -> -1 | Y6: =T6+S6 -> 115 | Z6: =V6 -> 123 | AA6: =(S6+T6)/V6 -> 0.93495935 | AB6: 20 | AC6: 17 | AD6: =AB6-AC6 -> 3 | AE6: 46112 | AF6: gb | AG6: ALL TAXED
A7: Bury | B7: 17 | D7: =SUM(B7:C7) -> 17 | E7: 15 | F7: =D7/E7 -> 1.1333333 | G7: 7 | J7: =SUM(G7:I7) -> 7 | K7: 9 | L7: 71 | O7: =SUM(L7:N7) -> 71 | P7: 64 | Q7: =O7/P7 -> 1.109375 | S7: =L7+G7+B7+M7+H7 -> 95 | T7: =N7+I7+C7 -> 0 | U7: =sum(R7:T7) -> 95 | V7: =E7+K7+P7 -> 88 | W7: =V7-U7 -> -7 | X7: =round(W7/$X$26*7,0) -> 0 | Y7: =T7+S7 -> 95 | Z7: =V7 -> 88 | AA7: =(S7+T7)/V7 -> 1.0795455 | AB7: 15 | AC7: 15 | AD7: =AB7-AC7 -> 0 | AE7: 46112 | AF7: gb | AG7: ALL TAXED
A8: Rochdale | B8: 28 | D8: =SUM(B8:C8) -> 28 | E8: 16 | F8: =D8/E8 -> 1.75 | G8: 6 | J8: =SUM(G8:I8) -> 6 | K8: 9 | L8: 83 | O8: =SUM(L8:N8) -> 83 | P8: 74 | Q8: =O8/P8 -> 1.1216216 | S8: =L8+G8+B8+M8+H8 -> 117 | T8: =N8+I8+C8 -> 0 | U8: =sum(R8:T8) -> 117 | V8: =E8+K8+P8 -> 99 | W8: =V8-U8 -> -18 | X8: =round(W8/$X$26*7,0) -> 1 | Y8: =T8+S8 -> 117 | Z8: =V8 -> 99 | AA8: =(S8+T8)/V8 -> 1.1818182 | AB8: 20 | AC8: 20 | AD8: =AB8-AC8 -> 0 | AE8: 46112 | AF8: gb | AG8: ALL TAXED
A9: SQ | B9: 30 | C9: 9 | D9: =SUM(B9:C9) -> 39 | E9: 31 | F9: =D9/E9 -> 1.2580645 | G9: 25 | I9: 2 | J9: =SUM(G9:I9) -> 27 | K9: 15 | L9: 75 | N9: 7 | O9: =SUM(L9:N9) -> 82 | P9: 109 | Q9: =O9/P9 -> 0.75229358 | S9: =L9+G9+B9+M9+H9 -> 130 | T9: =N9+I9+C9 -> 18 | U9: =sum(R9:T9) -> 148 | V9: =E9+K9+P9 -> 155 | W9: =V9-U9 -> 7 | X9: =round(W9/$X$26*7,0) -> 0 | Y9: =T9+S9 -> 148 | Z9: =V9 -> 155 | AA9: =(S9+T9)/V9 -> 0.95483871 | AB9: 30 | AC9: 30 | AD9: =AB9-AC9 -> 0 | AE9: 46112 | AF9: gb | AG9: ALL TAXED
A10: NORTH CDA | B10: =sum(B6:B9) -> 100 | C10: =sum(C6:C9) -> 9 | D10: =sum(D6:D9) -> 109 | E10: =sum(E6:E9) -> 84 | F10: =D10/E10 -> 1.297619 | G10: =sum(G6:G9) -> 48 | H10: =sum(H6:H9) -> 0 | I10: =sum(I6:I9) -> 2 | J10: =sum(J6:J9) -> 50 | K10: =sum(K6:K9) -> 44 | L10: =sum(L6:L9) -> 309 | M10: =sum(M6:M9) -> 0 | N10: =sum(N6:N9) -> 7 | ... P10: =sum(P6:P9) -> 337 | Q10: =O10/P10 -> 0.93768546 | R10: =sum(R6:R9) -> 0 | S10: =sum(S6:S9) -> 457 | T10: =sum(T6:T9) -> 18 | U10: =sum(U6:U9) -> 475 | V10: =sum(V6:V9) -> 465 | W10: =sum(W6:W9) -> -10 | X10: =round(W10/X26*7,0) -> 1 | Y10: =sum(Y6:Y9) -> 475 | Z10: =sum(Z6:Z9) -> 465 | AA10: =Y10/Z10 -> 1.0215054 | AB10: =sum(AB6:AB9) -> 85 | AC10: =sum(AC6:AC9) -> 82 | AD10: =sum(AD6:AD9) -> 3
A11: Altrincham | B11: 20 | D11: =SUM(B11:C11) -> 20 | E11: 16 | F11: =D11/E11 -> 1.25 | G11: 14 | J11: =SUM(G11:I11) -> 14 | K11: 9 | L11: 58 | N11: 1 | O11: =SUM(L11:N11) -> 59 | P11: 68 | Q11: =O11/P11 -> 0.86764706 | S11: =L11+G11+B11+M11+H11 -> 92 | T11: =N11+I11+C11 -> 1 | U11: =sum(R11:T11) -> 93 | V11: =E11+K11+P11 -> 93 | W11: =V11-U11 -> 0 | X11: =round(W11/$X$26*7,0) -> 0 | Y11: =T11+S11 -> 93 | Z11: =V11 -> 93 | AA11: =(S11+T11)/V11 -> 1 | AB11: 15 | AC11: 15 | AD11: =AB11-AC11 -> 0 | AE11: 46112 | AF11: NF | AG11: ALL TAXED
A12: Denton | B12: 21 | C12: 2 | D12: =SUM(B12:C12) -> 23 | E12: 17 | F12: =D12/E12 -> 1.3529412 | G12: 16 | I12: 0 | J12: =SUM(G12:I12) -> 16 | K12: 9 | L12: 60 | N12: 3 | O12: =SUM(L12:N12) -> 63 | P12: 76 | Q12: =O12/P12 -> 0.82894737 | S12: =L12+G12+B12+M12+H12 -> 97 | T12: =N12+I12+C12 -> 5 | U12: =sum(R12:T12) -> 102 | V12: =E12+K12+P12 -> 102 | W12: =V12-U12 -> 0 | X12: =round(W12/$X$26*7,0) -> 0 | Y12: =T12+S12 -> 102 | Z12: =V12 -> 102 | AA12: =(S12+T12)/V12 -> 1 | AB12: 20 | AC12: 20 | AD12: =AB12-AC12 -> 0 | AE12: 46112 | AF12: NF | AG12: ALL TAXED
A13: Macclesfield | B13: 19 | D13: =SUM(B13:C13) -> 19 | E13: 18 | F13: =D13/E13 -> 1.0555556 | G13: 11 | J13: =SUM(G13:I13) -> 11 | K13: 9 | L13: 89 | O13: =SUM(L13:N13) -> 89 | P13: 75 | Q13: =O13/P13 -> 1.1866667 | S13: 119 | T13: =N13+I13+C13 -> 0 | U13: =sum(R13:T13) -> 119 | V13: =E13+K13+P13 -> 102 | W13: =V13-U13 -> -17 | X13: =round(W13/$X$26*7,0) -> 1 | Y13: =T13+S13 -> 119 | Z13: =V13 -> 102 | AA13: =(S13+T13)/V13 -> 1.1666667 | AB13: 20 | AC13: 20 | AD13: =AB13-AC13 -> 0 | AE13: 46112 | AF13: NF | AG13: ALL TAXED
A14: Stockport | B14: 46 | D14: =SUM(B14:C14) -> 46 | E14: 31 | F14: =D14/E14 -> 1.483871 | G14: 8 | J14: =SUM(G14:I14) -> 8 | K14: 15 | L14: 103 | O14: =SUM(L14:N14) -> 103 | P14: 117 | Q14: =O14/P14 -> 0.88034188 | S14: =L14+G14+B14+M14+H14 -> 157 | T14: =N14+I14+C14 -> 0 | U14: =sum(R14:T14) -> 157 | V14: =E14+K14+P14 -> 163 | W14: =V14-U14 -> 6 | X14: =round(W14/$X$26*7,0) -> 0 | Y14: =T14+S14 -> 157 | Z14: =V14 -> 163 | AA14: =(S14+T14)/V14 -> 0.96319018 | AB14: 30 | AC14: 30 | AD14: =AB14-AC14 -> 0 | AE14: 46112 | AF14: NF | AG14: ALL TAXED
A15: SOUTH CDA | B15: =sum(B11:B14) -> 106 | C15: =sum(C11:C14) -> 2 | D15: =sum(D11:D14) -> 108 | E15: =sum(E11:E14) -> 82 | F15: =D15/E15 -> 1.3170732 | G15: =sum(G11:G14) -> 49 | H15: =sum(H11:H14) -> 0 | I15: =sum(I11:I14) -> 0 | J15: =sum(J11:J14) -> 49 | K15: =sum(K11:K14) -> 42 | L15: =sum(L11:L14) -> 310 | M15: =sum(M11:M14) -> 0 | N15: =sum(N11:N14) -> 4 | ... P15: =sum(P11:P14) -> 336 | Q15: =O15/P15 -> 0.93452381 | R15: =sum(R11:R14) -> 0 | S15: =sum(S11:S14) -> 465 | T15: =sum(T11:T14) -> 6 | U15: =sum(U11:U14) -> 471 | V15: =sum(V11:V14) -> 460 | W15: =sum(W11:W14) -> -11 | X15: =round(W15/X26*7,0) -> 1 | Y15: =sum(Y11:Y14) -> 471 | Z15: =sum(Z11:Z14) -> 460 | AA15: =Y15/Z15 -> 1.023913 | AB15: =sum(AB11:AB14) -> 85 | AC15: =sum(AC11:AC14) -> 85 | AD15: =sum(AD11:AD14) -> 0
A16: Bradford | B16: 13 | C16: 4 | D16: =SUM(B16:C16) -> 17 | E16: 22 | F16: =D16/E16 -> 0.77272727 | G16: 9 | I16: 2 | J16: =SUM(G16:I16) -> 11 | K16: 9 | L16: 55 | N16: 9 | O16: =SUM(L16:N16) -> 64 | P16: 82 | Q16: =O16/P16 -> 0.7804878 | S16: =L16+G16+B16+M16+H16 -> 77 | T16: =N16+I16+C16 -> 15 | U16: =sum(R16:T16) -> 92 | V16: =E16+K16+P16 -> 113 | W16: =V16-U16 -> 21 | X16: =round(W16/$X$26*7,0) -> -1 | Y16: =T16+S16 -> 92 | Z16: =V16 -> 113 | AA16: =(S16+T16)/V16 -> 0.81415929 | AB16: 20 | AC16: 20 | AE16: 46112 | AF16: PS | AG16: ALL TAXED
A17: Huddersfield | B17: 23 | C17: 1 | D17: =SUM(B17:C17) -> 24 | E17: 21 | F17: =D17/E17 -> 1.1428571 | G17: 8 | I17: 1 | J17: =SUM(G17:I17) -> 9 | K17: 11 | L17: 86 | N17: 1 | O17: =SUM(L17:N17) -> 87 | P17: 86 | Q17: =O17/P17 -> 1.0116279 | S17: =L17+G17+B17+M17+H17 -> 117 | T17: =N17+I17+C17 -> 3 | U17: =sum(R17:T17) -> 120 | V17: =E17+K17+P17 -> 118 | W17: =V17-U17 -> -2 | X17: =round(W17/$X$26*7,0) -> 0 | Y17: =T17+S17 -> 120 | Z17: =V17 -> 118 | AA17: =(S17+T17)/V17 -> 1.0169492 | AB17: 20 | AC17: 20 | AD17: =AB17-AC17 -> 0 | AE17: 46112 | AF17: PS | AG17: ALL TAXED
A18: Silsden | B18: 15 | D18: =SUM(B18:C18) -> 15 | E18: 9 | F18: =D18/E18 -> 1.6666667 | G18: 13 | J18: =SUM(G18:I18) -> 13 | K18: 3 | L18: 26 | O18: =SUM(L18:N18) -> 26 | P18: 31 | Q18: =O18/P18 -> 0.83870968 | S18: =L18+G18+B18+M18+H18 -> 54 | T18: =N18+I18+C18 -> 0 | U18: =sum(R18:T18) -> 54 | V18: =E18+K18+P18 -> 43 | W18: =V18-U18 -> -11 | X18: =round(W18/$X$26*7,0) -> 1 | Y18: =T18+S18 -> 54 | Z18: =V18 -> 43 | AA18: =(S18+T18)/V18 -> 1.255814 | AB18: 5 | AC18: 5 | AD18: =AB18-AC18 -> 0 | AE18: 46112 | AF18: PS | AG18: ALL TAXED
A19: WY CDA | B19: =sum(B16:B18) -> 51 | C19: =sum(C16:C18) -> 5 | D19: =sum(D16:D18) -> 56 | E19: =sum(E16:E18) -> 52 | F19: =D19/E19 -> 1.0769231 | G19: =sum(G16:G18) -> 30 | H19: =sum(H16:H18) -> 0 | I19: =sum(I16:I18) -> 3 | J19: =sum(J16:J18) -> 33 | K19: =sum(K16:K18) -> 23 | L19: =sum(L16:L18) -> 167 | M19: =sum(M16:M18) -> 0 | N19: =sum(N16:N18) -> 10 | ... P19: =sum(P16:P18) -> 199 | Q19: =O19/P19 -> 0.88944724 | R19: =sum(R16:R18) -> 0 | S19: =sum(S16:S18) -> 248 | T19: =sum(T16:T18) -> 18 | U19: =sum(U16:U18) -> 266 | V19: =sum(V16:V18) -> 274 | W19: =sum(W16:W18) -> 8 | X19: =round(W19/X26*7,0) -> -1 | Y19: =sum(Y16:Y18) -> 266 | Z19: =sum(Z16:Z18) -> 274 | AA19: =Y19/Z19 -> 0.97080292 | AB19: =sum(AB16:AB18) -> 45 | AC19: =sum(AC16:AC18) -> 45 | AD19: =sum(AD16:AD18) -> 0
AD20: =AB20-AC20 -> 0
AD21: =AB21-AC21 -> 0
A22: TOTAL | B22: =B19+B15+B10 -> 257 | C22: =C19+C15+C10 -> 16 | D22: =D19+D15+D10 -> 273 | E22: =E19+E15+E10 -> 218 | F22: =D22/E22 -> 1.2522936 | G22: =G19+G15+G10 -> 127 | H22: =H19+H15+H10 -> 0 | I22: =I19+I15+I10 -> 5 | J22: =J19+J15+J10 -> 132 | K22: =K19+K15+K10 -> 109 | L22: =L19+L15+L10 -> 786 | M22: =M19+M15+M10 -> 0 | N22: =N19+N15+N10 -> 21 | ... P22: =P19+P15+P10 -> 872 | Q22: =O22/P22 -> 0.92545872 | R22: =R19+R15+R10 -> 0 | S22: =S19+S15+S10 -> 1170 | T22: =T19+T15+T10 -> 42 | U22: =U19+U15+U10 -> 1212 | V22: =V19+V15+V10 -> 1199 | W22: =W19+W15+W10 -> -13 | X22: =round(W22/X26*7,0) -> 1 | Y22: =Y19+Y15+Y10 -> 1212 | Z22: =Z19+Z15+Z10 -> 1199 | AA22: =(S22+T22)/V22 -> 1.0108424 | AB22: =AB19+AB15+AB10 -> 215 | AC22: =AC19+AC15+AC10 -> 212 | AD22: =AD19+AD15+AD10 -> 3
AB23: =AB22*250 -> 53750 | AC23: =AC22*250 -> 53000 | AD23: =AD22*250 -> 750
X24: 46112 | Z24: =Z22-Y22 -> -13
X25: =today() -> 46216
A26: REGISTRATIONS (NON-COUNTING) | U26: Updated | V26: By | X26: =X24-X25 -> -104
B27: ='2026 - Q1'!B4 -> JAN | F27: ='2026 - Q1'!G4 -> FEB | J27: ='2026 - Q1'!L4 -> MAR | O27: TOTAL
B28: Non-Counting Fleet (Reg) | C28: Non-Counting Fleet (Unreg) | D28: Total | E28: Budget | F28: Non-Counting Fleet (Reg) | G28: Non-Counting Fleet (Unreg) | H28: Total | I28: Budget | J28: Non-Counting Fleet (Reg) | K28: Non-Counting Fleet (Unreg) | L28: Total | M28: Budget | O28: Non-Counting Fleet (Reg) | P28: Non-Counting Fleet (Unreg) | Q28: Total | R28: Budget | Y28: `
A29: Salford | B29: 124 | C29: 0 | D29: =SUM(B29:C29) -> 124 | E29: 134 | F29: 55 | G29: 0 | H29: =SUM(F29:G29) -> 55 | I29: 78 | J29: 230 | K29: 0 | L29: 0 | M29: 315 | O29: =J29+F29+B29 -> 409 | P29: =K29+G29+C29 -> 0 | Q29: =P29+O29 -> 409 | R29: =M29+I29+E29 -> 527 | U29: 46112 | V29: gb | W29: ALL TAXED
A30: NORTH CDA | B30: =sum(B29) -> 124 | C30: =sum(C29) -> 0 | D30: =sum(D29) -> 124 | E30: =sum(E29) -> 134 | F30: =sum(F29) -> 55 | G30: =sum(G29) -> 0 | H30: =sum(H29) -> 55 | I30: =sum(I29) -> 78 | ... M30: =sum(M29) -> 315 | O30: =sum(O29) -> 409 | P30: =sum(P29) -> 0 | Q30: =sum(Q29) -> 409 | R30: =sum(R29) -> 527
A31: Denton | B31: 29 | C31: 0 | D31: =SUM(B31:C31) -> 29 | E31: 26 | F31: 16 | H31: 20 | I31: 15 | J31: 42 | K31: 0 | L31: =K31+J31 -> 42 | M31: 72 | O31: =J31+F31+B31 -> 87 | P31: =C31+G31+K31 -> 0 | Q31: =P31+O31 -> 87 | R31: =M31+I31+E31 -> 113 | U31: 46112 | V31: NF | W31: ALL TAXED
A32: SOUTH CDA | B32: =sum(B31) -> 29 | C32: =sum(C31) -> 0 | D32: =sum(D31) -> 29 | E32: =sum(E31) -> 26 | F32: =sum(F31) -> 16 | G32: =sum(G31) -> 0 | H32: =sum(H31) -> 20 | I32: =sum(I31) -> 15 | ... M32: =sum(M31) -> 72 | O32: =sum(O31) -> 87 | P32: =sum(P31) -> 0 | Q32: =sum(Q31) -> 87 | R32: =sum(R31) -> 113
A33: Bradford | B33: 34 | C33: 0 | D33: =SUM(B33:C33) -> 34 | E33: 20 | F33: 89 | G33: 0 | H33: =SUM(F33:G33) -> 89 | I33: 12 | J33: 110 | K33: 0 | L33: =K33+J33 -> 110 | M33: 79 | O33: =J33+F33+B33 -> 233 | P33: =K33+G33+C33 -> 0 | Q33: =P33+O33 -> 233 | R33: =M33+I33+E33 -> 111 | U33: 31/032 | V33: PS | W33: ALL TAXED
A34: WY CDA | B34: =sum(B33) -> 34 | C34: =sum(C33) -> 0 | D34: =sum(D33) -> 34 | E34: =sum(E33) -> 20 | F34: =sum(F33) -> 89 | G34: =sum(G33) -> 0 | H34: =sum(H33) -> 89 | I34: =sum(I33) -> 12 | ... M34: =sum(M33) -> 79 | O34: =sum(O33) -> 233 | P34: =sum(P33) -> 0 | Q34: =sum(Q33) -> 233 | R34: =sum(R33) -> 111
A37: TOTAL | B37: =B34+B32+B30 -> 187 | C37: =C34+C32+C30 -> 0 | D37: =D34+D32+D30 -> 187 | E37: =E34+E32+E30 -> 180 | F37: =F34+F32+F30 -> 160 | G37: =G34+G32+G30 -> 0 | H37: =H34+H32+H30 -> 164 | I37: =I34+I32+I30 -> 105 | ... M37: =M34+M32+M30 -> 466 | O37: =O34+O32+O30 -> 729 | P37: =P34+P32+P30 -> 0 | Q37: =Q34+Q32+Q30 -> 729 | R37: =R34+R32+R30 -> 751
A41: USED COUNTING VOLUME | N41: By
E42: ='2026 - Q1'!F27 -> FEB | I42: ='2026 - Q1'!J27 -> MAR | L42: TOTAL
B43: Counting | C43: Target | E43: Counting | F43: Target | I43: Counting | J43: Target | L43: Counting | M43: Target
A44: Bolton | B44: 53 | C44: 66 | D44: =B44/C44 -> 0.8030303 | E44: 67 | F44: 61 | G44: =E44/F44 -> 1.0983607 | I44: 58 | J44: 64 | K44: =I44/J44 -> 0.90625 | L44: =I44+E44+B44 -> 178 | M44: =J44+F44+C44 -> 191 | N44: gb | O44: 46112
A45: Bury | B45: 40 | C45: 57 | D45: =B45/C45 -> 0.70175439 | E45: 39 | F45: 53 | G45: =E45/F45 -> 0.73584906 | I45: 47 | J45: 56 | K45: =I45/J45 -> 0.83928571 | L45: =I45+E45+B45 -> 126 | M45: =J45+F45+C45 -> 166 | N45: gb | O45: 46112
A46: Rochdale | B46: 48 | C46: 53 | D46: =B46/C46 -> 0.90566038 | E46: 56 | F46: 50 | G46: =E46/F46 -> 1.12 | I46: 54 | J46: 51 | K46: =I46/J46 -> 1.0588235 | L46: =I46+E46+B46 -> 158 | M46: =J46+F46+C46 -> 154 | N46: gb | O46: 46112
A47: SQ | B47: 55 | C47: 63 | D47: =B47/C47 -> 0.87301587 | E47: 46 | F47: 59 | G47: =E47/F47 -> 0.77966102 | I47: 61 | J47: 61 | K47: =I47/J47 -> 1 | L47: =I47+E47+B47 -> 162 | M47: =J47+F47+C47 -> 183 | N47: gb | O47: 46112
...

Sheet 2025 - Q4
A3: REGISTRATIONS (COUNTING) | AE3: Updated | AF3: By
C4: OCT | H4: NOV | N4: DEC | V4: TOTAL
B5: B/FWD | C5: Counting | D5: Counting Fleet | E5: Total | F5: Target | H5: Counting | I5: CLCP Regs | J5: Counting Fleet | K5: Total | L5: Target | N5: Counting | O5: CLCP Regs | P5: Double Counters | Q5: Counting Fleet | R5: Total | S5: Target | U5: B/FWD | V5: Counting | W5: Counting Fleet | X5: Total | Y5: Target | Z5: TO GO | AA5: PER WEEK | AB5: QTR REGS | AC5: TARGET | AD5: REGS v TGT
A6: Bolton | C6: 24 | E6: =SUM(C6:D6) -> 24 | F6: 31 | G6: =E6/F6 -> 0.77419355 | H6: 26 | I6: 4 | K6: =SUM(H6:J6) -> 30 | L6: 29 | M6: =K6/L6 -> 1.0344828 | N6: 21 | O6: 2 | R6: =SUM(N6:Q6) -> 23 | S6: 30 | T6: =R6/S6 -> 0.76666667 | V6: =N6+H6+C6+O6+P6+I6 -> 77 | W6: =Q6+J6+D6 -> 0 | X6: =sum(U6:W6) -> 77 | Y6: =S6+L6+F6 -> 90 | Z6: =Y6-X6 -> 13 | AA6: =round(Z6/$AA$26*7,0) -> 0 | AB6: =W6+V6 -> 77 | AC6: =Y6 -> 90 | AD6: =(V6+W6)/Y6 -> 0.85555556 | AE6: 46024 | AF6: gb
A7: Bury | C7: 26 | E7: =SUM(C7:D7) -> 26 | F7: 26 | G7: =E7/F7 -> 1 | H7: 20 | I7: 3 | K7: =SUM(H7:J7) -> 23 | L7: 26 | M7: =K7/L7 -> 0.88461538 | N7: 13 | O7: 1 | R7: =SUM(N7:Q7) -> 14 | S7: 25 | T7: =R7/S7 -> 0.56 | V7: =N7+H7+C7+O7+P7+I7 -> 63 | W7: =Q7+J7+D7 -> 0 | X7: =sum(U7:W7) -> 63 | Y7: =S7+L7+F7 -> 77 | Z7: =Y7-X7 -> 14 | AA7: =round(Z7/$AA$26*7,0) -> -1 | AB7: =W7+V7 -> 63 | AC7: =Y7 -> 77 | AD7: =(V7+W7)/Y7 -> 0.81818182 | AE7: 46024 | AF7: gb
A8: Rochdale | C8: 24 | D8: 2 | E8: =SUM(C8:D8) -> 26 | F8: 35 | G8: =E8/F8 -> 0.74285714 | H8: 14 | I8: 3 | K8: =SUM(H8:J8) -> 17 | L8: 31 | M8: =K8/L8 -> 0.5483871 | N8: 18 | O8: 1 | R8: =SUM(N8:Q8) -> 19 | S8: 30 | T8: =R8/S8 -> 0.63333333 | V8: =N8+H8+C8+O8+P8+I8 -> 60 | W8: =Q8+J8+D8 -> 2 | X8: =sum(U8:W8) -> 62 | Y8: =S8+L8+F8 -> 96 | Z8: =Y8-X8 -> 34 | AA8: =round(Z8/$AA$26*7,0) -> -1 | AB8: =W8+V8 -> 62 | AC8: =Y8 -> 96 | AD8: =(V8+W8)/Y8 -> 0.64583333 | AE8: 46024 | AF8: gb
A9: SQ | C9: 49 | D9: 6 | E9: =SUM(C9:D9) -> 55 | F9: 40 | G9: =E9/F9 -> 1.375 | H9: 37 | I9: 6 | K9: =SUM(H9:J9) -> 43 | L9: 38 | M9: =K9/L9 -> 1.1315789 | N9: 36 | O9: 3 | R9: =SUM(N9:Q9) -> 39 | S9: 39 | T9: =R9/S9 -> 1 | V9: =N9+H9+C9+O9+P9+I9 -> 131 | W9: =Q9+J9+D9 -> 6 | X9: =sum(U9:W9) -> 137 | Y9: =S9+L9+F9 -> 117 | Z9: =Y9-X9 -> -20 | AA9: =round(Z9/$AA$26*7,0) -> 1 | AB9: =W9+V9 -> 137 | AC9: =Y9 -> 117 | AD9: =(V9+W9)/Y9 -> 1.1709402 | AE9: 46024 | AF9: gb
A10: NORTH CDA | B10: =sum(B6:B9) -> 0 | C10: =sum(C6:C9) -> 123 | D10: =sum(D6:D9) -> 8 | E10: =sum(E6:E9) -> 131 | F10: =sum(F6:F9) -> 132 | G10: =E10/F10 -> 0.99242424 | H10: =sum(H6:H9) -> 97 | I10: =sum(I6:I9) -> 16 | J10: =sum(J6:J9) -> 0 | K10: =sum(K6:K9) -> 113 | L10: =sum(L6:L9) -> 124 | M10: =K10/L10 -> 0.91129032 | N10: =sum(N6:N9) -> 88 | O10: =sum(O6:O9) -> 7 | P10: =sum(P6:P9) -> 0 | Q10: =sum(Q6:Q9) -> 0 | R10: =sum(R6:R9) -> 95 | S10: =sum(S6:S9) -> 124 | T10: =R10/S10 -> 0.76612903 | U10: =sum(U6:U9) -> 0 | V10: =sum(V6:V9) -> 331 | W10: =sum(W6:W9) -> 8 | X10: =sum(X6:X9) -> 339 | Y10: =sum(Y6:Y9) -> 380 | Z10: =sum(Z6:Z9) -> 41 | AA10: =round(Z10/$AA$26*7,0) -> -1 | AB10: =sum(AB6:AB9) -> 339 | AC10: =sum(AC6:AC9) -> 380 | AD10: =AB10/AC10 -> 0.89210526
A11: Altrincham | C11: 23 | E11: =SUM(C11:D11) -> 23 | F11: 30 | G11: =E11/F11 -> 0.76666667 | H11: 18 | I11: 4 | K11: =SUM(H11:J11) -> 22 | L11: 24 | M11: =K11/L11 -> 0.91666667 | N11: 17 | O11: 1 | R11: =SUM(N11:Q11) -> 18 | S11: 22 | T11: =R11/S11 -> 0.81818182 | V11: =N11+H11+C11+O11+P11+I11 -> 63 | W11: =Q11+J11+D11 -> 0 | X11: =sum(U11:W11) -> 63 | Y11: =S11+L11+F11 -> 76 | Z11: =Y11-X11 -> 13 | AA11: =round(Z11/$AA$26*7,0) -> 0 | AB11: =W11+V11 -> 63 | AC11: =Y11 -> 76 | AD11: =(V11+W11)/Y11 -> 0.82894737 | AE11: 46022 | AF11: NF
A12: Denton | C12: 18 | D12: 2 | E12: =SUM(C12:D12) -> 20 | F12: 29 | G12: =E12/F12 -> 0.68965517 | H12: 41 | I12: 4 | K12: =SUM(H12:J12) -> 45 | L12: 30 | M12: =K12/L12 -> 1.5 | N12: 16 | O12: 3 | R12: =SUM(N12:Q12) -> 19 | S12: 28 | T12: =R12/S12 -> 0.67857143 | V12: =N12+H12+C12+O12+P12+I12 -> 82 | W12: =Q12+J12+D12 -> 2 | X12: =sum(U12:W12) -> 84 | Y12: =S12+L12+F12 -> 87 | Z12: =Y12-X12 -> 3 | AA12: =round(Z12/$AA$26*7,0) -> 0 | AB12: =W12+V12 -> 84 | AC12: =Y12 -> 87 | AD12: =(V12+W12)/Y12 -> 0.96551724 | AE12: 46022 | AF12: NF
A13: Macclesfield | C13: 16 | E13: =SUM(C13:D13) -> 16 | F13: 34 | G13: =E13/F13 -> 0.47058824 | H13: 27 | I13: 4 | K13: =SUM(H13:J13) -> 31 | L13: 29 | M13: =K13/L13 -> 1.0689655 | N13: 16 | O13: 1 | R13: =SUM(N13:Q13) -> 17 | S13: 27 | T13: =R13/S13 -> 0.62962963 | V13: =N13+H13+C13+O13+P13+I13 -> 64 | W13: =Q13+J13+D13 -> 0 | X13: =sum(U13:W13) -> 64 | Y13: =S13+L13+F13 -> 90 | Z13: =Y13-X13 -> 26 | AA13: =round(Z13/$AA$26*7,0) -> -1 | AB13: =W13+V13 -> 64 | AC13: =Y13 -> 90 | AD13: =(V13+W13)/Y13 -> 0.71111111 | AE13: 46022 | AF13: NF
A14: Stockport | C14: 40 | E14: =SUM(C14:D14) -> 40 | F14: 43 | G14: =E14/F14 -> 0.93023256 | H14: 36 | I14: 4 | K14: =SUM(H14:J14) -> 40 | L14: 43 | M14: =K14/L14 -> 0.93023256 | N14: 32 | O14: 2 | R14: =SUM(N14:Q14) -> 34 | S14: 42 | T14: =R14/S14 -> 0.80952381 | V14: =N14+H14+C14+O14+P14+I14 -> 114 | W14: =Q14+J14+D14 -> 0 | X14: =sum(U14:W14) -> 114 | Y14: =S14+L14+F14 -> 128 | Z14: =Y14-X14 -> 14 | AA14: =round(Z14/$AA$26*7,0) -> -1 | AB14: =W14+V14 -> 114 | AC14: =Y14 -> 128 | AD14: =(V14+W14)/Y14 -> 0.890625 | AE14: 46022 | AF14: NF
A15: SOUTH CDA | B15: =sum(B11:B14) -> 0 | C15: =sum(C11:C14) -> 97 | D15: =sum(D11:D14) -> 2 | E15: =sum(E11:E14) -> 99 | F15: =sum(F11:F14) -> 136 | G15: =E15/F15 -> 0.72794118 | H15: =sum(H11:H14) -> 122 | I15: =sum(I11:I14) -> 16 | J15: =sum(J11:J14) -> 0 | K15: =sum(K11:K14) -> 138 | L15: =sum(L11:L14) -> 126 | M15: =K15/L15 -> 1.0952381 | N15: =sum(N11:N14) -> 81 | O15: =sum(O11:O14) -> 7 | P15: =sum(P11:P14) -> 0 | Q15: =sum(Q11:Q14) -> 0 | R15: =sum(R11:R14) -> 88 | S15: =sum(S11:S14) -> 119 | T15: =R15/S15 -> 0.7394958 | U15: =sum(U11:U14) -> 0 | V15: =sum(V11:V14) -> 323 | W15: =sum(W11:W14) -> 2 | X15: =sum(X11:X14) -> 325 | Y15: =sum(Y11:Y14) -> 381 | Z15: =sum(Z11:Z14) -> 56 | AA15: =round(Z15/$AA$26*7,0) -> -2 | AB15: =sum(AB11:AB14) -> 325 | AC15: =sum(AC11:AC14) -> 381 | AD15: =AB15/AC15 -> 0.85301837
A16: Bradford | C16: 18 | D16: 5 | E16: =SUM(C16:D16) -> 23 | F16: 30 | G16: =E16/F16 -> 0.76666667 | H16: 28 | I16: 3 | J16: 3 | K16: =SUM(H16:J16) -> 34 | L16: 33 | M16: =K16/L16 -> 1.030303 | N16: 14 | O16: 4 | Q16: 12 | R16: =SUM(N16:Q16) -> 30 | S16: 30 | T16: =R16/S16 -> 1 | V16: =N16+H16+C16+O16+P16+I16 -> 67 | W16: =Q16+J16+D16 -> 20 | X16: =sum(U16:W16) -> 87 | Y16: =S16+L16+F16 -> 93 | Z16: =Y16-X16 -> 6 | AA16: =round(Z16/$AA$26*7,0) -> 0 | AB16: =W16+V16 -> 87 | AC16: =Y16 -> 93 | AD16: =(V16+W16)/Y16 -> 0.93548387 | AE16: 46022 | AF16: PS
A17: Huddersfield | C17: 39 | E17: =SUM(C17:D17) -> 39 | F17: 28 | G17: =E17/F17 -> 1.3928571 | H17: 18 | I17: 2 | J17: 3 | K17: =SUM(H17:J17) -> 23 | L17: 27 | M17: =K17/L17 -> 0.85185185 | N17: 21 | O17: 1 | Q17: 4 | R17: =SUM(N17:Q17) -> 26 | S17: 25 | T17: =R17/S17 -> 1.04 | V17: =N17+H17+C17+O17+P17+I17 -> 81 | W17: =Q17+J17+D17 -> 7 | X17: =sum(U17:W17) -> 88 | Y17: =S17+L17+F17 -> 80 | Z17: =Y17-X17 -> -8 | AA17: =round(Z17/$AA$26*7,0) -> 0 | AB17: =W17+V17 -> 88 | AC17: =Y17 -> 80 | AD17: =(V17+W17)/Y17 -> 1.1 | AE17: 46022 | AF17: PS
A18: Silsden | C18: 12 | E18: =SUM(C18:D18) -> 12 | F18: 13 | G18: =E18/F18 -> 0.92307692 | H18: 9 | I18: 3 | K18: =SUM(H18:J18) -> 12 | L18: 10 | M18: =K18/L18 -> 1.2 | N18: 5 | O18: 1 | Q18: 1 | R18: =SUM(N18:Q18) -> 7 | S18: 10 | T18: =R18/S18 -> 0.7 | V18: =N18+H18+C18+O18+P18+I18 -> 30 | W18: =Q18+J18+D18 -> 1 | X18: =sum(U18:W18) -> 31 | Y18: =S18+L18+F18 -> 33 | Z18: =Y18-X18 -> 2 | AA18: =round(Z18/$AA$26*7,0) -> 0 | AB18: =W18+V18 -> 31 | AC18: =Y18 -> 33 | AD18: =(V18+W18)/Y18 -> 0.93939394 | AE18: 46020 | AF18: PS
A19: WY CDA | B19: =sum(B16:B18) -> 0 | C19: =sum(C16:C18) -> 69 | D19: =sum(D16:D18) -> 5 | E19: =sum(E16:E18) -> 74 | F19: =sum(F16:F18) -> 71 | G19: =E19/F19 -> 1.0422535 | H19: =sum(H16:H18) -> 55 | I19: =sum(I16:I18) -> 8 | J19: =sum(J16:J18) -> 6 | K19: =sum(K16:K18) -> 69 | L19: =sum(L16:L18) -> 70 | M19: =K19/L19 -> 0.98571429 | N19: =sum(N16:N18) -> 40 | O19: =sum(O16:O18) -> 6 | P19: =sum(P16:P18) -> 0 | Q19: =sum(Q16:Q18) -> 17 | R19: =sum(R16:R18) -> 63 | S19: =sum(S16:S18) -> 65 | T19: =R19/S19 -> 0.96923077 | U19: =sum(U16:U18) -> 0 | V19: =sum(V16:V18) -> 178 | W19: =sum(W16:W18) -> 28 | X19: =sum(X16:X18) -> 206 | Y19: =sum(Y16:Y18) -> 206 | Z19: =sum(Z16:Z18) -> 0 | AA19: =round(Z19/$AA$26*7,0) -> 0 | AB19: =sum(AB16:AB18) -> 206 | AC19: =sum(AC16:AC18) -> 206 | AD19: =AB19/AC19 -> 1
A22: TOTAL | B22: =B19+B15+B10 -> 0 | C22: =C19+C15+C10 -> 289 | D22: =D19+D15+D10 -> 15 | E22: =E19+E15+E10 -> 304 | F22: =F19+F15+F10 -> 339 | G22: =E22/F22 -> 0.89675516 | H22: =H19+H15+H10 -> 274 | I22: =I19+I15+I10 -> 40 | J22: =J19+J15+J10 -> 6 | K22: =K19+K15+K10 -> 320 | L22: =L19+L15+L10 -> 320 | M22: =K22/L22 -> 1 | N22: =N19+N15+N10 -> 209 | O22: =O19+O15+O10 -> 20 | P22: =P19+P15+P10 -> 0 | Q22: =Q19+Q15+Q10 -> 17 | R22: =R19+R15+R10 -> 246 | S22: =S19+S15+S10 -> 308 | T22: =R22/S22 -> 0.7987013 | U22: =U19+U15+U10 -> 0 | V22: =V19+V15+V10 -> 832 | W22: =W19+W15+W10 -> 38 | X22: =X19+X15+X10 -> 870 | Y22: =Y19+Y15+Y10 -> 967 | Z22: =Z19+Z15+Z10 -> 97 | AA22: =round(Z22/$AA$26*7,0) -> -4 | AB22: =AB19+AB15+AB10 -> 870 | AC22: =AC19+AC15+AC10 -> 967 | AD22: =(V22+W22)/Y22 -> 0.89968976
AA24: 46022 | AC24: =AC22-AB22 -> 97
A25: SEPT-DEC - FLEET TARGETS | AA25: =today()-1 -> 46215
L26: INPUT HERE | AA26: =AA24-AA25 -> -193
B27: Total | C27: Target | D27: TO GO (100%) | F27: UNREG ORDERS | L27: Sept | M27: Oct | N27: Nov | O27: Dec | P27: Total
A28: Salford | B28: =P28 -> 7 | C28: =12+11 -> 23 | D28: =C28-B28 -> 16 | J28: Kinto One | K28: Salford | L28: 5 | M28: 2 | P28: =sum(L28:O28) -> 7
A29: Bolton | B29: =P29 -> 4 | C29: =6+7 -> 13 | D29: =C29-B29 -> 9 | F29: 4 | J29: Kinto Fleet Partnership | K29: Bolton | L29: 1 | N29: 3 | P29: =sum(L29:O29) -> 4
A30: Bury | B30: =P30 -> 0 | C30: =5+6 -> 11 | D30: =C30-B30 -> 11 | J30: Kinto PCH | K30: Bury | P30: =sum(L30:O30) -> 0
A31: Rochdale | B31: =P31 -> 2 | C31: =7+7 -> 14 | D31: =C31-B31 -> 12 | J31: Centre Fleet | K31: Rochdale | M31: 2 | P31: =sum(L31:O31) -> 2
A32: NORTH CDA | B32: =sum(B28:B31) -> 13 | C32: =sum(C28:C31) -> 61 | D32: =sum(D28:D31) -> 48 | F32: =sum(F28:F31) -> 4 | K32: NORTH CDA | L32: =sum(L28:L31) -> 6 | M32: =sum(M28:M31) -> 4 | N32: =sum(N28:N31) -> 3 | O32: =sum(O28:O31) -> 0 | P32: =sum(P28:P31) -> 13
A34: Macclesfield | B34: =P34 -> 1 | C34: =7+6 -> 13 | D34: =C34-B34 -> 12 | K34: Macclesfield | L34: 1 | P34: =sum(L34:O34) -> 1
A35: Denton | B35: 2 | C35: =9+9 -> 18 | D35: =C35-B35 -> 16 | F35: 2 | K35: Denton | M35: 1 | P35: =sum(L35:O35) -> 1
A36: Altrincham | B36: 1 | C36: =5+6 -> 11 | D36: =C36-B36 -> 10 | F36: 1 | K36: Altrincham | P36: =sum(L36:O36) -> 0
A37: Stockport | B37: 1 | C37: =9+9 -> 18 | D37: =C37-B37 -> 17 | F37: 1 | K37: Stockport | O37: 1 | P37: =sum(L37:O37) -> 1
A38: SOUTH CDA | B38: =sum(B34:B37) -> 5 | C38: =sum(C34:C37) -> 60 | D38: =sum(D34:D37) -> 55 | F38: =sum(F34:F37) -> 4 | K38: SOUTH CDA | L38: =sum(L34:L37) -> 1 | M38: =sum(M34:M37) -> 1 | N38: =sum(N34:N37) -> 0 | O38: =sum(O34:O37) -> 1 | P38: =sum(P34:P37) -> 3
A40: Bradford | B40: 22 | C40: =9+9 -> 18 | D40: =C40-B40 -> -4 | F40: 0 | K40: Bradford | L40: 3 | M40: 4 | N40: 3 | O40: 12 | P40: =sum(L40:O40) -> 22
A41: Huddersfield | B41: 3 | C41: =5+6 -> 11 | D41: =C41-B41 -> 8 | F41: 0 | K41: Huddersfield | N41: 2 | O41: 1 | P41: =sum(L41:O41) -> 3
A42: Silsden | B42: =P42 -> 0 | C42: =2+3 -> 5 | D42: =C42-B42 -> 5 | F42: 0 | K42: Silsden | P42: =sum(L42:O42) -> 0
A43: WY CDA | B43: =sum(B40:B42) -> 25 | C43: =sum(C40:C42) -> 34 | D43: =sum(D40:D42) -> 9 | F43: =sum(F40:F42) -> 0 | K43: WY CDA | L43: =sum(L40:L42) -> 3 | M43: =sum(M40:M42) -> 4 | N43: =sum(N40:N42) -> 5 | O43: =sum(O40:O42) -> 13 | P43: =sum(P40:P42) -> 25
A46: TOTAL | B46: =B43+B38+B32 -> 43 | C46: =C43+C38+C32 -> 155 | D46: =D43+D38+D32 -> 112 | F46: =F43+F38+F32 -> 8 | K46: TOTAL | L46: =L43+L38+L32 -> 10 | M46: =M43+M38+M32 -> 9 | N46: =N43+N38+N32 -> 8 | O46: =O43+O38+O32 -> 14 | P46: =P43+P38+P32 -> 41
A49: REGISTRATIONS (NON-COUNTING) | X49: Updated | Y49: By
C50: =C4 -> OCT | G50: =H4 -> NOV | L50: =N4 -> DEC | R50: TOTAL
C51: Non-Counting Fleet (Reg) | D51: Non-Counting Fleet (Unreg) | E51: Total | F51: Budget | G51: Non-Counting Fleet (Reg) | H51: Non-Counting Fleet (Unreg) | J51: Total | K51: Budget | L51: Non-Counting Fleet (Reg) | M51: Non-Counting Fleet (Unreg) | N51: Total | O51: Budget | R51: Non-Counting Fleet (Reg) | S51: Non-Counting Fleet (Unreg) | T51: Total | U51: Budget
...

Sheet Copy of 2025 - Q4
A3: REGISTRATIONS (COUNTING) | AE3: Updated | AF3: By
C4: OCT | H4: NOV | N4: DEC | V4: TOTAL
