Workbook

Sheet Forecast Q3
B2: 45550 | D2: ="Days = "&(+B2-A24) -> Days = 77 | E2: ="Days = "&(+A25-B2) -> Days = 15 | G2: 0.7 | M2: Weekly Orders
B3: QUARTER ORDERS | C3: CANCELLATIONS | D3: ORDERS PER DAY | E3: FORECAST ORDERS | F3: CURRENT TOTAL | G3: FORECAST TOTAL | H3: B/FWD | I3: TOTAL | J3: TARGET | K3: C/FWD | M3: 45480 | N3: 45487 | O3: 45494 | P3: 45501 | Q3: 45508 | R3: 45515 | S3: 45522 | T3: 45529 | U3: 45536 | V3: 45543 | W3: 45550 | X3: 45557 | Y3: 45564 | AA3: FORECAST 9/9/24 | AB3: FORECAST 15/9/24
A6: Salford | B6: 158 | C6: 2 | D6: =(B6-C6)/($B$2-$A$24) -> 2.025974 | E6: =ROUNDDOWN(D6*($A$25-$B$2),0) -> 30 | F6: ='2024 - Q3'!Q6+'2024 - Q3'!R6 -> 173 | G6: =F6+ROUND(E6*$G$2,0) -> 194 | H6: ='2024 - Q3'!B6 -> 80 | I6: =G6+H6 -> 274 | J6: ='2024 - Q3'!T6 -> 183 | K6: =I6-J6 -> 91 | M6: 13 | N6: 27 | O6: 30 | P6: 40 | Q6: 57 | R6: 65 | S6: 80 | T6: 106 | U6: 118 | V6: 147 | W6: 156 | AA6: 204 | AB6: 183
A7: Bolton | B7: 73 | C7: 8 | D7: =(B7-C7)/($B$2-$A$24) -> 0.84415584 | E7: =ROUNDDOWN(D7*($A$25-$B$2),0) -> 12 | F7: ='2024 - Q3'!Q7+'2024 - Q3'!R7 -> 94 | G7: =F7+ROUND(E7*$G$2,0) -> 102 | H7: ='2024 - Q3'!B7 -> -20 | I7: =G7+H7 -> 82 | J7: ='2024 - Q3'!T7 -> 168 | K7: =I7-J7 -> -86 | M7: 2 | N7: 8 | O7: 14 | P7: 16 | Q7: 25 | R7: 27 | S7: 36 | T7: 47 | U7: 54 | V7: 60 | W7: 65 | AA7: 103 | AB7: 93
A8: Bury | B8: 75 | C8: 3 | D8: =(B8-C8)/($B$2-$A$24) -> 0.93506494 | E8: =ROUNDDOWN(D8*($A$25-$B$2),0) -> 14 | F8: ='2024 - Q3'!Q8+'2024 - Q3'!R8 -> 107 | G8: =F8+ROUND(E8*$G$2,0) -> 117 | H8: ='2024 - Q3'!B8 -> 17 | I8: =G8+H8 -> 134 | J8: ='2024 - Q3'!T8 -> 118 | K8: =I8-J8 -> 16 | M8: 5 | N8: 6 | O8: 9 | P8: 18 | Q8: 30 | R8: 48 | S8: 53 | T8: 57 | U8: 62 | V8: 65 | W8: 72 | AA8: 120 | AB8: 111
A9: Rochdale | B9: 116 | C9: 2 | D9: =(B9-C9)/($B$2-$A$24) -> 1.4805195 | E9: =ROUNDDOWN(D9*($A$25-$B$2),0) -> 22 | F9: ='2024 - Q3'!Q9+'2024 - Q3'!R9 -> 144 | G9: =F9+ROUND(E9*$G$2,0) -> 159 | H9: ='2024 - Q3'!B9 -> 25 | I9: =G9+H9 -> 184 | J9: ='2024 - Q3'!T9 -> 148 | K9: =I9-J9 -> 36 | M9: 6 | N9: 23 | O9: 32 | P9: 42 | Q9: 48 | R9: 54 | S9: 60 | T9: 67 | U9: 73 | V9: 83 | W9: 114 | AA9: 150 | AB9: 159
A10: NORTH CDA | B10: =SUM(B6:B9) -> 422 | C10: =SUM(C6:C9) -> 15 | D10: =SUM(D6:D9) -> 5.2857143 | E10: =SUM(E6:E9) -> 78 | F10: =SUM(F6:F9) -> 518 | G10: =SUM(G6:G9) -> 572 | H10: =SUM(H6:H9) -> 102 | I10: =SUM(I6:I9) -> 674 | ... K10: =SUM(K6:K9) -> 57
A11: Macclesfield | B11: 126 | C11: 9 | D11: =(B11-C11)/($B$2-$A$24) -> 1.5194805 | E11: =ROUNDDOWN(D11*($A$25-$B$2),0) -> 22 | F11: ='2024 - Q3'!Q11+'2024 - Q3'!R11 -> 124 | G11: =F11+ROUND(E11*$G$2,0) -> 139 | H11: ='2024 - Q3'!B11 -> 31 | I11: =G11+H11 -> 170 | J11: ='2024 - Q3'!T11 -> 139 | K11: =I11-J11 -> 31 | M11: 6 | N11: 13 | O11: 17 | P11: 23 | Q11: 29 | R11: 42 | S11: 66 | T11: 77 | U11: 88 | V11: 100 | W11: 117 | AA11: 148 | AB11: 134
A12: Denton | B12: 102 | C12: 8 | D12: =(B12-C12)/($B$2-$A$24) -> 1.2207792 | E12: =ROUNDDOWN(D12*($A$25-$B$2),0) -> 18 | F12: ='2024 - Q3'!Q12+'2024 - Q3'!R12 -> 111 | G12: =F12+ROUND(E12*$G$2,0) -> 124 | H12: ='2024 - Q3'!B12 -> 20 | I12: =G12+H12 -> 144 | J12: ='2024 - Q3'!T12 -> 127 | K12: =I12-J12 -> 17 | M12: 4 | N12: 15 | O12: 16 | P12: 19 | Q12: 28 | R12: 31 | S12: 38 | T12: 46 | U12: 66 | V12: 87 | W12: 94 | AA12: 130 | AB12: 119
A13: Altrincham | B13: 82 | C13: 4 | D13: =(B13-C13)/($B$2-$A$24) -> 1.012987 | E13: =ROUNDDOWN(D13*($A$25-$B$2),0) -> 15 | F13: ='2024 - Q3'!Q13+'2024 - Q3'!R13 -> 89 | G13: =F13+ROUND(E13*$G$2,0) -> 100 | H13: ='2024 - Q3'!B13 -> 47 | I13: =G13+H13 -> 147 | J13: ='2024 - Q3'!T13 -> 107 | K13: =I13-J13 -> 40 | M13: 2 | N13: 3 | O13: 9 | P13: 13 | Q13: 18 | R13: 29 | S13: 38 | T13: 46 | U13: 53 | V13: 65 | W13: 78 | AA13: 104 | AB13: 100
A14: Stockport | B14: 142 | C14: 4 | D14: =(B14-C14)/($B$2-$A$24) -> 1.7922078 | E14: =ROUNDDOWN(D14*($A$25-$B$2),0) -> 26 | F14: ='2024 - Q3'!Q14+'2024 - Q3'!R14 -> 178 | G14: =F14+ROUND(E14*$G$2,0) -> 196 | H14: ='2024 - Q3'!B14 -> 9 | I14: =G14+H14 -> 205 | J14: ='2024 - Q3'!T14 -> 186 | K14: =I14-J14 -> 19 | M14: 14 | N14: 18 | O14: 25 | P14: 35 | Q14: 40 | R14: 58 | S14: 70 | T14: 81 | U14: 91 | V14: 103 | W14: 138 | AA14: 175 | AB14: 183
A15: SOUTH CDA | B15: =SUM(B11:B14) -> 452 | C15: =SUM(C11:C14) -> 25 | D15: =SUM(D11:D14) -> 5.5454545 | E15: =SUM(E11:E14) -> 81 | F15: =SUM(F11:F14) -> 502 | G15: =SUM(G11:G14) -> 559 | H15: =SUM(H11:H14) -> 107 | I15: =SUM(I11:I14) -> 666 | ... K15: =SUM(K11:K14) -> 107
A16: Bradford | B16: 105 | C16: 1 | D16: =(B16-C16)/($B$2-$A$24) -> 1.3506494 | E16: =ROUNDDOWN(D16*($A$25-$B$2),0) -> 20 | F16: ='2024 - Q3'!Q16+'2024 - Q3'!R16 -> 118 | G16: =F16+ROUND(E16*$G$2,0) -> 132 | H16: ='2024 - Q3'!B16 -> 20 | I16: =G16+H16 -> 152 | J16: ='2024 - Q3'!T16 -> 126 | K16: =I16-J16 -> 26 | M16: 1 | N16: 6 | O16: 8 | P16: 20 | Q16: 30 | R16: 35 | S16: 44 | T16: 53 | U16: 67 | V16: 72 | W16: 104 | AA16: 112 | AB16: 126
A17: Huddersfield | B17: 104 | C17: 2 | D17: =(B17-C17)/($B$2-$A$24) -> 1.3246753 | E17: =ROUNDDOWN(D17*($A$25-$B$2),0) -> 19 | F17: ='2024 - Q3'!Q17+'2024 - Q3'!R17 -> 134 | G17: =F17+ROUND(E17*$G$2,0) -> 147 | H17: ='2024 - Q3'!B17 -> 0 | I17: =G17+H17 -> 147 | J17: ='2024 - Q3'!T17 -> 149 | K17: =I17-J17 -> -2 | M17: 5 | N17: 11 | O17: 18 | P17: 22 | Q17: 28 | R17: 42 | S17: 54 | T17: 59 | U17: 71 | V17: 79 | W17: 102 | AA17: 140 | AB17: 136
A18: Silsden | B18: 41 | C18: 2 | D18: =(B18-C18)/($B$2-$A$24) -> 0.50649351 | E18: =ROUNDDOWN(D18*($A$25-$B$2),0) -> 7 | F18: ='2024 - Q3'!Q18+'2024 - Q3'!R18 -> 45 | G18: =F18+ROUND(E18*$G$2,0) -> 50 | H18: ='2024 - Q3'!B18 -> 14 | I18: =G18+H18 -> 64 | J18: ='2024 - Q3'!T18 -> 55 | K18: =I18-J18 -> 9 | M18: 3 | N18: 4 | O18: 5 | P18: 8 | Q18: 14 | R18: 16 | S18: 17 | T18: 19 | U18: 26 | V18: 31 | W18: 39 | AA18: 51 | AB18: 52
A19: WY CDA | B19: =SUM(B16:B18) -> 250 | C19: =SUM(C16:C18) -> 5 | D19: =SUM(D16:D18) -> 3.1818182 | E19: =SUM(E16:E18) -> 46 | F19: =SUM(F16:F18) -> 297 | G19: =SUM(G16:G18) -> 329 | H19: =SUM(H16:H18) -> 34 | I19: =SUM(I16:I18) -> 363 | ... K19: =SUM(K16:K18) -> 33
A22: TOTAL | B22: =B19+B15+B10 -> 1124 | C22: =C19+C15+C10 -> 45 | D22: =D19+D15+D10 -> 14.012987 | E22: =E19+E15+E10 -> 205 | F22: =F19+F15+F10 -> 1317 | G22: =G19+G15+G10 -> 1460 | H22: =H19+H15+H10 -> 243 | I22: =I19+I15+I10 -> 1703 | ... K22: =K19+K15+K10 -> 197 | M22: =SUM(M6:M21) -> 61 | N22: =SUM(N6:N21) -> 134 | O22: =SUM(O6:O21) -> 183 | P22: =SUM(P6:P21) -> 256 | Q22: =SUM(Q6:Q21) -> 347 | R22: =SUM(R6:R21) -> 447 | S22: =SUM(S6:S21) -> 556 | T22: =SUM(T6:T21) -> 658 | ... Y22: =SUM(Y6:Y21) -> 0 | AA22: =SUM(AA6:AA21) -> 1437 | AB22: =SUM(AB6:AB21) -> 1396
A24: 45473 | C24: =B22-C22 -> 1079 | L24: Orders Per Week | M24: =M22 -> 61 | N24: =N22-M22 -> 73 | O24: =O22-N22 -> 49 | P24: =P22-O22 -> 73 | Q24: =Q22-P22 -> 91 | R24: =R22-Q22 -> 100 | S24: =S22-R22 -> 109 | T24: =T22-S22 -> 102 | U24: =U22-T22 -> 111 | ... Y24: =Y22-X22 -> 0
A25: 45565

Sheet 2026 - Q4
A1: REGISTRATIONS (COUNTING) | AC1: Updated | AD1: By
B2: OCT | H2: NOV | N2: DEC | T2: TOTAL
B3: Counting | C3: CLCP Regs | D3: Counting Fleet | E3: Total | F3: Target | H3: Counting | I3: CLCP Regs | J3: Counting Fleet | K3: Total | L3: Target | N3: Counting | O3: CLCP Regs | P3: Counting Fleet | Q3: Total | R3: Target | T3: Counting | U3: Counting Fleet | V3: Total | W3: Target | X3: TO GO | Y3: PER WEEK | Z3: QTR REGS | AA3: TARGET | AB3: REGS v TGT
A4: Bolton | B4: 29 | D4: 1 | E4: =SUM(B4:D4) -> 30 | F4: 27 | G4: =E4/F4 -> 1.1111111 | H4: 14 | K4: =SUM(H4:J4) -> 14 | L4: 33 | M4: =K4/L4 -> 0.42424242 | N4: 6 | Q4: =SUM(N4:P4) -> 6 | R4: 27 | S4: =Q4/R4 -> 0.22222222 | T4: =N4+H4+B4+O4+I4 -> 49 | U4: =P4+J4+D4 -> 1 | V4: =SUM(T4:U4) -> 50 | W4: =F4+L4+R4 -> 87 | X4: =W4-V4 -> 37 | Y4: =ROUND(X4/$Y$24*7,0) -> 3 | Z4: =V4 -> 50 | AA4: =W4 -> 87 | AB4: =Z4/AA4 -> 0.57471264 | AC4: 46306 | AD4: DH
A5: Bury | B5: 22 | D5: 2 | E5: =SUM(B5:D5) -> 24 | F5: 20 | G5: =E5/F5 -> 1.2 | H5: 9 | K5: =SUM(H5:J5) -> 9 | L5: 23 | M5: =K5/L5 -> 0.39130435 | N5: 3 | Q5: =SUM(N5:P5) -> 3 | R5: 19 | S5: =Q5/R5 -> 0.15789474 | T5: =N5+H5+B5+O5+I5 -> 34 | U5: =P5+J5+D5 -> 2 | V5: =SUM(T5:U5) -> 36 | W5: =F5+L5+R5 -> 62 | X5: =W5-V5 -> 26 | Y5: =ROUND(X5/$Y$24*7,0) -> 2 | Z5: =V5 -> 36 | AA5: =W5 -> 62 | AB5: =Z5/AA5 -> 0.58064516 | AC5: 46306 | AD5: TP
A6: Rochdale | B6: 14 | E6: =SUM(B6:D6) -> 14 | F6: 21 | G6: =E6/F6 -> 0.66666667 | H6: 12 | K6: =SUM(H6:J6) -> 12 | L6: 27 | M6: =K6/L6 -> 0.44444444 | N6: 5 | Q6: =SUM(N6:P6) -> 5 | R6: 24 | S6: =Q6/R6 -> 0.20833333 | T6: =N6+H6+B6+O6+I6 -> 31 | U6: =P6+J6+D6 -> 0 | V6: =SUM(T6:U6) -> 31 | W6: =F6+L6+R6 -> 72 | X6: =W6-V6 -> 41 | Y6: =ROUND(X6/$Y$24*7,0) -> 4 | Z6: =V6 -> 31 | AA6: =W6 -> 72 | AB6: =Z6/AA6 -> 0.43055556 | AC6: 46306 | AD6: PF
A7: SQ | B7: 25 | D7: 7 | E7: =SUM(B7:D7) -> 32 | F7: 38 | G7: =E7/F7 -> 0.84210526 | H7: 4 | K7: =SUM(H7:J7) -> 4 | L7: 44 | M7: =K7/L7 -> 0.090909091 | N7: 8 | Q7: =SUM(N7:P7) -> 8 | R7: 34 | S7: =Q7/R7 -> 0.23529412 | T7: =N7+H7+B7+O7+I7 -> 37 | U7: =P7+J7+D7 -> 7 | V7: =SUM(T7:U7) -> 44 | W7: =F7+L7+R7 -> 116 | X7: =W7-V7 -> 72 | Y7: =ROUND(X7/$Y$24*7,0) -> 6 | Z7: =V7 -> 44 | AA7: =W7 -> 116 | AB7: =Z7/AA7 -> 0.37931034 | AC7: 46306 | AD7: DP
A8: NORTH CDA | B8: =SUM(B4:B7) -> 90 | C8: =SUM(C4:C7) -> 0 | D8: =SUM(D4:D7) -> 10 | E8: =SUM(E4:E7) -> 100 | F8: =SUM(F4:F7) -> 106 | G8: =E8/F8 -> 0.94339623 | H8: =SUM(H3:H7) -> 39 | I8: =SUM(I4:I7) -> 0 | J8: =SUM(J4:J7) -> 0 | K8: =SUM(K4:K7) -> 39 | L8: =SUM(L4:L7) -> 127 | M8: =K8/L8 -> 0.30708661 | N8: =SUM(N4:N7) -> 22 | O8: =SUM(O4:O7) -> 0 | P8: =SUM(P4:P7) -> 0 | Q8: =SUM(Q4:Q7) -> 22 | R8: =SUM(R4:R7) -> 104 | S8: =Q8/R8 -> 0.21153846 | T8: =SUM(T4:T7) -> 151 | U8: =SUM(U4:U7) -> 10 | V8: =SUM(V4:V7) -> 161 | W8: =SUM(W4:W7) -> 337 | X8: =SUM(X4:X7) -> 176 | Y8: =ROUND(X8/Y24*7,0) -> 16 | Z8: =SUM(Z4:Z7) -> 161 | AA8: =SUM(AA4:AA7) -> 337 | AB8: =Z8/AA8 -> 0.47774481
A9: Altrincham | B9: 18 | E9: =SUM(B9:D9) -> 18 | F9: 22 | G9: =E9/F9 -> 0.81818182 | H9: 10 | K9: =SUM(H9:J9) -> 10 | L9: 25 | M9: =K9/L9 -> 0.4 | N9: 2 | Q9: =SUM(N9:P9) -> 2 | R9: 23 | S9: =Q9/R9 -> 0.086956522 | T9: =N9+H9+B9+O9+I9 -> 30 | U9: =P9+J9+D9 -> 0 | V9: =SUM(T9:U9) -> 30 | W9: =F9+L9+R9 -> 70 | X9: =W9-V9 -> 40 | Y9: =ROUND(X9/$Y$24*7,0) -> 4 | Z9: =V9 -> 30 | AA9: =W9 -> 70 | AB9: =Z9/AA9 -> 0.42857143 | AC9: 46306 | AD9: NF
A10: Denton | B10: 13 | D10: 6 | E10: =SUM(B10:D10) -> 19 | F10: 24 | G10: =E10/F10 -> 0.79166667 | H10: 11 | K10: =SUM(H10:J10) -> 11 | L10: 28 | M10: =K10/L10 -> 0.39285714 | N10: 5 | Q10: =SUM(N10:P10) -> 5 | R10: 25 | S10: =Q10/R10 -> 0.2 | T10: =N10+H10+B10+O10+I10 -> 29 | U10: =P10+J10+D10 -> 6 | V10: =SUM(T10:U10) -> 35 | W10: =F10+L10+R10 -> 77 | X10: =W10-V10 -> 42 | Y10: =ROUND(X10/$Y$24*7,0) -> 4 | Z10: =V10 -> 35 | AA10: =W10 -> 77 | AB10: =Z10/AA10 -> 0.45454545 | AC10: 46306 | AD10: NF
A11: Macclesfield | B11: 22 | E11: =SUM(B11:D11) -> 22 | F11: 24 | G11: =E11/F11 -> 0.91666667 | H11: 7 | K11: =SUM(H11:J11) -> 7 | L11: 27 | M11: =K11/L11 -> 0.25925926 | N11: 8 | Q11: =SUM(N11:P11) -> 8 | R11: 27 | S11: =Q11/R11 -> 0.2962963 | T11: =N11+H11+B11+O11+I11 -> 37 | U11: =P11+J11+D11 -> 0 | V11: =SUM(T11:U11) -> 37 | W11: =F11+L11+R11 -> 78 | X11: =W11-V11 -> 41 | Y11: =ROUND(X11/$Y$24*7,0) -> 4 | Z11: =V11 -> 37 | AA11: =W11 -> 78 | AB11: =Z11/AA11 -> 0.47435897 | AC11: 46306 | AD11: NF
A12: Stockport | B12: 32 | E12: =SUM(B12:D12) -> 32 | F12: 40 | G12: =E12/F12 -> 0.8 | H12: 11 | K12: =SUM(H12:J12) -> 11 | L12: 46 | M12: =K12/L12 -> 0.23913043 | N12: 3 | Q12: =SUM(N12:P12) -> 3 | R12: 40 | S12: =Q12/R12 -> 0.075 | T12: =N12+H12+B12+O12+I12 -> 46 | U12: =P12+J12+D12 -> 0 | V12: =SUM(T12:U12) -> 46 | W12: =F12+L12+R12 -> 126 | X12: =W12-V12 -> 80 | Y12: =ROUND(X12/$Y$24*7,0) -> 7 | Z12: =V12 -> 46 | AA12: =W12 -> 126 | AB12: =Z12/AA12 -> 0.36507937 | AC12: 46306 | AD12: NF
A13: SOUTH CDA | B13: =SUM(B9:B12) -> 85 | C13: =SUM(C9:C12) -> 0 | D13: =SUM(D9:D12) -> 6 | E13: =SUM(E9:E12) -> 91 | F13: =SUM(F9:F12) -> 110 | G13: =E13/F13 -> 0.82727273 | H13: =SUM(H9:H12) -> 39 | I13: =SUM(I9:I12) -> 0 | J13: =SUM(J9:J12) -> 0 | K13: =SUM(K9:K12) -> 39 | L13: =SUM(L9:L12) -> 126 | M13: =K13/L13 -> 0.30952381 | N13: =SUM(N9:N12) -> 18 | O13: =SUM(O9:O12) -> 0 | P13: =SUM(P9:P12) -> 0 | Q13: =SUM(Q9:Q12) -> 18 | R13: =SUM(R9:R12) -> 115 | S13: =Q13/R13 -> 0.15652174 | T13: =SUM(T9:T12) -> 142 | U13: =SUM(U9:U12) -> 6 | V13: =SUM(V9:V12) -> 148 | W13: =SUM(W9:W12) -> 351 | X13: =SUM(X9:X12) -> 203 | Y13: =ROUND(X13/Y24*7,0) -> 18 | Z13: =SUM(Z9:Z12) -> 148 | AA13: =SUM(AA9:AA12) -> 351 | AB13: =Z13/AA13 -> 0.42165242
A14: Bradford | B14: 11 | D14: 7 | E14: =SUM(B14:D14) -> 18 | F14: 27 | G14: =E14/F14 -> 0.66666667 | H14: 6 | K14: =SUM(H14:J14) -> 6 | L14: 31 | M14: =K14/L14 -> 0.19354839 | N14: 6 | Q14: =SUM(N14:P14) -> 6 | R14: 29 | S14: =Q14/R14 -> 0.20689655 | T14: =N14+H14+B14+O14+I14 -> 23 | U14: =P14+J14+D14 -> 7 | V14: =SUM(T14:U14) -> 30 | W14: =F14+L14+R14 -> 87 | X14: =W14-V14 -> 57 | Y14: =ROUND(X14/$Y$24*7,0) -> 5 | Z14: =V14 -> 30 | AA14: =W14 -> 87 | AB14: =Z14/AA14 -> 0.34482759 | AC14: 46306 | AD14: DH
A15: Huddersfield | B15: 23 | D15: 12 | E15: =SUM(B15:D15) -> 35 | F15: 25 | G15: =E15/F15 -> 1.4 | H15: 15 | J15: 3 | K15: =SUM(H15:J15) -> 18 | L15: 32 | M15: =K15/L15 -> 0.5625 | N15: 10 | P15: 2 | Q15: =SUM(N15:P15) -> 12 | R15: 31 | S15: =Q15/R15 -> 0.38709677 | T15: =N15+H15+B15+O15+I15 -> 48 | U15: =P15+J15+D15 -> 17 | V15: =SUM(T15:U15) -> 65 | W15: =F15+L15+R15 -> 88 | X15: =W15-V15 -> 23 | Y15: =ROUND(X15/$Y$24*7,0) -> 2 | Z15: =V15 -> 65 | AA15: =W15 -> 88 | AB15: =Z15/AA15 -> 0.73863636 | AC15: 46306 | AD15: CM
A16: Silsden | B16: 10 | E16: =SUM(B16:D16) -> 10 | F16: 9 | G16: =E16/F16 -> 1.1111111 | H16: 3 | K16: =SUM(H16:J16) -> 3 | L16: 8 | M16: =K16/L16 -> 0.375 | N16: 3 | Q16: =SUM(N16:P16) -> 3 | R16: 10 | S16: =Q16/R16 -> 0.3 | T16: =N16+H16+B16+O16+I16 -> 16 | U16: =P16+J16+D16 -> 0 | V16: =SUM(T16:U16) -> 16 | W16: =F16+L16+R16 -> 27 | X16: =W16-V16 -> 11 | Y16: =ROUND(X16/$Y$24*7,0) -> 1 | Z16: =V16 -> 16 | AA16: =W16 -> 27 | AB16: =Z16/AA16 -> 0.59259259 | AC16: 46306 | AD16: RM
A17: WY CDA | B17: =SUM(B14:B16) -> 44 | C17: =SUM(C14:C16) -> 0 | D17: =SUM(D14:D16) -> 19 | E17: =SUM(E14:E16) -> 63 | F17: =SUM(F14:F16) -> 61 | G17: =E17/F17 -> 1.0327869 | H17: =SUM(H14:H16) -> 24 | I17: =SUM(I14:I16) -> 0 | J17: =SUM(J14:J16) -> 3 | K17: =SUM(K14:K16) -> 27 | L17: =SUM(L14:L16) -> 71 | M17: =K17/L17 -> 0.38028169 | N17: =SUM(N14:N16) -> 19 | O17: =SUM(O14:O16) -> 0 | P17: =SUM(P14:P16) -> 2 | Q17: =SUM(Q14:Q16) -> 21 | R17: =SUM(R14:R16) -> 70 | S17: =Q17/R17 -> 0.3 | T17: =SUM(T14:T16) -> 87 | U17: =SUM(U14:U16) -> 24 | V17: =SUM(V14:V16) -> 111 | W17: =SUM(W14:W16) -> 202 | X17: =SUM(X14:X16) -> 91 | Y17: =ROUND(X17/Y24*7,0) -> 8 | Z17: =SUM(Z14:Z16) -> 111 | AA17: =SUM(AA14:AA16) -> 202 | AB17: =Z17/AA17 -> 0.54950495
A20: TOTAL | B20: =SUM(B8+B13+B17) -> 219 | C20: =SUM(C8+C13+C17) -> 0 | D20: =SUM(D8+D13+D17) -> 35 | E20: =SUM(E8+E13+E17) -> 254 | F20: =SUM(F8+F13+F17) -> 277 | G20: =E20/F20 -> 0.91696751 | H20: =SUM(H8+H13+H17) -> 102 | I20: =SUM(I8+I13+I17) -> 0 | J20: =SUM(J8+J13+J17) -> 3 | K20: =SUM(K8+K13+K17) -> 105 | L20: =SUM(L8+L13+L17) -> 324 | M20: =K20/L20 -> 0.32407407 | N20: =SUM(N8+N13+N17) -> 59 | O20: =SUM(O8+O13+O17) -> 0 | P20: =SUM(P8+P13+P17) -> 2 | Q20: =SUM(Q8+Q13+Q17) -> 61 | R20: =SUM(R8+R13+R17) -> 289 | S20: =Q20/R20 -> 0.21107266 | T20: =SUM(T8+T13+T17) -> 380 | U20: =SUM(U8+U13+U17) -> 40 | V20: =SUM(V8+V13+V17) -> 420 | W20: =SUM(W8+W13+W17) -> 890 | X20: =SUM(X8+X13+X17) -> 470 | Y20: =ROUND(X20/Y24*7,0) -> 42 | Z20: =Z8+Z13+Z17 -> 420 | AA20: =AA8+AA13+AA17 -> 890 | AB20: =Z20/AA20 -> 0.47191011
Y22: 46387 | AA22: =Z17-AA17 -> -91
Y23: =TODAY() -> 46308
Y24: =Y22-Y23 -> 79
A25: REGISTRATIONS (NON-COUNTING) | S25: Updated | T25: By
B26: OCT | H26: NOV | N26: DEC
B27: Non-Counting Fleet (Reg) | C27: Non-Counting Fleet (Unreg) | D27: Total | E27: Budget | F27: Non-Counting Fleet (Reg) | G27: Non-Counting Fleet (Unreg) | H27: Total | I27: Budget | J27: Non-Counting Fleet (Reg) | K27: Non-Counting Fleet (Unreg) | L27: Total | M27: Budget | O27: Non-Counting Fleet (Reg) | P27: Non-Counting Fleet (Unreg) | Q27: Total | R27: Budget
A28: Salford | B28: 18 | C28: 72 | D28: =SUM(B28:C28) -> 90 | F28: 0 | G28: 55 | H28: =SUM(F28:G28) -> 55 | J28: 0 | K28: 20 | L28: =J28+K28 -> 20 | O28: =J28+F28+B28 -> 18 | P28: =K28+G28+C28 -> 147 | Q28: =P28+O28 -> 165 | R28: =M28+I28+E28 -> 0 | S28: DP | T28: 46308
A29: NORTH CDA | B29: =SUM(B28) -> 18 | C29: =SUM(C28) -> 72 | D29: =SUM(D28) -> 90 | E29: =SUM(E28) -> 0 | F29: =SUM(F28) -> 0 | G29: =SUM(G28) -> 55 | H29: =SUM(H28) -> 55 | I29: =SUM(I28) -> 0 | ... M29: =SUM(M28) -> 0 | O29: =SUM(O28) -> 18 | P29: =SUM(P28) -> 147 | Q29: =SUM(Q28) -> 165 | R29: =SUM(R28) -> 0
A30: Denton | B30: 0 | C30: 20 | D30: =SUM(B30:C30) -> 20 | F30: 0 | G30: 20 | H30: =SUM(F30:G30) -> 20 | J30: 0 | K30: 20 | L30: =K30+J30 -> 20 | O30: =J30+F30+B30 -> 0 | P30: =C30+G30+K30 -> 60 | Q30: =P30+O30 -> 60 | R30: =M30+I30+E30 -> 0 | S30: NF | T30: 46306
A31: SOUTH CDA | B31: =SUM(B30) -> 0 | C31: =SUM(C30) -> 20 | D31: =SUM(D30) -> 20 | E31: =SUM(E30) -> 0 | F31: =SUM(F30) -> 0 | G31: =SUM(G30) -> 20 | H31: =SUM(H30) -> 20 | I31: =SUM(I30) -> 0 | ... M31: =SUM(M30) -> 0 | O31: =SUM(O30) -> 0 | P31: =SUM(P30) -> 60 | Q31: =SUM(Q30) -> 60 | R31: =SUM(R30) -> 0
A32: Bradford | B32: 7 | C32: 18 | D32: =SUM(B32:C32) -> 25 | F32: 0 | G32: 25 | H32: =SUM(F32:G32) -> 25 | J32: 0 | K32: 25 | L32: =K32+J32 -> 25 | O32: =J32+F32+B32 -> 7 | P32: =K32+G32+C32 -> 68 | Q32: =P32+O32 -> 75 | R32: =M32+I32+E32 -> 0 | S32: gb | T32: 46307
A33: Huddersfield | B33: 0 | C33: 0 | D33: =SUM(B33:C33) -> 0 | F33: 0 | G33: 0 | H33: =SUM(F33:G33) -> 0 | J33: 0 | K33: 0 | L33: =K33+J33 -> 0 | O33: =J33+F33+B33 -> 0 | P33: =K33+G33+C33 -> 0 | Q33: =P33+O33 -> 0 | R33: =M33+I33+E33 -> 0
A34: WY CDA | B34: =SUM(B32+B33) -> 7 | C34: =SUM(C32+C33) -> 18 | D34: =SUM(D32+D33) -> 25 | E34: =SUM(E32+E33) -> 0 | F34: =SUM(F32+F33) -> 0 | G34: =SUM(G32+G33) -> 25 | H34: =SUM(H32+H33) -> 25 | I34: =SUM(I32+I33) -> 0 | ... M34: =SUM(M32+M33) -> 0 | O34: =SUM(O32+O33) -> 7 | P34: =SUM(P32+P33) -> 68 | Q34: =SUM(Q32+Q33) -> 75 | R34: =SUM(R32+R33) -> 0
A37: TOTAL | B37: =B34+B31+B29 -> 25 | C37: =C34+C31+C29 -> 110 | D37: =D34+D31+D29 -> 135 | E37: =E34+E31+E29 -> 0 | F37: =F34+F31+F29 -> 0 | G37: =G34+G31+G29 -> 100 | H37: =H34+H31+H29 -> 100 | I37: =I34+I31+I29 -> 0 | ... M37: =M34+M31+M29 -> 0 | O37: =O34+O31+O29 -> 25 | P37: =P34+P31+P29 -> 275 | Q37: =Q34+Q31+Q29 -> 300 | R37: =R34+R31+R29 -> 0
R39: =Q37/R37 -> #DIV/0!
A41: USED COUNTING VOLUME | M41: Updated | N41: By
B42: OCT | E42: NOV | H42: DEC | K42: TOTAL
B43: Counting | C43: Target | E43: Counting | F43: Target | H43: Counting | I43: Target | K43: Counting | L43: Target
A44: Bolton | B44: 22 | C44: 62 | D44: =B44/C44 -> 0.35483871 | F44: 57 | G44: =E44/F44 -> 0 | I44: 41 | J44: =H44/I44 -> 0 | K44: =H44+E44+B44 -> 22 | L44: =I44+F44+C44 -> 160 | M44: GB | N44: 46307
A45: Bury | B45: 16 | C45: 54 | D45: =B45/C45 -> 0.2962963 | F45: 50 | G45: =E45/F45 -> 0 | I45: 36 | J45: =H45/I45 -> 0 | K45: =H45+E45+B45 -> 16 | L45: =I45+F45+C45 -> 140 | M45: GB | N45: 46307
A46: Rochdale | B46: 10 | C46: 50 | D46: =B46/C46 -> 0.2 | F46: 46 | G46: =E46/F46 -> 0 | I46: 33 | J46: =H46/I46 -> 0 | K46: =H46+E46+B46 -> 10 | L46: =I46+F46+C46 -> 129 | M46: GB | N46: 46307
A47: SQ | B47: 27 | C47: 59 | D47: =B47/C47 -> 0.45762712 | F47: 54 | G47: =E47/F47 -> 0 | I47: 39 | J47: =H47/I47 -> 0 | K47: =H47+E47+B47 -> 27 | L47: =I47+F47+C47 -> 152 | M47: GB | N47: 46307
...

Sheet 2026 - Q3
A1: REGISTRATIONS (COUNTING) | AC1: Updated | AD1: By
B2: JULY | H2: AUG | N2: SEPT | T2: TOTAL
B3: Counting | C3: CLCP Regs | D3: Counting Fleet | E3: Total | F3: Target | H3: Counting | I3: CLCP Regs | J3: Counting Fleet | K3: Total | L3: Target | N3: Counting | O3: CLCP Regs | P3: Counting Fleet | Q3: Total | R3: Target | T3: Counting | U3: Counting Fleet | V3: Total | W3: Target | X3: TO GO | Y3: PER WEEK | Z3: QTR REGS | AA3: TARGET | AB3: REGS v TGT | AE3: BOOST VOUCHERS ALLOCATED | AF3: BOOST VOUCHERS USED | AG3: LEFT
A4: Bolton | B4: 39 | E4: =SUM(B4:D4) -> 39 | F4: 24 | G4: =E4/F4 -> 1.625 | H4: 13 | K4: =SUM(H4:J4) -> 13 | L4: 12 | M4: =K4/L4 -> 1.0833333 | N4: 66 | O4: 3 | P4: 1 | Q4: =SUM(N4:P4) -> 70 | R4: 69 | S4: =Q4/R4 -> 1.0144928 | T4: =N4+H4+B4+O4+I4 -> 121 | U4: =P4+J4+D4 -> 1 | V4: =SUM(T4:U4) -> 122 | W4: =F4+L4+R4 -> 105 | X4: =W4-V4 -> -17 | Y4: =ROUND(X4/$Y$24*7,0) -> 9 | Z4: =V4 -> 122 | AA4: =W4 -> 105 | AB4: =Z4/AA4 -> 1.1619048 | AC4: 46295 | AD4: GB | AE4: 25 | AF4: 27 | AG4: =AE4-AF4 -> -2
A5: Bury | B5: 25 | E5: =SUM(B5:D5) -> 25 | F5: 19 | G5: =E5/F5 -> 1.3157895 | H5: 9 | K5: =SUM(H5:J5) -> 9 | L5: 11 | M5: =K5/L5 -> 0.81818182 | N5: 50 | O5: 2 | Q5: =SUM(N5:P5) -> 52 | R5: 47 | S5: =Q5/R5 -> 1.106383 | T5: =N5+H5+B5+O5+I5 -> 86 | U5: =P5+J5+D5 -> 0 | V5: =SUM(T5:U5) -> 86 | W5: =F5+L5+R5 -> 77 | X5: =W5-V5 -> -9 | Y5: =ROUND(X5/$Y$24*7,0) -> 5 | Z5: =V5 -> 86 | AA5: =W5 -> 77 | AB5: =Z5/AA5 -> 1.1168831 | AC5: 46295 | AD5: gb | AE5: 20 | AF5: 20 | AG5: =AE5-AF5 -> 0
A6: Rochdale | B6: 34 | E6: =SUM(B6:D6) -> 34 | F6: 19 | G6: =E6/F6 -> 1.7894737 | H6: 13 | K6: =SUM(H6:J6) -> 13 | L6: 11 | M6: =K6/L6 -> 1.1818182 | N6: 82 | O6: 6 | Q6: =SUM(N6:P6) -> 88 | R6: 55 | S6: =Q6/R6 -> 1.6 | T6: =N6+H6+B6+O6+I6 -> 135 | U6: =P6+J6+D6 -> 0 | V6: =SUM(T6:U6) -> 135 | W6: =F6+L6+R6 -> 85 | X6: =W6-V6 -> -50 | Y6: =ROUND(X6/$Y$24*7,0) -> 27 | Z6: =V6 -> 135 | AA6: =W6 -> 85 | AB6: =Z6/AA6 -> 1.5882353 | AC6: 46295 | AD6: gb | AE6: 20 | AF6: 20 | AG6: =AE6-AF6 -> 0
A7: SQ | B7: 36 | D7: 8 | E7: =SUM(B7:D7) -> 44 | F7: 32 | G7: =E7/F7 -> 1.375 | H7: 14 | J7: 5 | K7: =SUM(H7:J7) -> 19 | L7: 18 | M7: =K7/L7 -> 1.0555556 | N7: 71 | O7: 6 | P7: 11 | Q7: =SUM(N7:P7) -> 88 | R7: 90 | S7: =Q7/R7 -> 0.97777778 | T7: =N7+H7+B7+O7+I7 -> 127 | U7: =P7+J7+D7 -> 24 | V7: =SUM(T7:U7) -> 151 | W7: =F7+L7+R7 -> 140 | X7: =W7-V7 -> -11 | Y7: =ROUND(X7/$Y$24*7,0) -> 6 | Z7: =V7 -> 151 | AA7: =W7 -> 140 | AB7: =Z7/AA7 -> 1.0785714 | AC7: 46295 | AD7: GB | AE7: 35 | AF7: 25 | AG7: =AE7-AF7 -> 10
A8: NORTH CDA | B8: =SUM(B4:B7) -> 134 | C8: =SUM(C4:C7) -> 0 | D8: =SUM(D4:D7) -> 8 | E8: =SUM(E4:E7) -> 142 | F8: =SUM(F4:F7) -> 94 | G8: =E8/F8 -> 1.5106383 | H8: =SUM(H3:H7) -> 49 | I8: =SUM(I4:I7) -> 0 | J8: =SUM(J4:J7) -> 5 | K8: =SUM(K4:K7) -> 54 | L8: =SUM(L4:L7) -> 52 | M8: =K8/L8 -> 1.0384615 | N8: =SUM(N4:N7) -> 269 | O8: =SUM(O4:O7) -> 17 | P8: =SUM(P4:P7) -> 12 | Q8: =SUM(Q4:Q7) -> 298 | R8: =SUM(R4:R7) -> 261 | S8: =Q8/R8 -> 1.1417625 | T8: =SUM(T4:T7) -> 469 | U8: =SUM(U4:U7) -> 25 | V8: =SUM(V4:V7) -> 494 | W8: =SUM(W4:W7) -> 407 | X8: =SUM(X4:X7) -> -87 | Y8: =ROUND(X8/Y24*7,0) -> 47 | Z8: =SUM(Z4:Z7) -> 494 | AA8: =SUM(AA4:AA7) -> 407 | AB8: =Z8/AA8 -> 1.2137592 | AE8: =SUM(AE4:AE7) -> 100 | AF8: =SUM(AF4:AF7) -> 92 | AG8: =SUM(AG4:AG7) -> 8
A9: Altrincham | B9: 27 | E9: =SUM(B9:D9) -> 27 | F9: 19 | G9: =E9/F9 -> 1.4210526 | H9: 13 | K9: =SUM(H9:J9) -> 13 | L9: 11 | M9: =K9/L9 -> 1.1818182 | N9: 36 | O9: 9 | Q9: =SUM(N9:P9) -> 45 | R9: 57 | S9: =Q9/R9 -> 0.78947368 | T9: =N9+H9+B9+O9+I9 -> 85 | U9: =P9+J9+D9 -> 0 | V9: =SUM(T9:U9) -> 85 | W9: =F9+L9+R9 -> 87 | X9: =W9-V9 -> 2 | Y9: =ROUND(X9/$Y$24*7,0) -> -1 | Z9: =V9 -> 85 | AA9: =W9 -> 87 | AB9: =Z9/AA9 -> 0.97701149 | AC9: 46295 | AD9: NF | AE9: 20 | AF9: 11 | AG9: =AE9-AF9 -> 9
A10: Denton | B10: 30 | D10: 4 | E10: =SUM(B10:D10) -> 34 | F10: 19 | G10: =E10/F10 -> 1.7894737 | H10: 21 | J10: 0 | K10: =SUM(H10:J10) -> 21 | L10: 11 | M10: =K10/L10 -> 1.9090909 | N10: 50 | O10: 3 | P10: 3 | Q10: =SUM(N10:P10) -> 56 | R10: 63 | S10: =Q10/R10 -> 0.88888889 | T10: =N10+H10+B10+O10+I10 -> 104 | U10: =P10+J10+D10 -> 7 | V10: =SUM(T10:U10) -> 111 | W10: =F10+L10+R10 -> 93 | X10: =W10-V10 -> -18 | Y10: =ROUND(X10/$Y$24*7,0) -> 10 | Z10: =V10 -> 111 | AA10: =W10 -> 93 | AB10: =Z10/AA10 -> 1.1935484 | AC10: 46295 | AD10: NF | AE10: 20 | AF10: 22 | AG10: =AE10-AF10 -> -2
A11: Macclesfield | B11: 23 | E11: =SUM(B11:D11) -> 23 | F11: 21 | G11: =E11/F11 -> 1.0952381 | H11: 19 | K11: =SUM(H11:J11) -> 19 | L11: 13 | M11: =K11/L11 -> 1.4615385 | N11: 59 | O11: 4 | Q11: =SUM(N11:P11) -> 63 | R11: 62 | S11: =Q11/R11 -> 1.016129 | T11: =N11+H11+B11+O11+I11 -> 105 | U11: =P11+J11+D11 -> 0 | V11: =SUM(T11:U11) -> 105 | W11: =F11+L11+R11 -> 96 | X11: =W11-V11 -> -9 | Y11: =ROUND(X11/$Y$24*7,0) -> 5 | Z11: =V11 -> 105 | AA11: =W11 -> 96 | AB11: =Z11/AA11 -> 1.09375 | AC11: 46295 | AD11: NF | AE11: 20 | AF11: 25 | AG11: =AE11-AF11 -> -5
A12: Stockport | B12: 48 | E12: =SUM(B12:D12) -> 48 | F12: 34 | G12: =E12/F12 -> 1.4117647 | H12: 25 | K12: =SUM(H12:J12) -> 25 | L12: 20 | M12: =K12/L12 -> 1.25 | N12: 82 | Q12: =SUM(N12:P12) -> 82 | R12: 97 | S12: =Q12/R12 -> 0.84536082 | T12: =N12+H12+B12+O12+I12 -> 155 | U12: =P12+J12+D12 -> 0 | V12: =SUM(T12:U12) -> 155 | W12: =F12+L12+R12 -> 151 | X12: =W12-V12 -> -4 | Y12: =ROUND(X12/$Y$24*7,0) -> 2 | Z12: =V12 -> 155 | AA12: =W12 -> 151 | AB12: =Z12/AA12 -> 1.0264901 | AC12: 46295 | AD12: NF | AE12: 35 | AF12: 23 | AG12: =AE12-AF12 -> 12
A13: SOUTH CDA | B13: =SUM(B9:B12) -> 128 | C13: =SUM(C9:C12) -> 0 | D13: =SUM(D9:D12) -> 4 | E13: =SUM(E9:E12) -> 132 | F13: =SUM(F9:F12) -> 93 | G13: =E13/F13 -> 1.4193548 | H13: =SUM(H9:H12) -> 78 | I13: =SUM(I9:I12) -> 0 | J13: =SUM(J9:J12) -> 0 | K13: =SUM(K9:K12) -> 78 | L13: =SUM(L9:L12) -> 55 | M13: =K13/L13 -> 1.4181818 | N13: =SUM(N9:N12) -> 227 | O13: =SUM(O9:O12) -> 16 | P13: =SUM(P9:P12) -> 3 | Q13: =SUM(Q9:Q12) -> 246 | R13: =SUM(R9:R12) -> 279 | S13: =Q13/R13 -> 0.88172043 | T13: =SUM(T9:T12) -> 449 | U13: =SUM(U9:U12) -> 7 | V13: =SUM(V9:V12) -> 456 | W13: =SUM(W9:W12) -> 427 | X13: =SUM(X9:X12) -> -29 | Y13: =ROUND(X13/Y24*7,0) -> 16 | Z13: =SUM(Z9:Z12) -> 456 | AA13: =SUM(AA9:AA12) -> 427 | AB13: =Z13/AA13 -> 1.0679157 | AE13: =SUM(AE9:AE12) -> 95 | AF13: =SUM(AF9:AF12) -> 81 | AG13: =SUM(AG9:AG12) -> 14
A14: Bradford | B14: 26 | D14: 13 | E14: =SUM(B14:D14) -> 39 | F14: 22 | G14: =E14/F14 -> 1.7727273 | H14: 17 | J14: 8 | K14: =SUM(H14:J14) -> 25 | L14: 13 | M14: =K14/L14 -> 1.9230769 | N14: 54 | O14: 7 | P14: 4 | Q14: =SUM(N14:P14) -> 65 | R14: 70 | S14: =Q14/R14 -> 0.92857143 | T14: =N14+H14+B14+O14+I14 -> 104 | U14: =P14+J14+D14 -> 25 | V14: =SUM(T14:U14) -> 129 | W14: =F14+L14+R14 -> 105 | X14: =W14-V14 -> -24 | Y14: =ROUND(X14/$Y$24*7,0) -> 13 | Z14: =V14 -> 129 | AA14: =W14 -> 105 | AB14: =Z14/AA14 -> 1.2285714 | AC14: 46295 | AD14: gb | AE14: 25 | AF14: 17 | AG14: =AE14-AF14 -> 8
A15: Huddersfield | B15: 30 | C15: 0 | D15: 2 | E15: =SUM(B15:D15) -> 32 | F15: 23 | G15: =E15/F15 -> 1.3913043 | H15: 18 | J15: 1 | K15: =SUM(H15:J15) -> 19 | L15: 13 | M15: =K15/L15 -> 1.4615385 | N15: 57 | O15: 5 | P15: 3 | Q15: =SUM(N15:P15) -> 65 | R15: 72 | S15: =Q15/R15 -> 0.90277778 | T15: =N15+H15+B15+O15+I15 -> 110 | U15: =P15+J15+D15 -> 6 | V15: =SUM(T15:U15) -> 116 | W15: =F15+L15+R15 -> 108 | X15: =W15-V15 -> -8 | Y15: =ROUND(X15/$Y$24*7,0) -> 4 | Z15: =V15 -> 116 | AA15: =W15 -> 108 | AB15: =Z15/AA15 -> 1.0740741 | AC15: 46295 | AD15: gb | AE15: 25 | AF15: 23 | AG15: =AE15-AF15 -> 2
A16: Silsden | B16: 8 | E16: =SUM(B16:D16) -> 8 | F16: 8 | G16: =E16/F16 -> 1 | H16: 9 | K16: =SUM(H16:J16) -> 9 | L16: 3 | M16: =K16/L16 -> 3 | N16: 21 | O16: 1 | Q16: =SUM(N16:P16) -> 22 | R16: 23 | S16: =Q16/R16 -> 0.95652174 | T16: =N16+H16+B16+O16+I16 -> 39 | U16: =P16+J16+D16 -> 0 | V16: =SUM(T16:U16) -> 39 | W16: =F16+L16+R16 -> 34 | X16: =W16-V16 -> -5 | Y16: =ROUND(X16/$Y$24*7,0) -> 3 | Z16: =V16 -> 39 | AA16: =W16 -> 34 | AB16: =Z16/AA16 -> 1.1470588 | AC16: 46295 | AD16: gb | AE16: 10 | AF16: 13 | AG16: =AE16-AF16 -> -3
A17: WY CDA | B17: =SUM(B14:B16) -> 64 | C17: =SUM(C14:C16) -> 0 | D17: =SUM(D14:D16) -> 15 | E17: =SUM(E14:E16) -> 79 | F17: =SUM(F14:F16) -> 53 | G17: =E17/F17 -> 1.490566 | H17: =SUM(H14:H16) -> 44 | I17: =SUM(I14:I16) -> 0 | J17: =SUM(J14:J16) -> 9 | K17: =SUM(K14:K16) -> 53 | L17: =SUM(L14:L16) -> 29 | M17: =K17/L17 -> 1.8275862 | N17: =SUM(N14:N16) -> 132 | O17: =SUM(O14:O16) -> 13 | P17: =SUM(P14:P16) -> 7 | Q17: =SUM(Q14:Q16) -> 152 | R17: =SUM(R14:R16) -> 165 | S17: =Q17/R17 -> 0.92121212 | T17: =SUM(T14:T16) -> 253 | U17: =SUM(U14:U16) -> 31 | V17: =SUM(V14:V16) -> 284 | W17: =SUM(W14:W16) -> 247 | X17: =SUM(X14:X16) -> -37 | Y17: =ROUND(X17/Y24*7,0) -> 20 | Z17: =SUM(Z14:Z16) -> 284 | AA17: =SUM(AA14:AA16) -> 247 | AB17: =Z17/AA17 -> 1.1497976 | AE17: =SUM(AE14:AE16) -> 60 | AF17: =SUM(AF14:AF16) -> 53 | AG17: =SUM(AG14:AG16) -> 7
AG18: =AE18-AF18 -> 0
AG19: =AE19-AF19 -> 0
A20: TOTAL | B20: =SUM(B8+B13+B17) -> 326 | C20: =SUM(C8+C13+C17) -> 0 | D20: =SUM(D8+D13+D17) -> 27 | E20: =SUM(E8+E13+E17) -> 353 | F20: =SUM(F8+F13+F17) -> 240 | G20: =E20/F20 -> 1.4708333 | H20: =SUM(H8+H13+H17) -> 171 | I20: =SUM(I8+I13+I17) -> 0 | J20: =SUM(J8+J13+J17) -> 14 | K20: =SUM(K8+K13+K17) -> 185 | L20: =SUM(L8+L13+L17) -> 136 | M20: =K20/L20 -> 1.3602941 | N20: =SUM(N8+N13+N17) -> 628 | O20: =SUM(O8+O13+O17) -> 46 | P20: =SUM(P8+P13+P17) -> 22 | Q20: =SUM(Q8+Q13+Q17) -> 696 | R20: =SUM(R8+R13+R17) -> 705 | S20: =Q20/R20 -> 0.98723404 | T20: =SUM(T8+T13+T17) -> 1171 | U20: =SUM(U8+U13+U17) -> 63 | V20: =SUM(V8+V13+V17) -> 1234 | W20: =SUM(W8+W13+W17) -> 1081 | X20: =SUM(X8+X13+X17) -> -153 | Y20: =ROUND(X20/Y24*7,0) -> 82 | Z20: =Z8+Z13+Z17 -> 1234 | AA20: =AA8+AA13+AA17 -> 1081 | AB20: =Z20/AA20 -> 1.1415356 | AE20: =AE17+AE13+AE8 -> 255 | AF20: =AF17+AF13+AF8 -> 226 | AG20: =AG17+AG13+AG8 -> 29
AE21: =AE20*750 -> 191250 | AF21: =AF20*750 -> 169500 | AG21: =AG20*750 -> 21750
Y22: 46295 | AA22: =Z17-AA17 -> 37
Y23: =TODAY() -> 46308
Y24: =Y22-Y23 -> -13
A25: REGISTRATIONS (NON-COUNTING) | S25: Updated | T25: By
B26: JULY | F26: AUGUST | J26: SEPT | O26: TOTAL
B27: Non-Counting Fleet (Reg) | C27: Non-Counting Fleet (Unreg) | D27: Total | E27: Budget | F27: Non-Counting Fleet (Reg) | G27: Non-Counting Fleet (Unreg) | H27: Total | I27: Budget | J27: Non-Counting Fleet (Reg) | K27: Non-Counting Fleet (Unreg) | L27: Total | M27: Budget | O27: Non-Counting Fleet (Reg) | P27: Non-Counting Fleet (Unreg) | Q27: Total | R27: Budget
A28: Salford | B28: 114 | C28: 0 | D28: =SUM(B28:C28) -> 114 | E28: 126 | F28: 55 | G28: 0 | H28: =SUM(F28:G28) -> 55 | I28: 55 | J28: 232 | K28: 0 | L28: =J28+K28 -> 232 | M28: 240 | O28: =J28+F28+B28 -> 401 | P28: =K28+G28+C28 -> 0 | Q28: =P28+O28 -> 401 | R28: =M28+I28+E28 -> 421 | S28: 46295 | T28: GB
A29: NORTH CDA | B29: =SUM(B28) -> 114 | C29: =SUM(C28) -> 0 | D29: =SUM(D28) -> 114 | E29: =SUM(E28) -> 126 | F29: =SUM(F28) -> 55 | G29: =SUM(G28) -> 0 | H29: =SUM(H28) -> 55 | I29: =SUM(I28) -> 55 | ... M29: =SUM(M28) -> 240 | O29: =SUM(O28) -> 401 | P29: =SUM(P28) -> 0 | Q29: =SUM(Q28) -> 401 | R29: =SUM(R28) -> 421
A30: Denton | B30: 9 | C30: 0 | D30: =SUM(B30:C30) -> 9 | E30: 35 | F30: 31 | G30: 0 | H30: =SUM(F30:G30) -> 31 | I30: 10 | J30: 47 | K30: 30 | L30: =K30+J30 -> 77 | M30: 85 | O30: 82 | P30: 0 | Q30: =P30+O30 -> 82 | R30: =M30+I30+E30 -> 130 | S30: 46295 | T30: NF
A31: SOUTH CDA | B31: =SUM(B30) -> 9 | C31: =SUM(C30) -> 0 | D31: =SUM(D30) -> 9 | E31: =SUM(E30) -> 35 | F31: =SUM(F30) -> 31 | G31: =SUM(G30) -> 0 | H31: =SUM(H30) -> 31 | I31: =SUM(I30) -> 10 | ... M31: =SUM(M30) -> 85 | O31: =SUM(O30) -> 82 | P31: =SUM(P30) -> 0 | Q31: =SUM(Q30) -> 82 | R31: =SUM(R30) -> 130
A32: Bradford | B32: 41 | C32: 0 | D32: =SUM(B32:C32) -> 41 | E32: 58 | F32: 62 | G32: 0 | H32: =SUM(F32:G32) -> 62 | I32: 32 | J32: 91 | K32: 0 | L32: =K32+J32 -> 91 | M32: 91 | O32: =J32+F32+B32 -> 194 | P32: =K32+G32+C32 -> 0 | Q32: =P32+O32 -> 194 | R32: =M32+I32+E32 -> 181 | S32: 46295 | T32: WR
A33: Huddersfield | B33: 4 | C33: 0 | D33: =SUM(B33:C33) -> 4 | F33: 2 | G33: 0 | H33: =SUM(F33:G33) -> 2 | L33: =K33+J33 -> 0 | O33: =J33+F33+B33 -> 6 | P33: =K33+G33+C33 -> 0 | Q33: =P33+O33 -> 6 | R33: =M33+I33+E33 -> 0 | S33: 46293 | T33: CM
A34: WY CDA | B34: =SUM(B32+B33) -> 45 | C34: =SUM(C32+C33) -> 0 | D34: =SUM(D32+D33) -> 45 | E34: =SUM(E32+E33) -> 58 | F34: =SUM(F32+F33) -> 64 | G34: =SUM(G32+G33) -> 0 | H34: =SUM(H32+H33) -> 64 | I34: =SUM(I32+I33) -> 32 | ... M34: =SUM(M32+M33) -> 91 | O34: =SUM(O32+O33) -> 200 | P34: =SUM(P32+P33) -> 0 | Q34: =SUM(Q32+Q33) -> 200 | R34: =SUM(R32+R33) -> 181
A37: TOTAL | B37: =B34+B31+B29 -> 168 | C37: =C34+C31+C29 -> 0 | D37: =D34+D31+D29 -> 168 | E37: =E34+E31+E29 -> 219 | F37: =F34+F31+F29 -> 150 | G37: =G34+G31+G29 -> 0 | H37: =H34+H31+H29 -> 150 | I37: =I34+I31+I29 -> 97 | ... M37: =M34+M31+M29 -> 416 | O37: =O34+O31+O29 -> 683 | P37: =P34+P31+P29 -> 0 | Q37: =Q34+Q31+Q29 -> 683 | R37: =R34+R31+R29 -> 732
R39: =Q37/R37 -> 0.93306011
A41: USED COUNTING VOLUME | M41: Updated | N41: By
B42: JULY | E42: AUG | H42: SEPT | K42: TOTAL
B43: Counting | C43: Target | E43: Counting | F43: Target | H43: Counting | I43: Target | K43: Counting | L43: Target
A44: Bolton | B44: 56 | C44: 63 | D44: =B44/C44 -> 0.88888889 | E44: 59 | F44: 62 | G44: =E44/F44 -> 0.9516129 | H44: 59 | I44: 62 | J44: =H44/I44 -> 0.9516129 | K44: =H44+E44+B44 -> 174 | L44: =I44+F44+C44 -> 187 | M44: 46295 | N44: GB
...

Sheet 2026 - Q2
A3: REGISTRATIONS (COUNTING) | AC3: Updated | AD3: By
B4: APR | G4: MAY | M4: JUNE | T4: TOTAL
B5: Counting | C5: Counting Fleet | D5: Total | E5: Target | G5: Counting | H5: CLCP Regs | I5: Counting Fleet | J5: Total | K5: Target | M5: Counting | N5: CLCP Regs | O5: Counting Fleet | P5: Total | Q5: Target | S5: B/FWD | T5: Counting | U5: Counting Fleet | V5: Total | W5: Target | X5: TO GO | Y5: PER WEEK | Z5: QTR REGS | AA5: TARGET | AB5: REGS v TGT
A6: Bolton | B6: 26 | D6: =SUM(B6:C6) -> 26 | E6: 21 | F6: =D6/E6 -> 1.2380952 | G6: 31 | I6: 1 | J6: =SUM(G6:I6) -> 32 | K6: 27 | L6: =J6/K6 -> 1.1851852 | M6: 42 | N6: 0 | O6: 1 | P6: =SUM(M6:O6) -> 43 | Q6: 48 | R6: =P6/Q6 -> 0.89583333 | T6: =M6+G6+B6+N6+H6 -> 99 | U6: =O6+I6+C6 -> 2 | V6: =SUM(S6:U6) -> 101 | W6: =E6+K6+Q6 -> 96 | X6: =W6-V6 -> -5 | Y6: =ROUND(X6/$Y$26*7,0) -> 0 | Z6: =U6+T6 -> 101 | AA6: =W6 -> 96 | AB6: =(T6+U6)/W6 -> 1.0520833 | AC6: 46203 | AD6: GB
A7: Bury | B7: 23 | D7: =SUM(B7:C7) -> 23 | E7: 15 | F7: =D7/E7 -> 1.5333333 | G7: 27 | I7: 1 | J7: =SUM(G7:I7) -> 28 | K7: 20 | L7: =J7/K7 -> 1.4 | M7: 25 | O7: 1 | P7: =SUM(M7:O7) -> 26 | Q7: 36 | R7: =P7/Q7 -> 0.72222222 | T7: =M7+G7+B7+N7+H7 -> 75 | U7: =O7+I7+C7 -> 2 | V7: =SUM(S7:U7) -> 77 | W7: =E7+K7+Q7 -> 71 | X7: =W7-V7 -> -6 | Y7: =ROUND(X7/$Y$26*7,0) -> 0 | Z7: =U7+T7 -> 77 | AA7: =W7 -> 71 | AB7: =(T7+U7)/W7 -> 1.084507 | AC7: 46203 | AD7: GB
A8: Rochdale | B8: 22 | D8: =SUM(B8:C8) -> 22 | E8: 17 | F8: =D8/E8 -> 1.2941176 | G8: 41 | J8: =SUM(G8:I8) -> 41 | K8: 23 | L8: =J8/K8 -> 1.7826087 | M8: 25 | N8: 2 | P8: =SUM(M8:O8) -> 27 | Q8: 40 | R8: =P8/Q8 -> 0.675 | T8: =M8+G8+B8+N8+H8 -> 90 | U8: =O8+I8+C8 -> 0 | V8: =SUM(S8:U8) -> 90 | W8: =E8+K8+Q8 -> 80 | X8: =W8-V8 -> -10 | Y8: =ROUND(X8/$Y$26*7,0) -> 1 | Z8: =U8+T8 -> 90 | AA8: =W8 -> 80 | AB8: =(T8+U8)/W8 -> 1.125 | AC8: 46203 | AD8: GB
A9: SQ | B9: 43 | C9: 9 | D9: =SUM(B9:C9) -> 52 | E9: 29 | F9: =D9/E9 -> 1.7931034 | G9: 38 | H9: 0 | I9: 7 | J9: =SUM(G9:I9) -> 45 | K9: 37 | L9: =J9/K9 -> 1.2162162 | M9: 43 | N9: 1 | O9: 6 | P9: =SUM(M9:O9) -> 50 | Q9: 60 | R9: =P9/Q9 -> 0.83333333 | T9: =M9+G9+B9+N9+H9 -> 125 | U9: =O9+I9+C9 -> 22 | V9: =SUM(S9:U9) -> 147 | W9: =E9+K9+Q9 -> 126 | X9: =W9-V9 -> -21 | Y9: =ROUND(X9/$Y$26*7,0) -> 1 | Z9: =U9+T9 -> 147 | AA9: =W9 -> 126 | AB9: =(T9+U9)/W9 -> 1.1666667 | AC9: 46203 | AD9: GB
A10: NORTH CDA | B10: =SUM(B6:B9) -> 114 | C10: =SUM(C6:C9) -> 9 | D10: =SUM(D6:D9) -> 123 | E10: =SUM(E6:E9) -> 82 | F10: =D10/E10 -> 1.5 | G10: =SUM(G6:G9) -> 137 | H10: =SUM(H6:H9) -> 0 | I10: =SUM(I6:I9) -> 9 | J10: =SUM(J6:J9) -> 146 | K10: =SUM(K6:K9) -> 107 | L10: =J10/K10 -> 1.364486 | M10: =SUM(M6:M9) -> 135 | N10: =SUM(N6:N9) -> 3 | O10: =SUM(O6:O9) -> 8 | P10: =SUM(P6:P9) -> 146 | Q10: =SUM(Q6:Q9) -> 184 | R10: =P10/Q10 -> 0.79347826 | S10: =SUM(S6:S9) -> 0 | T10: =SUM(T6:T9) -> 389 | U10: =SUM(U6:U9) -> 26 | V10: =SUM(V6:V9) -> 415 | W10: =SUM(W6:W9) -> 373 | X10: =SUM(X6:X9) -> -42 | Y10: =ROUND(X10/Y26*7,0) -> 3 | Z10: =SUM(Z6:Z9) -> 415 | AA10: =SUM(AA6:AA9) -> 373 | AB10: =Z10/AA10 -> 1.1126005
A11: Altrincham | B11: 10 | D11: =SUM(B11:C11) -> 10 | E11: 16 | F11: =D11/E11 -> 0.625 | G11: 31 | J11: =SUM(G11:I11) -> 31 | K11: 21 | L11: =J11/K11 -> 1.4761905 | M11: 32 | P11: =SUM(M11:O11) -> 32 | Q11: 36 | R11: =P11/Q11 -> 0.88888889 | T11: =M11+G11+B11+N11+H11 -> 73 | U11: =O11+I11+C11 -> 0 | V11: =SUM(S11:U11) -> 73 | W11: =E11+K11+Q11 -> 73 | X11: =W11-V11 -> 0 | Y11: =ROUND(X11/$Y$26*7,0) -> 0 | Z11: =U11+T11 -> 73 | AA11: =W11 -> 73 | AB11: =(T11+U11)/W11 -> 1 | AC11: 46204 | AD11: NF
A12: Denton | B12: 27 | C12: 1 | D12: =SUM(B12:C12) -> 28 | E12: 17 | F12: =D12/E12 -> 1.6470588 | G12: 25 | I12: 1 | J12: =SUM(G12:I12) -> 26 | K12: 24 | L12: =J12/K12 -> 1.0833333 | M12: 28 | O12: 5 | P12: =SUM(M12:O12) -> 33 | Q12: 42 | R12: =P12/Q12 -> 0.78571429 | T12: =M12+G12+B12+N12+H12 -> 80 | U12: =O12+I12+C12 -> 7 | V12: =SUM(S12:U12) -> 87 | W12: =E12+K12+Q12 -> 83 | X12: =W12-V12 -> -4 | Y12: =ROUND(X12/$Y$26*7,0) -> 0 | Z12: =U12+T12 -> 87 | AA12: =W12 -> 83 | AB12: =(T12+U12)/W12 -> 1.0481928 | AC12: 46204 | AD12: NF
A13: Macclesfield | B13: 18 | D13: =SUM(B13:C13) -> 18 | E13: 18 | F13: =D13/E13 -> 1 | G13: 26 | J13: =SUM(G13:I13) -> 26 | K13: 23 | L13: =J13/K13 -> 1.1304348 | M13: 39 | P13: =SUM(M13:O13) -> 39 | Q13: 40 | R13: =P13/Q13 -> 0.975 | T13: =M13+G13+B13+N13+H13 -> 83 | U13: =O13+I13+C13 -> 0 | V13: =SUM(S13:U13) -> 83 | W13: =E13+K13+Q13 -> 81 | X13: =W13-V13 -> -2 | Y13: =ROUND(X13/$Y$26*7,0) -> 0 | Z13: =U13+T13 -> 83 | AA13: =W13 -> 81 | AB13: =(T13+U13)/W13 -> 1.0246914 | AC13: 46204 | AD13: NF
A14: Stockport | B14: 30 | D14: =SUM(B14:C14) -> 30 | E14: 30 | F14: =D14/E14 -> 1 | G14: 40 | J14: =SUM(G14:I14) -> 40 | K14: 39 | L14: =J14/K14 -> 1.025641 | M14: 62 | P14: =SUM(M14:O14) -> 62 | Q14: 66 | R14: =P14/Q14 -> 0.93939394 | T14: =M14+G14+B14+N14+H14 -> 132 | U14: =O14+I14+C14 -> 0 | V14: =SUM(S14:U14) -> 132 | W14: =E14+K14+Q14 -> 135 | X14: =W14-V14 -> 3 | Y14: =ROUND(X14/$Y$26*7,0) -> 0 | Z14: =U14+T14 -> 132 | AA14: =W14 -> 135 | AB14: =(T14+U14)/W14 -> 0.97777778 | AC14: 46204 | AD14: NF
A15: SOUTH CDA | B15: =SUM(B11:B14) -> 85 | C15: =SUM(C11:C14) -> 1 | D15: =SUM(D11:D14) -> 86 | E15: =SUM(E11:E14) -> 81 | F15: =D15/E15 -> 1.0617284 | G15: =SUM(G11:G14) -> 122 | H15: =SUM(H11:H14) -> 0 | I15: =SUM(I11:I14) -> 1 | J15: =SUM(J11:J14) -> 123 | K15: =SUM(K11:K14) -> 107 | L15: =J15/K15 -> 1.1495327 | M15: =SUM(M11:M14) -> 161 | N15: =SUM(N11:N14) -> 0 | O15: =SUM(O11:O14) -> 5 | P15: =SUM(P11:P14) -> 166 | Q15: =SUM(Q11:Q14) -> 184 | R15: =P15/Q15 -> 0.90217391 | S15: =SUM(S11:S14) -> 0 | T15: =SUM(T11:T14) -> 368 | U15: =SUM(U11:U14) -> 7 | V15: =SUM(V11:V14) -> 375 | W15: =SUM(W11:W14) -> 372 | X15: =SUM(X11:X14) -> -3 | Y15: =ROUND(X15/Y26*7,0) -> 0 | Z15: =SUM(Z11:Z14) -> 375 | AA15: =SUM(AA11:AA14) -> 372 | AB15: =Z15/AA15 -> 1.0080645
A16: Bradford | B16: 18 | C16: 4 | D16: =SUM(B16:C16) -> 22 | E16: 22 | F16: =D16/E16 -> 1 | G16: 21 | I16: 6 | J16: =SUM(G16:I16) -> 27 | K16: 26 | L16: =J16/K16 -> 1.0384615 | M16: 23 | N16: 4 | O16: 3 | P16: =SUM(M16:O16) -> 30 | Q16: 44 | R16: =P16/Q16 -> 0.68181818 | T16: =M16+G16+B16+N16+H16 -> 66 | U16: =O16+I16+C16 -> 13 | V16: =SUM(S16:U16) -> 79 | W16: =E16+K16+Q16 -> 92 | X16: =W16-V16 -> 13 | Y16: =ROUND(X16/$Y$26*7,0) -> -1 | Z16: =U16+T16 -> 79 | AA16: =W16 -> 92 | AB16: =(T16+U16)/W16 -> 0.85869565 | AC16: 46203 | AD16: GB
A17: Huddersfield | B17: 19 | C17: 6 | D17: =SUM(B17:C17) -> 25 | E17: 21 | F17: =D17/E17 -> 1.1904762 | G17: 37 | H17: 1 | I17: 0 | J17: =SUM(G17:I17) -> 38 | K17: 27 | L17: =J17/K17 -> 1.4074074 | M17: 31 | N17: 1 | O17: 2 | P17: =SUM(M17:O17) -> 34 | Q17: 49 | R17: =P17/Q17 -> 0.69387755 | T17: =M17+G17+B17+N17+H17 -> 89 | U17: =O17+I17+C17 -> 8 | V17: =SUM(S17:U17) -> 97 | W17: =E17+K17+Q17 -> 97 | X17: =W17-V17 -> 0 | Y17: =ROUND(X17/$Y$26*7,0) -> 0 | Z17: =U17+T17 -> 97 | AA17: =W17 -> 97 | AB17: =(T17+U17)/W17 -> 1 | AC17: 46203 | AD17: GB
A18: Silsden | B18: 6 | D18: =SUM(B18:C18) -> 6 | E18: 6 | F18: =D18/E18 -> 1 | G18: 7 | J18: =SUM(G18:I18) -> 7 | K18: 9 | L18: =J18/K18 -> 0.77777778 | M18: 15 | N18: 2 | P18: =SUM(M18:O18) -> 17 | Q18: 13 | R18: =P18/Q18 -> 1.3076923 | T18: =M18+G18+B18+N18+H18 -> 30 | U18: =O18+I18+C18 -> 0 | V18: =SUM(S18:U18) -> 30 | W18: =E18+K18+Q18 -> 28 | X18: =W18-V18 -> -2 | Y18: =ROUND(X18/$Y$26*7,0) -> 0 | Z18: =U18+T18 -> 30 | AA18: =W18 -> 28 | AB18: =(T18+U18)/W18 -> 1.0714286 | AC18: 46203 | AD18: GB
A19: WY CDA | B19: =SUM(B16:B18) -> 43 | C19: =SUM(C16:C18) -> 10 | D19: =SUM(D16:D18) -> 53 | E19: =SUM(E16:E18) -> 49 | F19: =D19/E19 -> 1.0816327 | G19: =SUM(G16:G18) -> 65 | H19: =SUM(H16:H18) -> 1 | I19: =SUM(I16:I18) -> 6 | J19: =SUM(J16:J18) -> 72 | K19: =SUM(K16:K18) -> 62 | L19: =J19/K19 -> 1.1612903 | M19: =SUM(M16:M18) -> 69 | N19: =SUM(N16:N18) -> 7 | O19: =SUM(O16:O18) -> 5 | P19: =SUM(P16:P18) -> 81 | Q19: =SUM(Q16:Q18) -> 106 | R19: =P19/Q19 -> 0.76415094 | S19: =SUM(S16:S18) -> 0 | T19: =SUM(T16:T18) -> 185 | U19: =SUM(U16:U18) -> 21 | V19: =SUM(V16:V18) -> 206 | W19: =SUM(W16:W18) -> 217 | X19: =SUM(X16:X18) -> 11 | Y19: =ROUND(X19/Y26*7,0) -> -1 | Z19: =SUM(Z16:Z18) -> 206 | AA19: =SUM(AA16:AA18) -> 217 | AB19: =Z19/AA19 -> 0.94930876
A22: TOTAL | B22: =B19+B15+B10 -> 242 | C22: =C19+C15+C10 -> 20 | D22: =D19+D15+D10 -> 262 | E22: =E19+E15+E10 -> 212 | F22: =D22/E22 -> 1.2358491 | G22: =G19+G15+G10 -> 324 | H22: =H19+H15+H10 -> 1 | I22: =I19+I15+I10 -> 16 | J22: =J19+J15+J10 -> 341 | K22: =K19+K15+K10 -> 276 | L22: =J22/K22 -> 1.2355072 | M22: =M19+M15+M10 -> 365 | N22: =N19+N15+N10 -> 10 | O22: =O19+O15+O10 -> 18 | P22: =P19+P15+P10 -> 393 | Q22: =Q19+Q15+Q10 -> 474 | R22: =P22/Q22 -> 0.82911392 | S22: =S19+S15+S10 -> 0 | T22: =T19+T15+T10 -> 942 | U22: =U19+U15+U10 -> 54 | V22: =V19+V15+V10 -> 996 | W22: =W19+W15+W10 -> 962 | X22: =X19+X15+X10 -> -34 | Y22: =ROUND(X22/Y26*7,0) -> 2 | Z22: =Z19+Z15+Z10 -> 996 | AA22: =AA19+AA15+AA10 -> 962 | AB22: =(T22+U22)/W22 -> 1.035343
Y24: 46203 | AA24: =AA22-Z22 -> -34
A25: REGISTRATIONS (NON-COUNTING) | S25: Updated | T25: By | Y25: =TODAY() -> 46308
B26: APRIL | F26: MAY | J26: JUNE | O26: TOTAL | Y26: =Y24-Y25 -> -105
B27: Non-Counting Fleet (Reg) | C27: Non-Counting Fleet (Unreg) | D27: Total | E27: Budget | F27: Non-Counting Fleet (Reg) | G27: Non-Counting Fleet (Unreg) | H27: Total | I27: Budget | J27: Non-Counting Fleet (Reg) | K27: Non-Counting Fleet (Unreg) | L27: Total | M27: Budget | O27: Non-Counting Fleet (Reg) | P27: Non-Counting Fleet (Unreg) | Q27: Total | R27: Budget
A28: Salford | B28: 198 | C28: 0 | D28: =SUM(B28:C28) -> 198 | E28: 100 | F28: 128 | G28: 0 | H28: =SUM(F28:G28) -> 128 | I28: 100 | J28: 328 | K28: 0 | L28: 0 | M28: 157 | O28: =J28+F28+B28 -> 654 | P28: =K28+G28+C28 -> 0 | Q28: =P28+O28 -> 654 | R28: =M28+I28+E28 -> 357 | S28: 46203 | T28: GB | Z28: `
A29: NORTH CDA | B29: =SUM(B28) -> 198 | C29: =SUM(C28) -> 0 | D29: =SUM(D28) -> 198 | E29: =SUM(E28) -> 100 | F29: =SUM(F28) -> 128 | G29: =SUM(G28) -> 0 | H29: =SUM(H28) -> 128 | I29: =SUM(I28) -> 100 | ... M29: =SUM(M28) -> 157 | O29: =SUM(O28) -> 654 | P29: =SUM(P28) -> 0 | Q29: =SUM(Q28) -> 654 | R29: =SUM(R28) -> 357
A30: Denton | B30: 27 | D30: =SUM(B30:C30) -> 27 | E30: 20 | F30: 8 | G30: 0 | H30: =SUM(F30:G30) -> 8 | I30: 20 | J30: 45 | K30: 0 | L30: =K30+J30 -> 45 | M30: 47 | O30: =J30+F30+B30 -> 80 | P30: =C30+G30+K30 -> 0 | Q30: =P30+O30 -> 80 | R30: =M30+I30+E30 -> 87 | S30: 46204 | T30: NF
A31: SOUTH CDA | B31: =SUM(B30) -> 27 | C31: =SUM(C30) -> 0 | D31: =SUM(D30) -> 27 | E31: =SUM(E30) -> 20 | F31: =SUM(F30) -> 8 | G31: =SUM(G30) -> 0 | H31: =SUM(H30) -> 8 | I31: =SUM(I30) -> 20 | ... M31: =SUM(M30) -> 47 | O31: =SUM(O30) -> 80 | P31: =SUM(P30) -> 0 | Q31: =SUM(Q30) -> 80 | R31: =SUM(R30) -> 87
A32: Bradford | B32: 13 | C32: 0 | D32: =SUM(B32:C32) -> 13 | E32: 27 | F32: 237 | G32: 0 | H32: =SUM(F32:G32) -> 237 | I32: 45 | J32: 34 | K32: 0 | L32: =K32+J32 -> 34 | M32: 57 | O32: =J32+F32+B32 -> 284 | P32: =K32+G32+C32 -> 0 | Q32: =P32+O32 -> 284 | R32: =M32+I32+E32 -> 129 | S32: 46203 | T32: GB
A33: WY CDA | B33: =SUM(B32) -> 13 | C33: =SUM(C32) -> 0 | D33: =SUM(D32) -> 13 | E33: =SUM(E32) -> 27 | F33: =SUM(F32) -> 237 | G33: =SUM(G32) -> 0 | H33: =SUM(H32) -> 237 | I33: =SUM(I32) -> 45 | ... M33: =SUM(M32) -> 57 | O33: =SUM(O32) -> 284 | P33: =SUM(P32) -> 0 | Q33: =SUM(Q32) -> 284 | R33: =SUM(R32) -> 129
A36: TOTAL | B36: =B33+B31+B29 -> 238 | C36: =C33+C31+C29 -> 0 | D36: =D33+D31+D29 -> 238 | E36: =E33+E31+E29 -> 147 | F36: =F33+F31+F29 -> 373 | G36: =G33+G31+G29 -> 0 | H36: =H33+H31+H29 -> 373 | I36: =I33+I31+I29 -> 165 | ... M36: =M33+M31+M29 -> 261 | O36: =O33+O31+O29 -> 1018 | P36: =P33+P31+P29 -> 0 | Q36: =Q33+Q31+Q29 -> 1018 | R36: =R33+R31+R29 -> 573
R38: =Q36/R36 -> 1.7766143
A40: USED COUNTING VOLUME | M40: Updated | N40: By
B41: APRIL | E41: MAY | H41: JUNE | K41: TOTAL
B42: Counting | C42: Target | E42: Counting | F42: Target | H42: Counting | I42: Target | K42: Counting | L42: Target
A43: Bolton | B43: 68 | C43: 59 | D43: =B43/C43 -> 1.1525424 | E43: 57 | F43: 59 | G43: =E43/F43 -> 0.96610169 | H43: 56 | I43: 62 | J43: =H43/I43 -> 0.90322581 | K43: =H43+E43+B43 -> 181 | L43: =I43+F43+C43 -> 180 | M43: 46203 | N43: GB
A44: Bury | B44: 59 | C44: 51 | D44: =B44/C44 -> 1.1568627 | E44: 42 | F44: 51 | G44: =E44/F44 -> 0.82352941 | H44: 42 | I44: 54 | J44: =H44/I44 -> 0.77777778 | K44: =H44+E44+B44 -> 143 | L44: =I44+F44+C44 -> 156 | M44: 46203 | N44: GB
A45: Rochdale | B45: 49 | C45: 47 | D45: =B45/C45 -> 1.0425532 | E45: 47 | F45: 47 | G45: =E45/F45 -> 1 | H45: 44 | I45: 50 | J45: =H45/I45 -> 0.88 | K45: =H45+E45+B45 -> 140 | L45: =I45+F45+C45 -> 144 | M45: 46203 | N45: GB
A46: SQ | B46: 59 | C46: 56 | D46: =B46/C46 -> 1.0535714 | E46: 52 | F46: 56 | G46: =E46/F46 -> 0.92857143 | H46: 49 | I46: 59 | J46: =H46/I46 -> 0.83050847 | K46: =H46+E46+B46 -> 160 | L46: =I46+F46+C46 -> 171 | M46: 46203 | N46: GB | O46: =K47/L47 -> 0.95852535 | Q46: =K47-L47 -> -27
A47: NORTH CDA | B47: =SUM(B43:B46) -> 235 | C47: =SUM(C43:C46) -> 213 | D47: =B47/C47 -> 1.1032864 | E47: =SUM(E43:E46) -> 198 | F47: =SUM(F43:F46) -> 213 | G47: =E47/F47 -> 0.92957746 | H47: =SUM(H43:H46) -> 191 | I47: =SUM(I43:I46) -> 225 | J47: =H47/I47 -> 0.84888889 | K47: =SUM(K43:K46) -> 624 | L47: =SUM(L43:L46) -> 651
A48: Altrincham | B48: 49 | C48: 47 | D48: =B48/C48 -> 1.0425532 | E48: 41 | F48: 47 | G48: =E48/F48 -> 0.87234043 | H48: 48 | I48: 50 | J48: =H48/I48 -> 0.96 | K48: =H48+E48+B48 -> 138 | L48: =I48+F48+C48 -> 144 | M48: 46204 | N48: NF
A49: Denton | B49: 41 | C49: 42 | D49: =B49/C49 -> 0.97619048 | E49: 42 | F49: 42 | G49: =E49/F49 -> 1 | H49: 39 | I49: 44 | J49: =H49/I49 -> 0.88636364 | K49: =H49+E49+B49 -> 122 | L49: =I49+F49+C49 -> 128 | M49: 46204 | N49: NF
...

Sheet 2026 - Q1
A3: REGISTRATIONS (COUNTING) | AE3: Updated | AF3: By
B4: JAN | G4: FEB | L4: MAR | S4: TOTAL
B5: Counting | C5: Counting Fleet | D5: Total | E5: Target | G5: Counting | H5: CLCP Regs | I5: Counting Fleet | J5: Total | K5: Target | L5: Counting | M5: CLCP Regs | N5: Counting Fleet | O5: Total | P5: Target | R5: B/FWD | S5: Counting | T5: Counting Fleet | U5: Total | V5: Target | W5: TO GO | X5: PER WEEK | Y5: QTR REGS | Z5: TARGET | AA5: REGS v TGT | AB5: BOOST VOUCHERS ALLOCATED | AC5: BOOST VOUCHERS USED | AD5: LEFT
A6: Bolton | B6: 25 | D6: =SUM(B6:C6) -> 25 | E6: 22 | F6: =D6/E6 -> 1.1363636 | G6: 10 | J6: =SUM(G6:I6) -> 10 | K6: 11 | L6: 80 | O6: =SUM(L6:N6) -> 80 | P6: 90 | Q6: =O6/P6 -> 0.88888889 | S6: =L6+G6+B6+M6+H6 -> 115 | T6: =N6+I6+C6 -> 0 | U6: =SUM(R6:T6) -> 115 | V6: =E6+K6+P6 -> 123 | W6: =V6-U6 -> 8 | X6: =ROUND(W6/$X$26*7,0) -> 0 | Y6: =T6+S6 -> 115 | Z6: =V6 -> 123 | AA6: =(S6+T6)/V6 -> 0.93495935 | AB6: 20 | AC6: 17 | AD6: =AB6-AC6 -> 3 | AE6: 46112 | AF6: gb | AG6: ALL TAXED
A7: Bury | B7: 17 | D7: =SUM(B7:C7) -> 17 | E7: 15 | F7: =D7/E7 -> 1.1333333 | G7: 7 | J7: =SUM(G7:I7) -> 7 | K7: 9 | L7: 71 | O7: =SUM(L7:N7) -> 71 | P7: 64 | Q7: =O7/P7 -> 1.109375 | S7: =L7+G7+B7+M7+H7 -> 95 | T7: =N7+I7+C7 -> 0 | U7: =SUM(R7:T7) -> 95 | V7: =E7+K7+P7 -> 88 | W7: =V7-U7 -> -7 | X7: =ROUND(W7/$X$26*7,0) -> 0 | Y7: =T7+S7 -> 95 | Z7: =V7 -> 88 | AA7: =(S7+T7)/V7 -> 1.0795455 | AB7: 15 | AC7: 15 | AD7: =AB7-AC7 -> 0 | AE7: 46112 | AF7: gb | AG7: ALL TAXED
A8: Rochdale | B8: 28 | D8: =SUM(B8:C8) -> 28 | E8: 16 | F8: =D8/E8 -> 1.75 | G8: 6 | J8: =SUM(G8:I8) -> 6 | K8: 9 | L8: 83 | O8: =SUM(L8:N8) -> 83 | P8: 74 | Q8: =O8/P8 -> 1.1216216 | S8: =L8+G8+B8+M8+H8 -> 117 | T8: =N8+I8+C8 -> 0 | U8: =SUM(R8:T8) -> 117 | V8: =E8+K8+P8 -> 99 | W8: =V8-U8 -> -18 | X8: =ROUND(W8/$X$26*7,0) -> 1 | Y8: =T8+S8 -> 117 | Z8: =V8 -> 99 | AA8: =(S8+T8)/V8 -> 1.1818182 | AB8: 20 | AC8: 20 | AD8: =AB8-AC8 -> 0 | AE8: 46112 | AF8: gb | AG8: ALL TAXED
A9: SQ | B9: 30 | C9: 9 | D9: =SUM(B9:C9) -> 39 | E9: 31 | F9: =D9/E9 -> 1.2580645 | G9: 25 | I9: 2 | J9: =SUM(G9:I9) -> 27 | K9: 15 | L9: 75 | N9: 7 | O9: =SUM(L9:N9) -> 82 | P9: 109 | Q9: =O9/P9 -> 0.75229358 | S9: =L9+G9+B9+M9+H9 -> 130 | T9: =N9+I9+C9 -> 18 | U9: =SUM(R9:T9) -> 148 | V9: =E9+K9+P9 -> 155 | W9: =V9-U9 -> 7 | X9: =ROUND(W9/$X$26*7,0) -> 0 | Y9: =T9+S9 -> 148 | Z9: =V9 -> 155 | AA9: =(S9+T9)/V9 -> 0.95483871 | AB9: 30 | AC9: 30 | AD9: =AB9-AC9 -> 0 | AE9: 46112 | AF9: gb | AG9: ALL TAXED
A10: NORTH CDA | B10: =SUM(B6:B9) -> 100 | C10: =SUM(C6:C9) -> 9 | D10: =SUM(D6:D9) -> 109 | E10: =SUM(E6:E9) -> 84 | F10: =D10/E10 -> 1.297619 | G10: =SUM(G6:G9) -> 48 | H10: =SUM(H6:H9) -> 0 | I10: =SUM(I6:I9) -> 2 | J10: =SUM(J6:J9) -> 50 | K10: =SUM(K6:K9) -> 44 | L10: =SUM(L6:L9) -> 309 | M10: =SUM(M6:M9) -> 0 | N10: =SUM(N6:N9) -> 7 | ... P10: =SUM(P6:P9) -> 337 | Q10: =O10/P10 -> 0.93768546 | R10: =SUM(R6:R9) -> 0 | S10: =SUM(S6:S9) -> 457 | T10: =SUM(T6:T9) -> 18 | U10: =SUM(U6:U9) -> 475 | V10: =SUM(V6:V9) -> 465 | W10: =SUM(W6:W9) -> -10 | X10: =ROUND(W10/X26*7,0) -> 0 | Y10: =SUM(Y6:Y9) -> 475 | Z10: =SUM(Z6:Z9) -> 465 | AA10: =Y10/Z10 -> 1.0215054 | AB10: =SUM(AB6:AB9) -> 85 | AC10: =SUM(AC6:AC9) -> 82 | AD10: =SUM(AD6:AD9) -> 3
A11: Altrincham | B11: 20 | D11: =SUM(B11:C11) -> 20 | E11: 16 | F11: =D11/E11 -> 1.25 | G11: 14 | J11: =SUM(G11:I11) -> 14 | K11: 9 | L11: 58 | N11: 1 | O11: =SUM(L11:N11) -> 59 | P11: 68 | Q11: =O11/P11 -> 0.86764706 | S11: =L11+G11+B11+M11+H11 -> 92 | T11: =N11+I11+C11 -> 1 | U11: =SUM(R11:T11) -> 93 | V11: =E11+K11+P11 -> 93 | W11: =V11-U11 -> 0 | X11: =ROUND(W11/$X$26*7,0) -> 0 | Y11: =T11+S11 -> 93 | Z11: =V11 -> 93 | AA11: =(S11+T11)/V11 -> 1 | AB11: 15 | AC11: 15 | AD11: =AB11-AC11 -> 0 | AE11: 46112 | AF11: NF | AG11: ALL TAXED
A12: Denton | B12: 21 | C12: 2 | D12: =SUM(B12:C12) -> 23 | E12: 17 | F12: =D12/E12 -> 1.3529412 | G12: 16 | I12: 0 | J12: =SUM(G12:I12) -> 16 | K12: 9 | L12: 60 | N12: 3 | O12: =SUM(L12:N12) -> 63 | P12: 76 | Q12: =O12/P12 -> 0.82894737 | S12: =L12+G12+B12+M12+H12 -> 97 | T12: =N12+I12+C12 -> 5 | U12: =SUM(R12:T12) -> 102 | V12: =E12+K12+P12 -> 102 | W12: =V12-U12 -> 0 | X12: =ROUND(W12/$X$26*7,0) -> 0 | Y12: =T12+S12 -> 102 | Z12: =V12 -> 102 | AA12: =(S12+T12)/V12 -> 1 | AB12: 20 | AC12: 20 | AD12: =AB12-AC12 -> 0 | AE12: 46112 | AF12: NF | AG12: ALL TAXED
A13: Macclesfield | B13: 19 | D13: =SUM(B13:C13) -> 19 | E13: 18 | F13: =D13/E13 -> 1.0555556 | G13: 11 | J13: =SUM(G13:I13) -> 11 | K13: 9 | L13: 89 | O13: =SUM(L13:N13) -> 89 | P13: 75 | Q13: =O13/P13 -> 1.1866667 | S13: 119 | T13: =N13+I13+C13 -> 0 | U13: =SUM(R13:T13) -> 119 | V13: =E13+K13+P13 -> 102 | W13: =V13-U13 -> -17 | X13: =ROUND(W13/$X$26*7,0) -> 1 | Y13: =T13+S13 -> 119 | Z13: =V13 -> 102 | AA13: =(S13+T13)/V13 -> 1.1666667 | AB13: 20 | AC13: 20 | AD13: =AB13-AC13 -> 0 | AE13: 46112 | AF13: NF | AG13: ALL TAXED
A14: Stockport | B14: 46 | D14: =SUM(B14:C14) -> 46 | E14: 31 | F14: =D14/E14 -> 1.483871 | G14: 8 | J14: =SUM(G14:I14) -> 8 | K14: 15 | L14: 103 | O14: =SUM(L14:N14) -> 103 | P14: 117 | Q14: =O14/P14 -> 0.88034188 | S14: =L14+G14+B14+M14+H14 -> 157 | T14: =N14+I14+C14 -> 0 | U14: =SUM(R14:T14) -> 157 | V14: =E14+K14+P14 -> 163 | W14: =V14-U14 -> 6 | X14: =ROUND(W14/$X$26*7,0) -> 0 | Y14: =T14+S14 -> 157 | Z14: =V14 -> 163 | AA14: =(S14+T14)/V14 -> 0.96319018 | AB14: 30 | AC14: 30 | AD14: =AB14-AC14 -> 0 | AE14: 46112 | AF14: NF | AG14: ALL TAXED
A15: SOUTH CDA | B15: =SUM(B11:B14) -> 106 | C15: =SUM(C11:C14) -> 2 | D15: =SUM(D11:D14) -> 108 | E15: =SUM(E11:E14) -> 82 | F15: =D15/E15 -> 1.3170732 | G15: =SUM(G11:G14) -> 49 | H15: =SUM(H11:H14) -> 0 | I15: =SUM(I11:I14) -> 0 | J15: =SUM(J11:J14) -> 49 | K15: =SUM(K11:K14) -> 42 | L15: =SUM(L11:L14) -> 310 | M15: =SUM(M11:M14) -> 0 | N15: =SUM(N11:N14) -> 4 | ... P15: =SUM(P11:P14) -> 336 | Q15: =O15/P15 -> 0.93452381 | R15: =SUM(R11:R14) -> 0 | S15: =SUM(S11:S14) -> 465 | T15: =SUM(T11:T14) -> 6 | U15: =SUM(U11:U14) -> 471 | V15: =SUM(V11:V14) -> 460 | W15: =SUM(W11:W14) -> -11 | X15: =ROUND(W15/X26*7,0) -> 0 | Y15: =SUM(Y11:Y14) -> 471 | Z15: =SUM(Z11:Z14) -> 460 | AA15: =Y15/Z15 -> 1.023913 | AB15: =SUM(AB11:AB14) -> 85 | AC15: =SUM(AC11:AC14) -> 85 | AD15: =SUM(AD11:AD14) -> 0
A16: Bradford | B16: 13 | C16: 4 | D16: =SUM(B16:C16) -> 17 | E16: 22 | F16: =D16/E16 -> 0.77272727 | G16: 9 | I16: 2 | J16: =SUM(G16:I16) -> 11 | K16: 9 | L16: 55 | N16: 9 | O16: =SUM(L16:N16) -> 64 | P16: 82 | Q16: =O16/P16 -> 0.7804878 | S16: =L16+G16+B16+M16+H16 -> 77 | T16: =N16+I16+C16 -> 15 | U16: =SUM(R16:T16) -> 92 | V16: =E16+K16+P16 -> 113 | W16: =V16-U16 -> 21 | X16: =ROUND(W16/$X$26*7,0) -> -1 | Y16: =T16+S16 -> 92 | Z16: =V16 -> 113 | AA16: =(S16+T16)/V16 -> 0.81415929 | AB16: 20 | AC16: 20 | AE16: 46112 | AF16: PS | AG16: ALL TAXED
A17: Huddersfield | B17: 23 | C17: 1 | D17: =SUM(B17:C17) -> 24 | E17: 21 | F17: =D17/E17 -> 1.1428571 | G17: 8 | I17: 1 | J17: =SUM(G17:I17) -> 9 | K17: 11 | L17: 86 | N17: 1 | O17: =SUM(L17:N17) -> 87 | P17: 86 | Q17: =O17/P17 -> 1.0116279 | S17: =L17+G17+B17+M17+H17 -> 117 | T17: =N17+I17+C17 -> 3 | U17: =SUM(R17:T17) -> 120 | V17: =E17+K17+P17 -> 118 | W17: =V17-U17 -> -2 | X17: =ROUND(W17/$X$26*7,0) -> 0 | Y17: =T17+S17 -> 120 | Z17: =V17 -> 118 | AA17: =(S17+T17)/V17 -> 1.0169492 | AB17: 20 | AC17: 20 | AD17: =AB17-AC17 -> 0 | AE17: 46112 | AF17: PS | AG17: ALL TAXED
A18: Silsden | B18: 15 | D18: =SUM(B18:C18) -> 15 | E18: 9 | F18: =D18/E18 -> 1.6666667 | G18: 13 | J18: =SUM(G18:I18) -> 13 | K18: 3 | L18: 26 | O18: =SUM(L18:N18) -> 26 | P18: 31 | Q18: =O18/P18 -> 0.83870968 | S18: =L18+G18+B18+M18+H18 -> 54 | T18: =N18+I18+C18 -> 0 | U18: =SUM(R18:T18) -> 54 | V18: =E18+K18+P18 -> 43 | W18: =V18-U18 -> -11 | X18: =ROUND(W18/$X$26*7,0) -> 0 | Y18: =T18+S18 -> 54 | Z18: =V18 -> 43 | AA18: =(S18+T18)/V18 -> 1.255814 | AB18: 5 | AC18: 5 | AD18: =AB18-AC18 -> 0 | AE18: 46112 | AF18: PS | AG18: ALL TAXED
A19: WY CDA | B19: =SUM(B16:B18) -> 51 | C19: =SUM(C16:C18) -> 5 | D19: =SUM(D16:D18) -> 56 | E19: =SUM(E16:E18) -> 52 | F19: =D19/E19 -> 1.0769231 | G19: =SUM(G16:G18) -> 30 | H19: =SUM(H16:H18) -> 0 | I19: =SUM(I16:I18) -> 3 | J19: =SUM(J16:J18) -> 33 | K19: =SUM(K16:K18) -> 23 | L19: =SUM(L16:L18) -> 167 | M19: =SUM(M16:M18) -> 0 | N19: =SUM(N16:N18) -> 10 | ... P19: =SUM(P16:P18) -> 199 | Q19: =O19/P19 -> 0.88944724 | R19: =SUM(R16:R18) -> 0 | S19: =SUM(S16:S18) -> 248 | T19: =SUM(T16:T18) -> 18 | U19: =SUM(U16:U18) -> 266 | V19: =SUM(V16:V18) -> 274 | W19: =SUM(W16:W18) -> 8 | X19: =ROUND(W19/X26*7,0) -> 0 | Y19: =SUM(Y16:Y18) -> 266 | Z19: =SUM(Z16:Z18) -> 274 | AA19: =Y19/Z19 -> 0.97080292 | AB19: =SUM(AB16:AB18) -> 45 | AC19: =SUM(AC16:AC18) -> 45 | AD19: =SUM(AD16:AD18) -> 0
AD20: =AB20-AC20 -> 0
AD21: =AB21-AC21 -> 0
A22: TOTAL | B22: =B19+B15+B10 -> 257 | C22: =C19+C15+C10 -> 16 | D22: =D19+D15+D10 -> 273 | E22: =E19+E15+E10 -> 218 | F22: =D22/E22 -> 1.2522936 | G22: =G19+G15+G10 -> 127 | H22: =H19+H15+H10 -> 0 | I22: =I19+I15+I10 -> 5 | J22: =J19+J15+J10 -> 132 | K22: =K19+K15+K10 -> 109 | L22: =L19+L15+L10 -> 786 | M22: =M19+M15+M10 -> 0 | N22: =N19+N15+N10 -> 21 | ... P22: =P19+P15+P10 -> 872 | Q22: =O22/P22 -> 0.92545872 | R22: =R19+R15+R10 -> 0 | S22: =S19+S15+S10 -> 1170 | T22: =T19+T15+T10 -> 42 | U22: =U19+U15+U10 -> 1212 | V22: =V19+V15+V10 -> 1199 | W22: =W19+W15+W10 -> -13 | X22: =ROUND(W22/X26*7,0) -> 0 | Y22: =Y19+Y15+Y10 -> 1212 | Z22: =Z19+Z15+Z10 -> 1199 | AA22: =(S22+T22)/V22 -> 1.0108424 | AB22: =AB19+AB15+AB10 -> 215 | AC22: =AC19+AC15+AC10 -> 212 | AD22: =AD19+AD15+AD10 -> 3
AB23: =AB22*250 -> 53750 | AC23: =AC22*250 -> 53000 | AD23: =AD22*250 -> 750
X24: 46112 | Z24: =Z22-Y22 -> -13
X25: =TODAY() -> 46308
A26: REGISTRATIONS (NON-COUNTING) | U26: Updated | V26: By | X26: =X24-X25 -> -196
B27: ='2026 - Q1'!B4 -> JAN | F27: ='2026 - Q1'!G4 -> FEB | J27: ='2026 - Q1'!L4 -> MAR | O27: TOTAL
B28: Non-Counting Fleet (Reg) | C28: Non-Counting Fleet (Unreg) | D28: Total | E28: Budget | F28: Non-Counting Fleet (Reg) | G28: Non-Counting Fleet (Unreg) | H28: Total | I28: Budget | J28: Non-Counting Fleet (Reg) | K28: Non-Counting Fleet (Unreg) | L28: Total | M28: Budget | O28: Non-Counting Fleet (Reg) | P28: Non-Counting Fleet (Unreg) | Q28: Total | R28: Budget | Y28: `
A29: Salford | B29: 124 | C29: 0 | D29: =SUM(B29:C29) -> 124 | E29: 134 | F29: 55 | G29: 0 | H29: =SUM(F29:G29) -> 55 | I29: 78 | J29: 230 | K29: 0 | L29: 0 | M29: 315 | O29: =J29+F29+B29 -> 409 | P29: =K29+G29+C29 -> 0 | Q29: =P29+O29 -> 409 | R29: =M29+I29+E29 -> 527 | U29: 46112 | V29: gb | W29: ALL TAXED
A30: NORTH CDA | B30: =SUM(B29) -> 124 | C30: =SUM(C29) -> 0 | D30: =SUM(D29) -> 124 | E30: =SUM(E29) -> 134 | F30: =SUM(F29) -> 55 | G30: =SUM(G29) -> 0 | H30: =SUM(H29) -> 55 | I30: =SUM(I29) -> 78 | ... M30: =SUM(M29) -> 315 | O30: =SUM(O29) -> 409 | P30: =SUM(P29) -> 0 | Q30: =SUM(Q29) -> 409 | R30: =SUM(R29) -> 527
A31: Denton | B31: 29 | C31: 0 | D31: =SUM(B31:C31) -> 29 | E31: 26 | F31: 16 | H31: 20 | I31: 15 | J31: 42 | K31: 0 | L31: =K31+J31 -> 42 | M31: 72 | O31: =J31+F31+B31 -> 87 | P31: =C31+G31+K31 -> 0 | Q31: =P31+O31 -> 87 | R31: =M31+I31+E31 -> 113 | U31: 46112 | V31: NF | W31: ALL TAXED
A32: SOUTH CDA | B32: =SUM(B31) -> 29 | C32: =SUM(C31) -> 0 | D32: =SUM(D31) -> 29 | E32: =SUM(E31) -> 26 | F32: =SUM(F31) -> 16 | G32: =SUM(G31) -> 0 | H32: =SUM(H31) -> 20 | I32: =SUM(I31) -> 15 | ... M32: =SUM(M31) -> 72 | O32: =SUM(O31) -> 87 | P32: =SUM(P31) -> 0 | Q32: =SUM(Q31) -> 87 | R32: =SUM(R31) -> 113
A33: Bradford | B33: 34 | C33: 0 | D33: =SUM(B33:C33) -> 34 | E33: 20 | F33: 89 | G33: 0 | H33: =SUM(F33:G33) -> 89 | I33: 12 | J33: 110 | K33: 0 | L33: =K33+J33 -> 110 | M33: 79 | O33: =J33+F33+B33 -> 233 | P33: =K33+G33+C33 -> 0 | Q33: =P33+O33 -> 233 | R33: =M33+I33+E33 -> 111 | U33: 31/032 | V33: PS | W33: ALL TAXED
A34: WY CDA | B34: =SUM(B33) -> 34 | C34: =SUM(C33) -> 0 | D34: =SUM(D33) -> 34 | E34: =SUM(E33) -> 20 | F34: =SUM(F33) -> 89 | G34: =SUM(G33) -> 0 | H34: =SUM(H33) -> 89 | I34: =SUM(I33) -> 12 | ... M34: =SUM(M33) -> 79 | O34: =SUM(O33) -> 233 | P34: =SUM(P33) -> 0 | Q34: =SUM(Q33) -> 233 | R34: =SUM(R33) -> 111
A37: TOTAL | B37: =B34+B32+B30 -> 187 | C37: =C34+C32+C30 -> 0 | D37: =D34+D32+D30 -> 187 | E37: =E34+E32+E30 -> 180 | F37: =F34+F32+F30 -> 160 | G37: =G34+G32+G30 -> 0 | H37: =H34+H32+H30 -> 164 | I37: =I34+I32+I30 -> 105 | ... M37: =M34+M32+M30 -> 466 | O37: =O34+O32+O30 -> 729 | P37: =P34+P32+P30 -> 0 | Q37: =Q34+Q32+Q30 -> 729 | R37: =R34+R32+R30 -> 751
A41: USED COUNTING VOLUME | N41: By
E42: ='2026 - Q1'!F27 -> FEB | I42: ='2026 - Q1'!J27 -> MAR | L42: TOTAL
B43: Counting | C43: Target | E43: Counting | F43: Target | I43: Counting | J43: Target | L43: Counting | M43: Target
A44: Bolton | B44: 53 | C44: 66 | D44: =B44/C44 -> 0.8030303 | E44: 67 | F44: 61 | G44: =E44/F44 -> 1.0983607 | I44: 58 | J44: 64 | K44: =I44/J44 -> 0.90625 | L44: =I44+E44+B44 -> 178 | M44: =J44+F44+C44 -> 191 | N44: gb | O44: 46112
